Workbook

Sheet 新初一数据看板
B2: 校区看板 | C2: 在读UV | D2: 在读PV
D3: 整体在读 | E3: 暑续秋 | F3: PV续报率 | G3: 数学 | H3: 暑续秋 | I3: 转化率 | J3: 语文 | K3: 暑续秋 | L3: 转化率 | M3: 英语 | N3: 暑续秋 | O3: 转化率 | Q3: 成绩分类 | R3: 数学UV | S3: 占比 | T3: 新宝利 | U3: 同创汇 | V3: 天成大厦
B4: 新宝利 | C4: =COUNTIFS('UV台帐'!A:A,B4,'UV台帐'!H:H,"在读") | D4: =G4+J4+M4 | E4: =H4+K4+N4 | F4: =E4/D4 | G4: =COUNTIFS('UV台帐'!A:A,B4,'UV台帐'!S:S,"在读") | H4: =SUMPRODUCT(('UV台帐'!A:A=B4)*('UV台帐'!T$3:T528="是")) | I4: =H4/G4 | J4: =COUNTIFS('UV台帐'!A:A,B4,'UV台帐'!AB:AB,"在读") | K4: =SUMPRODUCT(('UV台帐'!A:A=B4)*('UV台帐'!AC$3:AC528="是")) | L4: =K4/J4 | M4: =COUNTIFS('UV台帐'!A:A,B4,'UV台帐'!AK:AK,"在读") | N4: =SUMPRODUCT(('UV台帐'!A:A=B4)*('UV台帐'!AL$3:AL528="是")) | O4: =N4/M4 | Q4: 老师预估 | R4: =COUNTIF('UV台帐'!K:K,"老师预估") | S4: =R4/$R$7 | T4: =COUNTIFS('UV台帐'!K:K,"老师预估",'UV台帐'!A:A,"新宝利") | U4: =COUNTIFS('UV台帐'!K:K,"老师预估",'UV台帐'!A:A,"同创汇") | V4: =COUNTIFS('UV台帐'!K:K,"老师预估",'UV台帐'!A:A,"天成大厦")
B5: 同创汇 | C5: =COUNTIFS('UV台帐'!A:A,B5,'UV台帐'!H:H,"在读") | D5: =G5+J5+M5 | E5: =H5+K5+N5 | F5: =E5/D5 | G5: =COUNTIFS('UV台帐'!A:A,B5,'UV台帐'!S:S,"在读") | H5: =SUMPRODUCT(('UV台帐'!A:A=B5)*('UV台帐'!T$3:T528="是")) | I5: =H5/G5 | J5: =COUNTIFS('UV台帐'!A:A,B5,'UV台帐'!AB:AB,"在读") | K5: =SUMPRODUCT(('UV台帐'!A:A=B5)*('UV台帐'!AC$3:AC528="是")) | L5: =K5/J5 | M5: =COUNTIFS('UV台帐'!A:A,B5,'UV台帐'!AK:AK,"在读") | N5: =SUMPRODUCT(('UV台帐'!A:A=B5)*('UV台帐'!AL$3:AL528="是")) | O5: =N5/M5 | Q5: 报前测成绩 | R5: =COUNTIF('UV台帐'!K:K,"报前测成绩") | S5: =R5/$R$7 | T5: =COUNTIFS('UV台帐'!K:K,"报前测成绩",'UV台帐'!A:A,"新宝利") | U5: =COUNTIFS('UV台帐'!K:K,"报前测成绩",'UV台帐'!A:A,"同创汇") | V5: =COUNTIFS('UV台帐'!K:K,"报前测成绩",'UV台帐'!A:A,"天成大厦")
B6: 天成大厦 | C6: =COUNTIFS('UV台帐'!A:A,B6,'UV台帐'!H:H,"在读") | D6: =G6+J6+M6 | E6: =H6+K6+N6 | F6: =E6/D6 | G6: =COUNTIFS('UV台帐'!A:A,B6,'UV台帐'!S:S,"在读") | H6: =SUMPRODUCT(('UV台帐'!A:A=B6)*('UV台帐'!T$3:T528="是")) | I6: =H6/G6 | J6: =COUNTIFS('UV台帐'!A:A,B6,'UV台帐'!AB:AB,"在读") | K6: =SUMPRODUCT(('UV台帐'!A:A=B6)*('UV台帐'!AC$3:AC528="是")) | L6: =K6/J6 | M6: =COUNTIFS('UV台帐'!A:A,B6,'UV台帐'!AK:AK,"在读") | N6: =SUMPRODUCT(('UV台帐'!A:A=B6)*('UV台帐'!AL$3:AL528="是")) | O6: =N6/M6 | Q6: 校内成绩 | R6: =COUNTIF('UV台帐'!K:K,"校内成绩") | S6: =R6/$R$7 | T6: =COUNTIFS('UV台帐'!K:K,"校内成绩",'UV台帐'!A:A,"新宝利") | U6: =COUNTIFS('UV台帐'!K:K,"校内成绩",'UV台帐'!A:A,"同创汇") | V6: =COUNTIFS('UV台帐'!K:K,"校内成绩",'UV台帐'!A:A,"天成大厦")
B7: 合计 | C7: =SUM(C4:C6) | D7: =SUM(D4:D6) | E7: =SUM(E4:E6) | F7: =E7/D7 | G7: =SUM(G4:G6) | H7: =SUM(H4:H6) | I7: =H7/G7 | J7: =SUM(J4:J6) | K7: =SUM(K4:K6) | L7: =K7/J7 | M7: =SUM(M4:M6) | N7: =SUM(N4:N6) | O7: =N7/M7 | Q7: 合计 | R7: =SUM(R4:R6) | S7: - | T7: =SUM(T4:T6) | U7: =SUM(U4:U6) | V7: =SUM(V4:V6)
B9: 班型 | C9: 分数段 | D9: 数学分层 | U9: 生源质量 | V9: 整体 | X9: 新宝利 | Z9: 同创汇 | AB9: 天成大厦
D10: 校区合计 | E10: 新宝利 | F10: 零期 | G10: 一期 | H10: 二期 | I10: 三期 | J10: 同创汇 | K10: 零期 | L10: 一期 | M10: 二期 | N10: 三期 | O10: 天成大厦 | P10: 零期 | Q10: 一期 | R10: 二期 | S10: 三期 | V10: UV | W10: 占比 | X10: UV | Y10: 占比 | Z10: UV | AA10: 占比 | AB10: UV | AC10: 占比
B11: 启能 | C11: 95-120 | D11: =E11+J11+O11 | E11: =COUNTIFS('UV台帐'!A:A,$E$10,'UV台帐'!L:L,">=95") | F11: =COUNTIFS('UV台帐'!A:A,$E$10,'UV台帐'!L:L,">=95",'UV台帐'!R:R,"零期") | G11: =COUNTIFS('UV台帐'!A:A,$E$10,'UV台帐'!L:L,">=95",'UV台帐'!R:R,"一期") | H11: =COUNTIFS('UV台帐'!A:A,$E$10,'UV台帐'!L:L,">=95",'UV台帐'!R:R,"二期") | I11: =COUNTIFS('UV台帐'!A:A,$E$10,'UV台帐'!L:L,">=95",'UV台帐'!R:R,"三期") | J11: =COUNTIFS('UV台帐'!A:A,$J$10,'UV台帐'!L:L,">=95") | K11: =COUNTIFS('UV台帐'!A:A,"同创汇",'UV台帐'!L:L,">=95",'UV台帐'!R:R,"零期") | L11: =COUNTIFS('UV台帐'!A:A,"同创汇",'UV台帐'!L:L,">=95",'UV台帐'!R:R,"一期") | M11: =COUNTIFS('UV台帐'!A:A,"同创汇",'UV台帐'!L:L,">=95",'UV台帐'!R:R,"二期") | N11: =COUNTIFS('UV台帐'!A:A,"同创汇",'UV台帐'!L:L,">=95",'UV台帐'!R:R,"三期") | O11: =COUNTIFS('UV台帐'!A:A,$O$10,'UV台帐'!L:L,">=95") | P11: =COUNTIFS('UV台帐'!A:A,"天成大厦",'UV台帐'!L:L,">=95",'UV台帐'!R:R,"零期") | Q11: =COUNTIFS('UV台帐'!A:A,"天成大厦",'UV台帐'!L:L,">=95",'UV台帐'!R:R,"一期") | R11: =COUNTIFS('UV台帐'!A:A,"天成大厦",'UV台帐'!L:L,">=95",'UV台帐'!R:R,"二期") | S11: =COUNTIFS('UV台帐'!A:A,"天成大厦",'UV台帐'!L:L,">=95",'UV台帐'!R:R,"三期") | U11: 纯拉新 | V11: =X11+Z11+AB11 | W11: =V11/$V$17 | X11: =COUNTIFS('UV台帐'!A:A,$X$9,'UV台帐'!E:E,U11) | Y11: =X11/$X$17 | Z11: =COUNTIFS('UV台帐'!A:A,$Z$9,'UV台帐'!E:E,U11) | AA11: =Z11/$Z$17 | AB11: =COUNTIFS('UV台帐'!A:A,$AB$9,'UV台帐'!E:E,U11) | AC11: =AB11/$AB$17
C12: 80-94 | D12: =E12+J12+O12 | E12: =COUNTIFS('UV台帐'!A:A,$E$10,'UV台帐'!L:L,">=80",'UV台帐'!L:L,"<95") | F12: =COUNTIFS('UV台帐'!A:A,$E$10,'UV台帐'!L:L,">=80",'UV台帐'!L:L,"<95",'UV台帐'!R:R,"零期") | G12: =COUNTIFS('UV台帐'!A:A,$E$10,'UV台帐'!L:L,">=80",'UV台帐'!L:L,"<95",'UV台帐'!R:R,"一期") | H12: =COUNTIFS('UV台帐'!A:A,$E$10,'UV台帐'!L:L,">=80",'UV台帐'!L:L,"<95",'UV台帐'!R:R,"二期") | I12: =COUNTIFS('UV台帐'!A:A,$E$10,'UV台帐'!L:L,">=80",'UV台帐'!L:L,"<95",'UV台帐'!R:R,"三期") | J12: =COUNTIFS('UV台帐'!A:A,$J$10,'UV台帐'!L:L,">=80",'UV台帐'!L:L,"<95") | K12: =COUNTIFS('UV台帐'!A:A,"同创汇",'UV台帐'!L:L,">=80",'UV台帐'!L:L,"<95",'UV台帐'!R:R,"零期") | L12: =COUNTIFS('UV台帐'!A:A,"同创汇",'UV台帐'!L:L,">=80",'UV台帐'!L:L,"<95",'UV台帐'!R:R,"一期") | M12: =COUNTIFS('UV台帐'!A:A,"同创汇",'UV台帐'!L:L,">=80",'UV台帐'!L:L,"<95",'UV台帐'!R:R,"二期") | N12: =COUNTIFS('UV台帐'!A:A,"同创汇",'UV台帐'!L:L,">=80",'UV台帐'!L:L,"<95",'UV台帐'!R:R,"三期") | O12: =COUNTIFS('UV台帐'!A:A,$O$10,'UV台帐'!L:L,">=80",'UV台帐'!L:L,"<95") | P12: =COUNTIFS('UV台帐'!A:A,"天成大厦",'UV台帐'!L:L,">=80",'UV台帐'!L:L,"<95",'UV台帐'!R:R,"零期") | Q12: =COUNTIFS('UV台帐'!A:A,"天成大厦",'UV台帐'!L:L,">=80",'UV台帐'!L:L,"<95",'UV台帐'!R:R,"一期") | R12: =COUNTIFS('UV台帐'!A:A,"天成大厦",'UV台帐'!L:L,">=80",'UV台帐'!L:L,"<95",'UV台帐'!R:R,"二期") | S12: =COUNTIFS('UV台帐'!A:A,"天成大厦",'UV台帐'!L:L,">=80",'UV台帐'!L:L,"<95",'UV台帐'!R:R,"三期") | U12: 春季在读老生 | V12: =X12+Z12+AB12 | W12: =V12/$V$17 | X12: =COUNTIFS('UV台帐'!A:A,$X$9,'UV台帐'!E:E,U12) | Y12: =X12/$X$17 | Z12: =COUNTIFS('UV台帐'!A:A,$Z$9,'UV台帐'!E:E,U12) | AA12: =Z12/$Z$17 | AB12: =COUNTIFS('UV台帐'!A:A,$AB$9,'UV台帐'!E:E,U12) | AC12: =AB12/$AB$17
B13: 潜能 | C13: 60-79 | D13: =E13+J13+O13 | E13: =COUNTIFS('UV台帐'!A:A,$E$10,'UV台帐'!L:L,">=60",'UV台帐'!L:L,"<80") | F13: =COUNTIFS('UV台帐'!A:A,$E$10,'UV台帐'!L:L,">=60",'UV台帐'!L:L,"<80",'UV台帐'!R:R,"零期") | G13: =COUNTIFS('UV台帐'!A:A,$E$10,'UV台帐'!L:L,">=60",'UV台帐'!L:L,"<80",'UV台帐'!R:R,"一期") | H13: =COUNTIFS('UV台帐'!A:A,$E$10,'UV台帐'!L:L,">=60",'UV台帐'!L:L,"<80",'UV台帐'!R:R,"二期") | I13: =COUNTIFS('UV台帐'!A:A,$E$10,'UV台帐'!L:L,">=60",'UV台帐'!L:L,"<80",'UV台帐'!R:R,"三期") | J13: =COUNTIFS('UV台帐'!A:A,$J$10,'UV台帐'!L:L,">=60",'UV台帐'!L:L,"<80") | K13: =COUNTIFS('UV台帐'!A:A,"同创汇",'UV台帐'!L:L,">=60",'UV台帐'!L:L,"<80",'UV台帐'!R:R,"零期") | L13: =COUNTIFS('UV台帐'!A:A,"同创汇",'UV台帐'!L:L,">=60",'UV台帐'!L:L,"<80",'UV台帐'!R:R,"一期") | M13: =COUNTIFS('UV台帐'!A:A,"同创汇",'UV台帐'!L:L,">=60",'UV台帐'!L:L,"<80",'UV台帐'!R:R,"二期") | N13: =COUNTIFS('UV台帐'!A:A,"同创汇",'UV台帐'!L:L,">=60",'UV台帐'!L:L,"<80",'UV台帐'!R:R,"三期") | O13: =COUNTIFS('UV台帐'!A:A,$O$10,'UV台帐'!L:L,">=60",'UV台帐'!L:L,"<80") | P13: =COUNTIFS('UV台帐'!A:A,"天成大厦",'UV台帐'!L:L,">=60",'UV台帐'!L:L,"<80",'UV台帐'!R:R,"零期") | Q13: =COUNTIFS('UV台帐'!A:A,"天成大厦",'UV台帐'!L:L,">=60",'UV台帐'!L:L,"<80",'UV台帐'!R:R,"一期") | R13: =COUNTIFS('UV台帐'!A:A,"天成大厦",'UV台帐'!L:L,">=60",'UV台帐'!L:L,"<80",'UV台帐'!R:R,"二期") | S13: =COUNTIFS('UV台帐'!A:A,"天成大厦",'UV台帐'!L:L,">=60",'UV台帐'!L:L,"<80",'UV台帐'!R:R,"三期") | U13: 老生转介绍 | V13: =X13+Z13+AB13 | W13: =V13/$V$17 | X13: =COUNTIFS('UV台帐'!A:A,$X$9,'UV台帐'!E:E,U13) | Y13: =X13/$X$17 | Z13: =COUNTIFS('UV台帐'!A:A,$Z$9,'UV台帐'!E:E,U13) | AA13: =Z13/$Z$17 | AB13: =COUNTIFS('UV台帐'!A:A,$AB$9,'UV台帐'!E:E,U13) | AC13: =AB13/$AB$17
B14: 启航 | C14: 40-59 | D14: =E14+J14+O14 | E14: =COUNTIFS('UV台帐'!A:A,$E$10,'UV台帐'!L:L,">=40",'UV台帐'!L:L,"<=59") | F14: =COUNTIFS('UV台帐'!A:A,$E$10,'UV台帐'!L:L,">=40",'UV台帐'!L:L,"<=59",'UV台帐'!R:R,"零期") | G14: =COUNTIFS('UV台帐'!A:A,$E$10,'UV台帐'!L:L,">=40",'UV台帐'!L:L,"<=59",'UV台帐'!R:R,"一期") | H14: =COUNTIFS('UV台帐'!A:A,$E$10,'UV台帐'!L:L,">=40",'UV台帐'!L:L,"<=59",'UV台帐'!R:R,"二期") | I14: =COUNTIFS('UV台帐'!A:A,$E$10,'UV台帐'!L:L,">=40",'UV台帐'!L:L,"<=59",'UV台帐'!R:R,"三期") | J14: =COUNTIFS('UV台帐'!A:A,$J$10,'UV台帐'!L:L,">=40",'UV台帐'!L:L,"<=59") | K14: =COUNTIFS('UV台帐'!A:A,"同创汇",'UV台帐'!L:L,">=40",'UV台帐'!L:L,"<=59",'UV台帐'!R:R,"零期") | L14: =COUNTIFS('UV台帐'!A:A,"同创汇",'UV台帐'!L:L,">=40",'UV台帐'!L:L,"<=59",'UV台帐'!R:R,"一期") | M14: =COUNTIFS('UV台帐'!A:A,"同创汇",'UV台帐'!L:L,">=40",'UV台帐'!L:L,"<=59",'UV台帐'!R:R,"二期") | N14: =COUNTIFS('UV台帐'!A:A,"同创汇",'UV台帐'!L:L,">=40",'UV台帐'!L:L,"<=59",'UV台帐'!R:R,"三期") | O14: =COUNTIFS('UV台帐'!A:A,$O$10,'UV台帐'!L:L,">=40",'UV台帐'!L:L,"<=59") | P14: =COUNTIFS('UV台帐'!A:A,"天成大厦",'UV台帐'!L:L,">=40",'UV台帐'!L:L,"<=59",'UV台帐'!R:R,"零期") | Q14: =COUNTIFS('UV台帐'!A:A,"天成大厦",'UV台帐'!L:L,">=40",'UV台帐'!L:L,"<=59",'UV台帐'!R:R,"一期") | R14: =COUNTIFS('UV台帐'!A:A,"天成大厦",'UV台帐'!L:L,">=40",'UV台帐'!L:L,"<=59",'UV台帐'!R:R,"二期") | S14: =COUNTIFS('UV台帐'!A:A,"天成大厦",'UV台帐'!L:L,">=40",'UV台帐'!L:L,"<=59",'UV台帐'!R:R,"三期") | U14: 新生转介绍 | V14: =X14+Z14+AB14 | W14: =V14/$V$17 | X14: =COUNTIFS('UV台帐'!A:A,$X$9,'UV台帐'!E:E,U14) | Y14: =X14/$X$17 | Z14: =COUNTIFS('UV台帐'!A:A,$Z$9,'UV台帐'!E:E,U14) | AA14: =Z14/$Z$17 | AB14: =COUNTIFS('UV台帐'!A:A,$AB$9,'UV台帐'!E:E,U14) | AC14: =AB14/$AB$17
C15: <39 | D15: =E15+J15+O15 | E15: =COUNTIFS('UV台帐'!A:A,$E$10,'UV台帐'!L:L,">1",'UV台帐'!L:L,"<=39") | F15: =COUNTIFS('UV台帐'!A:A,$E$10,'UV台帐'!L:L,">1",'UV台帐'!L:L,"<=39",'UV台帐'!R:R,"零期") | G15: =COUNTIFS('UV台帐'!A:A,$E$10,'UV台帐'!L:L,">1",'UV台帐'!L:L,"<=39",'UV台帐'!R:R,"一期") | H15: =COUNTIFS('UV台帐'!A:A,$E$10,'UV台帐'!L:L,">1",'UV台帐'!L:L,"<=39",'UV台帐'!R:R,"二期") | I15: =COUNTIFS('UV台帐'!A:A,$E$10,'UV台帐'!L:L,">1",'UV台帐'!L:L,"<=39",'UV台帐'!R:R,"三期") | J15: =COUNTIFS('UV台帐'!A:A,$J$10,'UV台帐'!L:L,">1",'UV台帐'!L:L,"<=39") | K15: =COUNTIFS('UV台帐'!A:A,"同创汇",'UV台帐'!L:L,">1",'UV台帐'!L:L,"<=39",'UV台帐'!R:R,"零期") | L15: =COUNTIFS('UV台帐'!A:A,"同创汇",'UV台帐'!L:L,">1",'UV台帐'!L:L,"<=39",'UV台帐'!R:R,"一期") | M15: =COUNTIFS('UV台帐'!A:A,"同创汇",'UV台帐'!L:L,">1",'UV台帐'!L:L,"<=39",'UV台帐'!R:R,"二期") | N15: =COUNTIFS('UV台帐'!A:A,"同创汇",'UV台帐'!L:L,">1",'UV台帐'!L:L,"<=39",'UV台帐'!R:R,"三期") | O15: =COUNTIFS('UV台帐'!A:A,$O$10,'UV台帐'!L:L,">1",'UV台帐'!L:L,"<=39") | P15: =COUNTIFS('UV台帐'!A:A,"天成大厦",'UV台帐'!L:L,">1",'UV台帐'!L:L,"<=39",'UV台帐'!R:R,"零期") | Q15: =COUNTIFS('UV台帐'!O:O,"天成大厦",'UV台帐'!L:L,">1",'UV台帐'!L:L,"<=39",'UV台帐'!R:R,"一期") | R15: =COUNTIFS('UV台帐'!O:O,"天成大厦",'UV台帐'!L:L,">1",'UV台帐'!L:L,"<=39",'UV台帐'!R:R,"二期") | S15: =COUNTIFS('UV台帐'!O:O,"天成大厦",'UV台帐'!L:L,">1",'UV台帐'!L:L,"<=39",'UV台帐'!R:R,"三期") | U15: 反复低价 | V15: =X15+Z15+AB15 | W15: =V15/$V$17 | X15: =COUNTIFS('UV台帐'!A:A,$X$9,'UV台帐'!E:E,U15) | Y15: =X15/$X$17 | Z15: =COUNTIFS('UV台帐'!A:A,$Z$9,'UV台帐'!E:E,U15) | AA15: =Z15/$Z$17 | AB15: =COUNTIFS('UV台帐'!A:A,$AB$9,'UV台帐'!E:E,U15) | AC15: =AB15/$AB$17
B16: 合计 | D16: =SUM(D11:D15) | E16: =SUM(E11:E15) | F16: =SUM(F11:F15) | G16: =SUM(G11:G15) | H16: =SUM(H11:H15) | I16: =SUM(I11:I15) | J16: =SUM(J11:J15) | K16: =SUM(K11:K15) | ... S16: =SUM(S11:S15) | U16: 断报老生 | V16: =X16+Z16+AB16 | W16: =V16/$V$17 | X16: =COUNTIFS('UV台帐'!A:A,$X$9,'UV台帐'!E:E,U16) | Y16: =X16/$X$17 | Z16: =COUNTIFS('UV台帐'!A:A,$Z$9,'UV台帐'!E:E,U16) | AA16: =Z16/$Z$17 | AB16: =COUNTIFS('UV台帐'!A:A,$AB$9,'UV台帐'!E:E,U16) | AC16: =AB16/$AB$17
U17: 合计 | V17: =X17+Z17+AB17 | W17: - | X17: =SUM(X11:X16) | Y17: - | Z17: =SUM(Z11:Z16) | AA17: - | AB17: =SUM(AB11:AB16) | AC17: -
B21: 暑假整体汇总 | D21: =SUM(D23:D35)/2 | E21: =E27+E31+E35 | F21: =E21/(25*D21) | G21: =G27+G31+G35 | H21: =G21/E21 | I21: =SUM(I23:I35)/2 | J21: =I21/(E21+I21) | K21: =(K27*$E$27+K31*$E$31+K35*$E$35)/$E$21 | L21: =(L27*$E$27+L31*$E$31+L35*$E$35)/$E$21 | M21: =(M27*$E$27+M31*$E$31+M35*$E$35)/$E$21 | N21: =(N27*$E$27+N31*$E$31+N35*$E$35)/$E$21 | O21: =(O27*$E$27+O31*$E$31+O35*$E$35)/$E$21 | P21: =(P27*$E$27+P31*$E$31+P35*$E$35)/$E$21
B22: 老师看板 | C22: 学科 | D22: 班量 | E22: 在读PV | F22: 满班率 | G22: 暑续秋PV | H22: 转化率 | I22: 课前退PV | J22: 课前退率 | K22: 加微率 | L22: 首联率 | M22: vip入群率 | N22: 课前诺访 | O22: 课前确访 | P22: 课前确访
B23: 陈中帅 | C23: 数学 | D23: 7 | E23: =COUNTIFS('UV台帐'!N:N,B23,'UV台帐'!S:S,"在读") | F23: =E23/(D23*25) | G23: =SUMPRODUCT(('UV台帐'!N:N=B23)*('UV台帐'!T:T="是")) | H23: =G23/E23 | I23: =COUNTIFS('UV台帐'!N:N,B23,'UV台帐'!S:S,"课前退") | J23: =I23/(E23+I23) | K23: =COUNTIF('陈中帅'!T:T,"是")/E23 | L23: =COUNTIF('陈中帅'!U:U,"是")/E23 | M23: =COUNTIF('陈中帅'!V:V,"是")/E23 | N23: =COUNTIF('陈中帅'!Z:Z,"是")/E23 | O23: =COUNTIF('陈中帅'!AA:AA,"是")/E23 | P23: =COUNTIF('陈中帅'!AI:AI,"是")/E23
B24: 何咏04 | C24: 数学 | D24: 4 | E24: =COUNTIFS('UV台帐'!N:N,B24,'UV台帐'!S:S,"在读") | F24: =E24/(D24*25) | G24: =SUMPRODUCT(('UV台帐'!N:N=B24)*('UV台帐'!T:T="是")) | H24: =G24/E24 | I24: =COUNTIFS('UV台帐'!N:N,B24,'UV台帐'!S:S,"课前退") | J24: =I24/(E24+I24) | K24: =COUNTIF('何咏04'!T:T,"是")/E24 | L24: =COUNTIF('何咏04'!U:U,"是")/E24 | M24: =COUNTIF('何咏04'!V:V,"是")/E24 | N24: =COUNTIF('何咏04'!Z:Z,"是")/E24 | O24: =COUNTIF('何咏04'!AA:AA,"是")/E24 | P24: =COUNTIF('何咏04'!AI:AI,"是")/E24
B25: 田雨涵01 | C25: 数学 | D25: 5 | E25: =COUNTIFS('UV台帐'!N:N,B25,'UV台帐'!S:S,"在读") | F25: =E25/(D25*25) | G25: =SUMPRODUCT(('UV台帐'!N:N=B25)*('UV台帐'!T:T="是")) | H25: =G25/E25 | I25: =COUNTIFS('UV台帐'!N:N,B25,'UV台帐'!S:S,"课前退") | J25: =I25/(E25+I25) | K25: =COUNTIF('田雨涵01'!T:T,"是")/E25 | L25: =COUNTIF('田雨涵01'!U:U,"是")/E25 | M25: =COUNTIF('田雨涵01'!V:V,"是")/E25 | N25: =COUNTIF('田雨涵01'!Z:Z,"是")/E25 | O25: =COUNTIF('田雨涵01'!AA:AA,"是")/E25 | P25: =COUNTIF('田雨涵01'!AI:AI,"是")/E25
B26: 宗志鹏 | C26: 数学 | D26: 1 | E26: =COUNTIFS('UV台帐'!N:N,B26,'UV台帐'!S:S,"在读") | F26: =E26/(D26*25) | G26: =SUMPRODUCT(('UV台帐'!N:N=B26)*('UV台帐'!T:T="是")) | H26: =G26/E26 | I26: =COUNTIFS('UV台帐'!N:N,B26,'UV台帐'!S:S,"课前退") | J26: =I26/(E26+I26) | K26: =COUNTIF('宗志鹏'!T:T,"是")/E26 | L26: =COUNTIF('宗志鹏'!U:U,"是")/E26 | M26: =COUNTIF('宗志鹏'!V:V,"是")/E26 | N26: =COUNTIF('宗志鹏'!Z:Z,"是")/E26 | O26: =COUNTIF('宗志鹏'!AA:AA,"是")/E26 | P26: =COUNTIF('宗志鹏'!AI:AI,"是")/E26
B27: 数学合计 | D27: =SUM(D23:D26) | E27: =SUM(E23:E26) | F27: =E27/(D27*25) | G27: =SUM(G23:G26) | H27: =G27/E27 | I27: =SUM(I23:I26) | J27: =I27/(E27+I27) | K27: =(K23*$E$23+K24*$E$24+K25*$E$25+K26*$E$26)/$E$27 | L27: =(L23*$E$23+L24*$E$24+L25*$E$25+L26*$E$26)/$E$27 | M27: =(M23*$E$23+M24*$E$24+M25*$E$25+M26*$E$26)/$E$27 | N27: =(N23*$E$23+N24*$E$24+N25*$E$25+N26*$E$26)/$E$27 | O27: =(O23*$E$23+O24*$E$24+O25*$E$25+O26*$E$26)/$E$27 | P27: =(P23*$E$23+P24*$E$24+P25*$E$25+P26*$E$26)/$E$27
B28: 黄铭怡 | C28: 语文 | D28: 5 | E28: =COUNTIFS('UV台帐'!W:W,B28,'UV台帐'!AB:AB,"在读") | F28: =E28/(D28*25) | G28: =SUMPRODUCT(('UV台帐'!W:W=B28)*('UV台帐'!AC:AC="是")) | H28: =G28/E28 | I28: =COUNTIFS('UV台帐'!W:W,B28,'UV台帐'!AB:AB,"课前退") | J28: =I28/(E28+I28) | K28: =COUNTIF('黄铭怡'!T:T,"是")/E28 | L28: =COUNTIF('黄铭怡'!U:U,"是")/E28 | M28: =COUNTIF('黄铭怡'!V:V,"是")/E28 | N28: =COUNTIF('黄铭怡'!Z:Z,"是")/E28 | O28: =COUNTIF('黄铭怡'!AA:AA,"是")/E28 | P28: =COUNTIF('黄铭怡'!AI:AI,"是")/E28
B29: 李润 | C29: 语文 | D29: 7 | E29: =COUNTIFS('UV台帐'!W:W,B29,'UV台帐'!AB:AB,"在读") | F29: =E29/(D29*25) | G29: =SUMPRODUCT(('UV台帐'!W:W=B29)*('UV台帐'!AC:AC="是")) | H29: =G29/E29 | I29: =COUNTIFS('UV台帐'!W:W,B29,'UV台帐'!AB:AB,"课前退") | J29: =I29/(E29+I29) | K29: =COUNTIF('李润'!T:T,"是")/E29 | L29: =COUNTIF('李润'!U:U,"是")/E29 | M29: =COUNTIF('李润'!V:V,"是")/E29 | N29: =COUNTIF('李润'!Z:Z,"是")/E29 | O29: =COUNTIF('李润'!AA:AA,"是")/E29 | P29: =COUNTIF('李润'!AI:AI,"是")/E29 | U29: 零期 | V29: 学员数 | X29: vip入群率 | Y29: 课前家长会（UV） | AA29: 课中家长会（UV） | AC29: 转化率 （PV） | AD29: 学员意向分层(PV)
B30: 陈南05 | C30: 语文 | D30: 4 | E30: =COUNTIFS('UV台帐'!W:W,B30,'UV台帐'!AB:AB,"在读") | F30: =E30/(D30*25) | G30: =SUMPRODUCT(('UV台帐'!W:W=B30)*('UV台帐'!AC:AC="是")) | H30: =G30/E30 | I30: =COUNTIFS('UV台帐'!W:W,B30,'UV台帐'!AB:AB,"课前退") | J30: =I30/(E30+I30) | K30: =COUNTIF('陈南05'!T:T,"是")/E30 | L30: =COUNTIF('陈南05'!U:U,"是")/E30 | M30: =COUNTIF('陈南05'!V:V,"是")/E30 | N30: =COUNTIF('陈南05'!Z:Z,"是")/E30 | O30: =COUNTIF('陈南05'!AA:AA,"是")/E30 | P30: =COUNTIF('陈南05'!AI:AI,"是")/E30 | U30: 校区 | V30: PV | W30: UV | Y30: 课前诺访 | Z30: 课前确访 | AA30: 课中诺访 | AB30: 课中确访 | AD30: S | AE30: 占比 | AF30: A | AG30: 占比 | AH30: B | AI30: 占比 | AJ30: C | AK30: 占比
B31: 语文合计 | D31: =SUM(D28:D30) | E31: =SUM(E28:E30) | F31: =E31/(D31*25) | G31: =SUM(G28:G30) | H31: =G31/E31 | I31: =SUM(I28:I30) | J31: =I31/(E31+I31) | K31: =(K28*$E$28+K29*$E$29+K30*$E$30)/$E$31 | L31: =(L28*$E$28+L29*$E$29+L30*$E$30)/$E$31 | M31: =(M28*$E$28+M29*$E$29+M30*$E$30)/$E$31 | N31: =(N28*$E$28+N29*$E$29+N30*$E$30)/$E$31 | O31: =(O28*$E$28+O29*$E$29+O30*$E$30)/$E$31 | P31: =(P28*$E$28+P29*$E$29+P30*$E$30)/$E$31 | U31: 天成大厦 | V31: =SUMIF('零期·UV电访分配'!A:A,U31,'零期·UV电访分配'!AS:AS) | W31: =COUNTIF('零期·UV电访分配'!A:A,U31) | X31: =IFERROR(COUNTIFS('零期·UV电访分配'!A:A,U31,'零期·UV电访分配'!AH:AH,"是")/W31,0) | Y31: =IFERROR(COUNTIFS('零期·UV电访分配'!A:A,U31,'零期·UV电访分配'!S:S,"是")/W31,0) | Z31: =IFERROR(COUNTIFS('零期·UV电访分配'!A:A,U31,'零期·UV电访分配'!T:T,"是")/W31,0) | AA31: =IFERROR(COUNTIFS('零期·UV电访分配'!A:A,U31,'零期·UV电访分配'!AB:AB,"是")/W31,0) | AB31: =IFERROR(COUNTIFS('零期·UV电访分配'!A:A,U31,'零期·UV电访分配'!AD:AD,"是")/W31,0) | AC31: =IFERROR(SUMIF('零期·UV电访分配'!A:A,U31,'零期·UV电访分配'!AX:AX)/V31,0) | AD31: =COUNTIFS('零期·UV电访分配'!A:A,U31,'零期·UV电访分配'!AM:AM,"S")+COUNTIFS('零期·UV电访分配'!A:A,U31,'零期·UV电访分配'!AN:AN,"S")+COUNTIFS('零期·UV电访分配'!A:A,U31,'零期·UV电访分配'!AO:AO,"S") | AE31: =IFERROR(AD31/V31,0) | AF31: =COUNTIFS('零期·UV电访分配'!A:A,U31,'零期·UV电访分配'!AM:AM,"A")+COUNTIFS('零期·UV电访分配'!A:A,U31,'零期·UV电访分配'!AN:AN,"A")+COUNTIFS('零期·UV电访分配'!A:A,U31,'零期·UV电访分配'!AO:AO,"A") | AG31: =IFERROR(AF31/V31,0) | AH31: =COUNTIFS('零期·UV电访分配'!A:A,U31,'零期·UV电访分配'!AM:AM,"B")+COUNTIFS('零期·UV电访分配'!A:A,U31,'零期·UV电访分配'!AN:AN,"B")+COUNTIFS('零期·UV电访分配'!A:A,U31,'零期·UV电访分配'!AO:AO,"B") | AI31: =IFERROR(AH31/V31,0) | AJ31: =COUNTIFS('零期·UV电访分配'!A:A,U31,'零期·UV电访分配'!AM:AM,"C")+COUNTIFS('零期·UV电访分配'!A:A,U31,'零期·UV电访分配'!AN:AN,"C")+COUNTIFS('零期·UV电访分配'!A:A,U31,'零期·UV电访分配'!AO:AO,"C") | AK31: =IFERROR(AJ31/V31,0)
B32: 刘希子 | C32: 英语 | D32: 6 | E32: =COUNTIFS('UV台帐'!AF:AF,B32,'UV台帐'!AK:AK,"在读") | F32: =E32/(D32*25) | G32: =SUMPRODUCT(('UV台帐'!AF:AF=B32)*('UV台帐'!AL:AL="是")) | H32: =G32/E32 | I32: =COUNTIFS('UV台帐'!AF:AF,B32,'UV台帐'!AK:AK,"课前退") | J32: =I32/(E32+I32) | K32: =COUNTIF('刘希子'!T:T,"是")/E32 | L32: =COUNTIF('刘希子'!U:U,"是")/E32 | M32: =COUNTIF('刘希子'!V:V,"是")/E32 | N32: =COUNTIF('刘希子'!Z:Z,"是")/E32 | O32: =COUNTIF('刘希子'!AA:AA,"是")/E32 | P32: =COUNTIF('刘希子'!AI:AI,"是")/E32 | U32: 同创汇 | V32: =SUMIF('零期·UV电访分配'!A:A,U32,'零期·UV电访分配'!AS:AS) | W32: =COUNTIF('零期·UV电访分配'!A:A,U32) | X32: =COUNTIFS('零期·UV电访分配'!A:A,U32,'零期·UV电访分配'!AH:AH,"是")/W32 | Y32: =COUNTIFS('零期·UV电访分配'!A:A,U32,'零期·UV电访分配'!S:S,"是")/W32 | Z32: =COUNTIFS('零期·UV电访分配'!A:A,U32,'零期·UV电访分配'!T:T,"是")/W32 | AA32: =COUNTIFS('零期·UV电访分配'!A:A,U32,'零期·UV电访分配'!AB:AB,"是")/W32 | AB32: =COUNTIFS('零期·UV电访分配'!A:A,U32,'零期·UV电访分配'!AD:AD,"是")/W32 | AC32: =SUMIF('零期·UV电访分配'!A:A,U32,'零期·UV电访分配'!AX:AX)/V32 | AD32: =COUNTIFS('零期·UV电访分配'!A:A,U32,'零期·UV电访分配'!AM:AM,"S")+COUNTIFS('零期·UV电访分配'!A:A,U32,'零期·UV电访分配'!AN:AN,"S")+COUNTIFS('零期·UV电访分配'!A:A,U32,'零期·UV电访分配'!AO:AO,"S") | AE32: =AD32/V32 | AF32: =COUNTIFS('零期·UV电访分配'!A:A,U32,'零期·UV电访分配'!AM:AM,"A")+COUNTIFS('零期·UV电访分配'!A:A,U32,'零期·UV电访分配'!AN:AN,"A")+COUNTIFS('零期·UV电访分配'!A:A,U32,'零期·UV电访分配'!AO:AO,"A") | AG32: =AF32/V32 | AH32: =COUNTIFS('零期·UV电访分配'!A:A,U32,'零期·UV电访分配'!AM:AM,"B")+COUNTIFS('零期·UV电访分配'!A:A,U32,'零期·UV电访分配'!AN:AN,"B")+COUNTIFS('零期·UV电访分配'!A:A,U32,'零期·UV电访分配'!AO:AO,"B") | AI32: =AH32/V32 | AJ32: =COUNTIFS('零期·UV电访分配'!A:A,U32,'零期·UV电访分配'!AM:AM,"C")+COUNTIFS('零期·UV电访分配'!A:A,U32,'零期·UV电访分配'!AN:AN,"C")+COUNTIFS('零期·UV电访分配'!A:A,U32,'零期·UV电访分配'!AO:AO,"C") | AK32: =AJ32/V32
B33: 肖锐03 | C33: 英语 | D33: 7 | E33: =COUNTIFS('UV台帐'!AF:AF,B33,'UV台帐'!AK:AK,"在读") | F33: =E33/(D33*25) | G33: =SUMPRODUCT(('UV台帐'!AF:AF=B33)*('UV台帐'!AL:AL="是")) | H33: =G33/E33 | I33: =COUNTIFS('UV台帐'!AF:AF,B33,'UV台帐'!AK:AK,"课前退") | J33: =I33/(E33+I33) | K33: =COUNTIF('肖锐03'!T:T,"是")/E33 | L33: =COUNTIF('肖锐03'!U:U,"是")/E33 | M33: =COUNTIF('肖锐03'!V:V,"是")/E33 | N33: =COUNTIF('肖锐03'!Z:Z,"是")/E33 | O33: =COUNTIF('肖锐03'!AA:AA,"是")/E33 | P33: =COUNTIF('肖锐03'!AI:AI,"是")/E33 | U33: 新宝利 | V33: =SUMIF('零期·UV电访分配'!A:A,U33,'零期·UV电访分配'!AS:AS) | W33: =COUNTIF('零期·UV电访分配'!A:A,U33) | X33: =COUNTIFS('零期·UV电访分配'!A:A,U33,'零期·UV电访分配'!AH:AH,"是")/W33 | Y33: =COUNTIFS('零期·UV电访分配'!A:A,U33,'零期·UV电访分配'!S:S,"是")/W33 | Z33: =COUNTIFS('零期·UV电访分配'!A:A,U33,'零期·UV电访分配'!T:T,"是")/W33 | AA33: =COUNTIFS('零期·UV电访分配'!A:A,U33,'零期·UV电访分配'!AB:AB,"是")/W33 | AB33: =COUNTIFS('零期·UV电访分配'!A:A,U33,'零期·UV电访分配'!AD:AD,"是")/W33 | AC33: =SUMIF('零期·UV电访分配'!A:A,U33,'零期·UV电访分配'!AX:AX)/V33 | AD33: =COUNTIFS('零期·UV电访分配'!A:A,U33,'零期·UV电访分配'!AM:AM,"S")+COUNTIFS('零期·UV电访分配'!A:A,U33,'零期·UV电访分配'!AN:AN,"S")+COUNTIFS('零期·UV电访分配'!A:A,U33,'零期·UV电访分配'!AO:AO,"S") | AE33: =AD33/V33 | AF33: =COUNTIFS('零期·UV电访分配'!A:A,U33,'零期·UV电访分配'!AM:AM,"A")+COUNTIFS('零期·UV电访分配'!A:A,U33,'零期·UV电访分配'!AN:AN,"A")+COUNTIFS('零期·UV电访分配'!A:A,U33,'零期·UV电访分配'!AO:AO,"A") | AG33: =AF33/V33 | AH33: =COUNTIFS('零期·UV电访分配'!A:A,U33,'零期·UV电访分配'!AM:AM,"B")+COUNTIFS('零期·UV电访分配'!A:A,U33,'零期·UV电访分配'!AN:AN,"B")+COUNTIFS('零期·UV电访分配'!A:A,U33,'零期·UV电访分配'!AO:AO,"B") | AI33: =AH33/V33 | AJ33: =COUNTIFS('零期·UV电访分配'!A:A,U33,'零期·UV电访分配'!AM:AM,"C")+COUNTIFS('零期·UV电访分配'!A:A,U33,'零期·UV电访分配'!AN:AN,"C")+COUNTIFS('零期·UV电访分配'!A:A,U33,'零期·UV电访分配'!AO:AO,"C") | AK33: =AJ33/V33
B34: 高心怡04 | C34: 英语 | D34: 6 | E34: =COUNTIFS('UV台帐'!AF:AF,B34,'UV台帐'!AK:AK,"在读") | F34: =E34/(D34*25) | G34: =SUMPRODUCT(('UV台帐'!AF:AF=B34)*('UV台帐'!AL:AL="是")) | H34: =G34/E34 | I34: =COUNTIFS('UV台帐'!AF:AF,B34,'UV台帐'!AK:AK,"课前退") | J34: =I34/(E34+I34) | K34: =COUNTIF('高心怡04'!T:T,"是")/E34 | L34: =COUNTIF('高心怡04'!U:U,"是")/E34 | M34: =COUNTIF('高心怡04'!V:V,"是")/E34 | N34: =COUNTIF('高心怡04'!Z:Z,"是")/E34 | O34: =COUNTIF('高心怡04'!AA:AA,"是")/E34 | P34: =COUNTIF('高心怡04'!AI:AI,"是")/E34 | U34: 分校合计 | V34: =SUM(V31:V33) | W34: =SUM(W31:W33) | X34: =COUNTIF('零期·UV电访分配'!AH:AH,"是")/W34 | Y34: =COUNTIF('零期·UV电访分配'!S:S,"是")/W34 | Z34: =COUNTIF('零期·UV电访分配'!T:T,"是")/W34 | AA34: =COUNTIF('零期·UV电访分配'!AB:AB,"是")/W34 | AB34: =COUNTIF('零期·UV电访分配'!AD:AD,"是")/W34 | AC34: ='零期·UV电访分配'!AX2/V34 | AD34: =SUM(AD31:AD33) | AE34: =AD34/V34 | AF34: =SUM(AF31:AF33) | AG34: =AF34/V34 | AH34: =SUM(AH31:AH33) | AI34: =AH34/V34 | AJ34: =SUM(AJ31:AJ33) | AK34: =AJ34/V34
B35: 英语合计 | D35: =SUM(D32:D33) | E35: =SUM(E32:E34) | F35: =E35/(D35*25) | G35: =SUM(G32:G34) | H35: =G35/E35 | I35: =SUM(I32:I34) | J35: =I35/(E35+I35) | K35: =(K32*$E$32+K33*$E$33+K34*$E$34)/$E$35 | L35: =(L32*$E$32+L33*$E$33+L34*$E$34)/$E$35 | M35: =(M32*$E$32+M33*$E$33+M34*$E$34)/$E$35 | N35: =(N32*$E$32+N33*$E$33+N34*$E$34)/$E$35 | O35: =(O32*$E$32+O33*$E$33+O34*$E$34)/$E$35 | P35: =(P32*$E$32+P33*$E$33+P34*$E$34)/$E$35
B37: 零期汇总 | D37: 基础信息 | K37: 课前服务 | P37: 首课电访 | S37: 课中家长会
D38: =SUM(D40:D52)/2 | E38: =E44+E48+E52 | F38: =E38/(25*D38) | G38: =G44+G48+G52 | H38: =G38/E38 | I38: =SUM(I40:I52)/2 | J38: =I38/(E38+I38) | K38: =(K44*$E$44+K48*$E$48+K52*$E$52)/$E$38 | L38: =(L44*$E$44+L48*$E$48+L52*$E$52)/$E$38 | M38: =(M44*$E$44+M48*$E$48+M52*$E$52)/$E$38 | N38: =(N44*$E$44+N48*$E$48+N52*$E$52)/$E$38 | O38: =(O44*$E$44+O48*$E$48+O52*$E$52)/$E$38 | P38: =(P44*$E$44+P48*$E$48+P52*$E$52)/$E$38 | Q38: =SUM(Q40:Q52)/2 | R38: =SUM(R40:R52)/2 | S38: =SUM(S40:S52)/2 | T38: =S38/E38 | U38: =SUM(U40:U52)/2 | V38: =SUM(V40:V52)/2 | W38: =V38/U38 | X38: =SUM(X40:X52)/2 | Y38: =SUM(Y40:Y52)/2 | Z38: =Y38/X38 | AA38: =SUM(AA40:AA52)/2 | AB38: =AA38/E38
B39: 老师看板 | C39: 学科 | D39: 班量 | E39: 在读PV | F39: 满班率 | G39: 暑续秋PV | H39: 转化率 | I39: 课前退PV | J39: 课前退率 | K39: 加微率 | L39: 首联率 | M39: vip入群率 | N39: 课前诺访 | O39: 课前确访 | P39: 电访覆盖率 | Q39: 首课电联量 | R39: 差值 | S39: 课中诺访 | T39: 诺访率PV | U39: 7月4日应到 | V39: 7月4日实到 | W39: 到场率 | X39: 7月5日应到 | Y39: 7月5日实到 | Z39: 到场率 | AA39: 整体到场 | AB39: 到场率
B40: 陈中帅 | C40: 数学 | D40: 3 | E40: =COUNTIFS('UV台帐'!N:N,B40,'UV台帐'!S:S,"在读",'UV台帐'!R:R,"零期") | F40: =E40/(D40*25) | G40: =SUMPRODUCT(('UV台帐'!N:N=B40)*('UV台帐'!T:T="是")*('UV台帐'!R:R="零期")) | H40: =G40/E40 | I40: =COUNTIFS('UV台帐'!N:N,B40,'UV台帐'!S:S,"课前退",'UV台帐'!R:R,"零期") | J40: =I40/(E40+I40) | K40: =IFERROR(COUNTIFS('陈中帅'!T:T,"是",'陈中帅'!B:B,"零期")/E40,"") | L40: =COUNTIFS('陈中帅'!U:U,"是",'陈中帅'!B:B,"零期")/E40 | M40: =COUNTIFS('陈中帅'!V:V,"是",'陈中帅'!B:B,"零期")/E40 | N40: =COUNTIFS('陈中帅'!Z:Z,"是",'陈中帅'!B:B,"零期")/E40 | O40: =COUNTIFS('陈中帅'!AA:AA,"是",'陈中帅'!B:B,"零期")/E40 | P40: =COUNTIFS('陈中帅'!AI:AI,"是",'陈中帅'!B:B,"零期")/E40 | Q40: =COUNTIFS('陈中帅'!AI:AI,"是",'陈中帅'!B:B,"零期") | R40: =Q40-E40 | S40: =COUNTIFS('零期·UV电访分配'!E:E,B40,'零期·UV电访分配'!AB:AB,"是") | T40: =S40/E40 | U40: =COUNTIFS('零期·UV电访分配'!E:E,B40,'零期·UV电访分配'!I:I,"在读",'零期·UV电访分配'!H:H,"零期",'零期·UV电访分配'!A:A,"同创汇") | V40: =COUNTIFS('零期·UV电访分配'!E:E,B40,'零期·UV电访分配'!I:I,"在读",'零期·UV电访分配'!H:H,"零期",'零期·UV电访分配'!A:A,"同创汇",'零期·UV电访分配'!AD:AD,"是") | W40: =V40/U40 | X40: =COUNTIFS('零期·UV电访分配'!E:E,B40,'零期·UV电访分配'!I:I,"在读",'零期·UV电访分配'!H:H,"零期",'零期·UV电访分配'!A:A,"新宝利") | Y40: =COUNTIFS('零期·UV电访分配'!E:E,B40,'零期·UV电访分配'!I:I,"在读",'零期·UV电访分配'!H:H,"零期",'零期·UV电访分配'!A:A,"新宝利",'零期·UV电访分配'!AD:AD,"是") | Z40: =Y40/X40 | AA40: =Y40+V40 | AB40: =AA40/E40
B41: 何咏04 | C41: 数学 | D41: 0 | E41: =COUNTIFS('UV台帐'!N:N,B41,'UV台帐'!S:S,"在读",'UV台帐'!R:R,"零期") | F41: =IFERROR(E41/(D41*25),"0") | G41: =SUMPRODUCT(('UV台帐'!N:N=B41)*('UV台帐'!T:T="是")*('UV台帐'!R:R="零期")) | H41: =IFERROR(G41/E41,"0") | I41: =COUNTIFS('UV台帐'!N:N,B41,'UV台帐'!S:S,"课前退",'UV台帐'!R:R,"零期") | J41: =IFERROR(I41/(E41+I41),"0") | K41: =IFERROR(COUNTIFS('何咏04'!T:T,"是",'何咏04'!B:B,"零期")/E41,"0") | L41: =IFERROR(COUNTIFS('何咏04'!U:U,"是",'何咏04'!B:B,"零期")/E41,"0") | M41: =IFERROR(COUNTIFS('何咏04'!V:V,"是",'何咏04'!B:B,"零期")/E41,"0") | N41: =IFERROR(COUNTIFS('何咏04'!Z:Z,"是",'何咏04'!B:B,"零期")/E41,"0") | O41: =IFERROR(COUNTIFS('何咏04'!AA:AA,"是",'何咏04'!B:B,"零期")/E41,"0") | P41: =IFERROR(COUNTIFS('何咏04'!AB:AB,"是",'何咏04'!C:C,"零期")/F41,"0") | Q41: =IFERROR(COUNTIFS('何咏04'!AC:AC,"是",'何咏04'!D:D,"零期")/G41,"0") | R41: =Q41-E41 | S41: =COUNTIFS('零期·UV电访分配'!E:E,B41,'零期·UV电访分配'!AB:AB,"是") | T41: =S41/E41 | U41: =COUNTIFS('零期·UV电访分配'!E:E,B41,'零期·UV电访分配'!I:I,"在读",'零期·UV电访分配'!H:H,"零期",'零期·UV电访分配'!A:A,"同创汇") | V41: =COUNTIFS('零期·UV电访分配'!E:E,B41,'零期·UV电访分配'!I:I,"在读",'零期·UV电访分配'!H:H,"零期",'零期·UV电访分配'!A:A,"同创汇",'零期·UV电访分配'!AD:AD,"是") | W41: =V41/U41 | Y41: 0 | Z41: =Y41/X41 | AA41: =Y41+V41 | AB41: =AA41/E41
B42: 田雨涵01 | C42: 数学 | D42: 2 | E42: =COUNTIFS('UV台帐'!N:N,B42,'UV台帐'!S:S,"在读",'UV台帐'!R:R,"零期") | F42: =E42/(D42*25) | G42: =SUMPRODUCT(('UV台帐'!N:N=B42)*('UV台帐'!T:T="是")*('UV台帐'!R:R="零期")) | H42: =G42/E42 | I42: =COUNTIFS('UV台帐'!N:N,B42,'UV台帐'!S:S,"课前退",'UV台帐'!R:R,"零期") | J42: =I42/(E42+I42) | K42: =COUNTIFS('田雨涵01'!T:T,"是",'田雨涵01'!B:B,"零期")/E42 | L42: =COUNTIFS('田雨涵01'!U:U,"是",'田雨涵01'!B:B,"零期")/E42 | M42: =COUNTIFS('田雨涵01'!V:V,"是",'田雨涵01'!B:B,"零期")/E42 | N42: =COUNTIFS('田雨涵01'!Z:Z,"是",'田雨涵01'!B:B,"零期")/E42 | O42: =COUNTIFS('田雨涵01'!AA:AA,"是",'田雨涵01'!B:B,"零期")/E42 | P42: =COUNTIFS('田雨涵01'!AI:AI,"是",'田雨涵01'!B:B,"零期")/E42 | Q42: =COUNTIFS('田雨涵01'!AI:AI,"是",'田雨涵01'!B:B,"零期") | R42: =Q42-E42 | S42: =COUNTIFS('零期·UV电访分配'!E:E,B42,'零期·UV电访分配'!AB:AB,"是") | T42: =S42/E42 | U42: =COUNTIFS('零期·UV电访分配'!E:E,B42,'零期·UV电访分配'!I:I,"在读",'零期·UV电访分配'!H:H,"零期",'零期·UV电访分配'!A:A,"同创汇") | V42: =COUNTIFS('零期·UV电访分配'!E:E,B42,'零期·UV电访分配'!I:I,"在读",'零期·UV电访分配'!H:H,"零期",'零期·UV电访分配'!A:A,"同创汇",'零期·UV电访分配'!AD:AD,"是") | W42: =V42/U42 | X42: =COUNTIFS('零期·UV电访分配'!E:E,B42,'零期·UV电访分配'!I:I,"在读",'零期·UV电访分配'!H:H,"零期",'零期·UV电访分配'!A:A,"新宝利") | Y42: =COUNTIFS('零期·UV电访分配'!E:E,B42,'零期·UV电访分配'!I:I,"在读",'零期·UV电访分配'!H:H,"零期",'零期·UV电访分配'!A:A,"新宝利",'零期·UV电访分配'!AD:AD,"是") | Z42: =Y42/X42 | AA42: =Y42+V42 | AB42: =AA42/E42
B43: 宗志鹏 | C43: 数学 | D43: 0 | E43: =COUNTIFS('UV台帐'!N:N,B43,'UV台帐'!S:S,"在读",'UV台帐'!R:R,"零期") | F43: =IFERROR(E43/(D43*25),"0") | G43: =SUMPRODUCT(('UV台帐'!N:N=B43)*('UV台帐'!T:T="是")*('UV台帐'!R:R="零期")) | H43: =IFERROR(G43/E43,"0") | I43: =COUNTIFS('UV台帐'!N:N,B43,'UV台帐'!S:S,"课前退",'UV台帐'!R:R,"零期") | J43: =IFERROR(I43/(E43+I43),"0") | K43: =IFERROR(COUNTIFS('宗志鹏'!T:T,"是",'宗志鹏'!B:B,"零期")/E43,"0") | L43: =IFERROR(COUNTIFS('宗志鹏'!U:U,"是",'宗志鹏'!B:B,"零期")/E43,"0") | M43: =IFERROR(COUNTIFS('宗志鹏'!V:V,"是",'宗志鹏'!B:B,"零期")/E43,"0") | N43: =IFERROR(COUNTIFS('宗志鹏'!Z:Z,"是",'宗志鹏'!B:B,"零期")/E43,"0") | O43: =IFERROR(COUNTIFS('宗志鹏'!AA:AA,"是",'宗志鹏'!B:B,"零期")/E43,"0") | P43: =IFERROR(COUNTIFS('宗志鹏'!AB:AB,"是",'宗志鹏'!C:C,"零期")/F43,"0") | Q43: =IFERROR(COUNTIFS('宗志鹏'!AC:AC,"是",'宗志鹏'!D:D,"零期")/G43,"0") | R43: =Q43-E43 | S43: =COUNTIFS('零期·UV电访分配'!E:E,B43,'零期·UV电访分配'!AB:AB,"是") | T43: =S43/E43 | U43: =COUNTIFS('零期·UV电访分配'!E:E,B43,'零期·UV电访分配'!I:I,"在读",'零期·UV电访分配'!H:H,"零期",'零期·UV电访分配'!A:A,"同创汇") | V43: 0 | W43: =V43/U43 | Y43: 0 | Z43: =Y43/X43 | AA43: =Y43+V43 | AB43: =AA43/E43
B44: 数学合计 | D44: =SUM(D40:D43) | E44: =SUM(E40:E43) | F44: =E44/(D44*25) | G44: =SUM(G40:G43) | H44: =G44/E44 | I44: =SUM(I40:I43) | J44: =I44/(E44+I44) | K44: =(K40*$E$40+K41*$E$41+K42*$E$42+K43*$E$43)/$E$44 | L44: =(L40*$E$40+L41*$E$41+L42*$E$42+L43*$E$43)/$E$44 | M44: =(M40*$E$40+M41*$E$41+M42*$E$42+M43*$E$43)/$E$44 | N44: =(N40*$E$40+N41*$E$41+N42*$E$42+N43*$E$43)/$E$44 | O44: =(O40*$E$40+O41*$E$41+O42*$E$42+O43*$E$43)/$E$44 | P44: =(P40*$E$40+P41*$E$41+P42*$E$42+P43*$E$43)/$E$44 | Q44: =SUM(Q40:Q42) | R44: =Q44-E44 | S44: =SUM(S40:S42) | T44: =S44/E44 | U44: =SUM(U40:U42) | V44: =SUM(V40:V42) | W44: =V44/U44 | X44: =SUM(X40:X42) | Y44: =SUM(Y40:Y42) | Z44: =Y44/X44 | AA44: =Y44+V44 | AB44: =AA44/E44
B45: 黄铭怡 | C45: 语文 | D45: 2 | E45: =COUNTIFS('UV台帐'!W:W,B45,'UV台帐'!AB:AB,"在读",'UV台帐'!AA:AA,"零期") | F45: =E45/(D45*25) | G45: =SUMPRODUCT(('UV台帐'!W:W=B45)*('UV台帐'!AC:AC="是")*('UV台帐'!AA:AA="零期")) | H45: =G45/E45 | I45: =COUNTIFS('UV台帐'!W:W,B45,'UV台帐'!AB:AB,"课前退",'UV台帐'!AA:AA,"零期") | J45: =I45/(E45+I45) | K45: =COUNTIFS('黄铭怡'!T:T,"是",'黄铭怡'!B:B,"零期")/E45 | L45: =COUNTIFS('黄铭怡'!U:U,"是",'黄铭怡'!B:B,"零期")/E45 | M45: =COUNTIFS('黄铭怡'!V:V,"是",'黄铭怡'!B:B,"零期")/E45 | N45: =COUNTIFS('黄铭怡'!Z:Z,"是",'黄铭怡'!B:B,"零期")/E45 | O45: =COUNTIFS('黄铭怡'!AA:AA,"是",'黄铭怡'!B:B,"零期")/E45 | P45: =COUNTIFS('黄铭怡'!AI:AI,"是",'黄铭怡'!B:B,"零期")/E45 | Q45: =COUNTIFS('黄铭怡'!AI:AI,"是",'黄铭怡'!B:B,"零期") | R45: =Q45-E45 | S45: =COUNTIFS('零期·UV电访分配'!J:J,B45,'零期·UV电访分配'!AB:AB,"是") | T45: =S45/E45 | U45: =COUNTIFS('零期·UV电访分配'!J:J,B45,'零期·UV电访分配'!M:M,"在读",'零期·UV电访分配'!L:L,"零期",'零期·UV电访分配'!A:A,"同创汇") | V45: =COUNTIFS('零期·UV电访分配'!J:J,B45,'零期·UV电访分配'!M:M,"在读",'零期·UV电访分配'!L:L,"零期",'零期·UV电访分配'!A:A,"同创汇",'零期·UV电访分配'!AD:AD,"是") | W45: =V45/U45 | X45: =COUNTIFS('零期·UV电访分配'!J:J,B45,'零期·UV电访分配'!M:M,"在读",'零期·UV电访分配'!L:L,"零期",'零期·UV电访分配'!A:A,"新宝利") | Y45: =COUNTIFS('零期·UV电访分配'!J:J,B45,'零期·UV电访分配'!M:M,"在读",'零期·UV电访分配'!L:L,"零期",'零期·UV电访分配'!A:A,"新宝利",'零期·UV电访分配'!AD:AD,"是") | Z45: =Y45/X45 | AA45: =Y45+V45 | AB45: =AA45/E45
B46: 李润 | C46: 语文 | D46: 2 | E46: =COUNTIFS('UV台帐'!W:W,B46,'UV台帐'!AB:AB,"在读",'UV台帐'!AA:AA,"零期") | F46: =E46/(D46*25) | G46: =SUMPRODUCT(('UV台帐'!W:W=B46)*('UV台帐'!AC:AC="是")*('UV台帐'!AA:AA="零期")) | H46: =G46/E46 | I46: =COUNTIFS('UV台帐'!W:W,B46,'UV台帐'!AB:AB,"课前退",'UV台帐'!AA:AA,"零期") | J46: =I46/(E46+I46) | K46: =COUNTIFS('李润'!T:T,"是",'李润'!B:B,"零期")/E46 | L46: =COUNTIFS('李润'!U:U,"是",'李润'!B:B,"零期")/E46 | M46: =COUNTIFS('李润'!V:V,"是",'李润'!B:B,"零期")/E46 | N46: =COUNTIFS('李润'!Z:Z,"是",'李润'!B:B,"零期")/E46 | O46: =COUNTIFS('李润'!AA:AA,"是",'李润'!B:B,"零期")/E46 | P46: =COUNTIFS('李润'!AI:AI,"是",'李润'!B:B,"零期")/E46 | Q46: =COUNTIFS('李润'!AI:AI,"是",'李润'!B:B,"零期") | R46: =Q46-E46 | S46: =COUNTIFS('零期·UV电访分配'!J:J,B46,'零期·UV电访分配'!AB:AB,"是") | T46: =S46/E46 | U46: =COUNTIFS('零期·UV电访分配'!J:J,B46,'零期·UV电访分配'!M:M,"在读",'零期·UV电访分配'!L:L,"零期",'零期·UV电访分配'!A:A,"同创汇") | V46: =COUNTIFS('零期·UV电访分配'!J:J,B46,'零期·UV电访分配'!M:M,"在读",'零期·UV电访分配'!L:L,"零期",'零期·UV电访分配'!A:A,"同创汇",'零期·UV电访分配'!AD:AD,"是") | W46: =V46/U46 | X46: =COUNTIFS('零期·UV电访分配'!J:J,B46,'零期·UV电访分配'!M:M,"在读",'零期·UV电访分配'!L:L,"零期",'零期·UV电访分配'!A:A,"新宝利") | Y46: =COUNTIFS('零期·UV电访分配'!J:J,B46,'零期·UV电访分配'!M:M,"在读",'零期·UV电访分配'!L:L,"零期",'零期·UV电访分配'!A:A,"新宝利",'零期·UV电访分配'!AD:AD,"是") | Z46: =Y46/X46 | AA46: =Y46+V46 | AB46: =AA46/E46
...

Sheet UV台帐
A1: 教学点 | B1: 学生uid | C1: 学生姓名 | D1: 归属顾问 | E1: 渠道来源 | F1: 备注 | G1: 介绍人 | H1: UV在读情况 | I1: 期次 | J1: 雪球思维 | U1: 悦读创作 | AD1: 双语素养 | AM1: 是否加入VIP群 | AN1: 家长会 | AR1: 顾问盘点
J2: 班级id | K2: 成绩来源 | L2: 报前测成绩 | M2: 校内未加权 | N2: 主讲 | O2: 教室 | P2: 上课时段 | Q2: 班型 | R2: 期次 | S2: 是否在读 | T2: 是否续秋 | U2: 班级id | V2: 报前测成绩 | W2: 主讲 | X2: 教室 | Y2: 上课时段 | Z2: 班型 | AA2: 期次 | AB2: 是否在读 | AC2: 是否续秋 | AD2: 班级id | AE2: 报前测成绩 | AF2: 主讲 | AG2: 教室 | AH2: 上课时段 | AI2: 班型 | AJ2: 期次 | AK2: 是否在读 | AL2: 是否续秋 | AN2: 课前诺访 | AO2: 课前确访 | AP2: 课中诺访 | AQ2: 课中确访 | AR2: 续费意愿 | AS2: 盘点依据
A3: 新宝利 | B3: 4859453289 | C3: 辉辉 | D3: 沈思浩 | H3: 在读 | I3: 三期 | J3: 5111035 | N3: 何咏04 | O3: 教室2 | P3: 15:50-18:00 | Q3: 启能班 | R3: 三期 | S3: 在读 | T3: - | U3: 5170873 | W3: 李润 | X3: 教室2 | Y3: 13:20-15:30 | Z3: 潜能班 | AA3: 三期 | AB3: 在读 | AC3: - | AD3: 5170871 | AF3: 肖锐03 | AG3: 教室2 | AH3: 10:20-12:30 | AI3: 潜能班 | AJ3: 三期 | AK3: 在读 | AL3: -
A4: 新宝利 | B4: 2365706460 | C4: 赵宏达 | D4: 张敏烨 | H4: 在读 | I4: 三期 | J4: 4632447 | N4: 田雨涵01 | O4: 教室5 | P4: 10:20-12:30 | Q4: 潜能班 | R4: 三期 | S4: 在读 | T4: - | U4: 5111226 | W4: 李润 | X4: 教室5 | Y4: 15:50-18:00 | Z4: 潜能班 | AA4: 三期 | AB4: 在读 | AC4: - | AD4: 4513388 | AF4: 肖锐03 | AG4: 教室5 | AH4: 13:20-15:30 | AI4: 潜能班 | AJ4: 三期 | AK4: 在读 | AL4: -
A5: 新宝利 | B5: 4739786737 | C5: 吴宸宇 | D5: 王丽 | H5: 在读 | I5: 二期 | J5: 5111034 | N5: 田雨涵01 | O5: 教室4 | P5: 13:20-15:30 | Q5: 潜能班 | R5: 二期 | S5: 在读 | T5: - | U5: - | W5: - | X5: - | Y5: - | Z5: - | AA5: - | AB5: - | AC5: - | AD5: - | AF5: - | AG5: - | AH5: - | AI5: - | AJ5: - | AK5: - | AL5: -
A6: 天成大厦 | B6: 4857404593 | C6: 许嘉言 | D6: 龙倩敏 | H6: 在读 | I6: 三期 | J6: 5230801 | N6: 宗志鹏 | O6: 03品尚 | P6: 13:20-15:30 | Q6: 潜能班 | R6: 三期 | S6: 在读 | T6: - | U6: 5230739 | W6: 李润 | X6: 03品尚 | Y6: 10:20-12:30 | Z6: 潜能班 | AA6: 三期 | AB6: 在读 | AC6: - | AD6: 5230788 | AF6: 刘希子 | AG6: 03品尚 | AH6: 15:50-18:00 | AI6: 潜能班 | AJ6: 三期 | AK6: 在读 | AL6: -
A7: 同创汇 | B7: 4238523947 | C7: 丁俊熙 | D7: 王丽 | H7: 在读 | I7: 一期 | J7: 5230802 | N7: 田雨涵01 | O7: 02彩虹桥 | P7: 15:50-18:00 | Q7: 潜能班 | R7: 一期 | S7: 在读 | T7: - | U7: 4632448 | W7: 陈南05 | X7: 02彩虹桥 | Y7: 10:20-12:30 | Z7: 潜能班 | AA7: 一期 | AB7: 在读 | AC7: - | AD7: 3132837 | AF7: 高心怡04 | AG7: 02彩虹桥 | AH7: 13:20-15:30 | AI7: 潜能班 | AJ7: 一期 | AK7: 在读 | AL7: -
A8: 同创汇 | B8: 2510657138 | C8: 梁赫 | D8: 戎凯01 | H8: 在读 | I8: 一期 | J8: 5230802 | N8: 田雨涵01 | O8: 02彩虹桥 | P8: 15:50-18:00 | Q8: 潜能班 | R8: 一期 | S8: 在读 | T8: - | U8: 4632448 | W8: 陈南05 | X8: 02彩虹桥 | Y8: 10:20-12:30 | Z8: 潜能班 | AA8: 一期 | AB8: 在读 | AC8: - | AD8: 3132837 | AF8: 高心怡04 | AG8: 02彩虹桥 | AH8: 13:20-15:30 | AI8: 潜能班 | AJ8: 一期 | AK8: 在读 | AL8: -
A9: 同创汇 | B9: 4858371265 | C9: 方嘉怡 | D9: 戎凯01 | H9: 在读 | I9: 二期 | J9: 3132872 | N9: 何咏04 | O9: 01智慧林 | P9: 13:20-15:30 | Q9: 潜能班 | R9: 二期 | S9: 在读 | T9: - | U9: 5230809 | W9: 李润 | X9: 01智慧林 | Y9: 10:20-12:30 | Z9: 潜能班 | AA9: 二期 | AB9: 在读 | AC9: - | AD9: 3132893 | AF9: 刘希子 | AG9: 01智慧林 | AH9: 15:50-18:00 | AI9: 潜能班 | AJ9: 二期 | AK9: 在读 | AL9: -
A10: 新宝利 | B10: 2341143960 | C10: 杨善曦 | D10: 杨林33 | H10: 在读 | I10: 一期 | J10: - | N10: - | O10: - | P10: - | Q10: - | R10: - | S10: - | T10: - | U10: 5230773 | W10: 陈南05 | X10: 教室2 | Y10: 15:50-18:00 | Z10: 潜能班 | AA10: 一期 | AB10: 在读 | AC10: - | AD10: 3132888 | AF10: 肖锐03 | AG10: 教室2 | AH10: 10:20-12:30 | AI10: 潜能班 | AJ10: 一期 | AK10: 在读 | AL10: -
A11: 新宝利 | B11: 2532873612 | C11: 范昕 | D11: 杨林33 | H11: 在读 | I11: 三期 | J11: 4632447 | N11: 田雨涵01 | O11: 教室5 | P11: 10:20-12:30 | Q11: 潜能班 | R11: 三期 | S11: 在读 | T11: - | U11: 5111226 | W11: 李润 | X11: 教室5 | Y11: 15:50-18:00 | Z11: 潜能班 | AA11: 三期 | AB11: 在读 | AC11: - | AD11: 5170871 | AF11: 肖锐03 | AG11: 教室2 | AH11: 10:20-12:30 | AI11: 潜能班 | AJ11: 三期 | AK11: 在读 | AL11: -
A12: 新宝利 | B12: 2649629431 | C12: 黄华辰 | D12: 林志豪01 | H12: 在读 | I12: 一期 | J12: 5230732 | N12: 何咏04 | O12: 教室3 | P12: 10:30-12:40 | Q12: 启能班 | R12: 一期 | S12: 在读 | T12: - | U12: 5230773 | W12: 陈南05 | X12: 教室2 | Y12: 15:50-18:00 | Z12: 潜能班 | AA12: 一期 | AB12: 在读 | AC12: - | AD12: 3132899 | AF12: 肖锐03 | AG12: 教室3 | AH12: 07:50-10:00 | AI12: 潜能班 | AJ12: 一期 | AK12: 在读 | AL12: -
A13: 新宝利 | B13: 2704638904 | C13: 许文铠 | D13: 林志豪01 | H13: 在读 | I13: 一期 | J13: 5230742 | N13: 何咏04 | O13: 教室2 | P13: 13:20-15:30 | Q13: 潜能班 | R13: 一期 | S13: 在读 | T13: - | U13: 5230773 | W13: 陈南05 | X13: 教室2 | Y13: 15:50-18:00 | Z13: 潜能班 | AA13: 一期 | AB13: 在读 | AC13: - | AD13: 3132899 | AF13: 肖锐03 | AG13: 教室3 | AH13: 07:50-10:00 | AI13: 潜能班 | AJ13: 一期 | AK13: 在读 | AL13: -
A14: 新宝利 | B14: 2260449861 | C14: 翟意恒 | D14: 杨林33 | H14: 在读 | I14: 一期 | J14: 5230732 | N14: 何咏04 | O14: 教室3 | P14: 10:30-12:40 | Q14: 启能班 | R14: 一期 | S14: 在读 | T14: - | U14: 5230773 | W14: 陈南05 | X14: 教室2 | Y14: 15:50-18:00 | Z14: 潜能班 | AA14: 一期 | AB14: 在读 | AC14: - | AD14: 3132899 | AF14: 肖锐03 | AG14: 教室3 | AH14: 07:50-10:00 | AI14: 潜能班 | AJ14: 一期 | AK14: 在读 | AL14: -
A15: 天成大厦 | B15: 4490857874 | C15: 郑惠雅 | D15: 沈思浩 | E15: 新生转介绍 | G15: 马诗涵 | H15: 在读 | I15: 一期/二期 | J15: 3132864 | K15: 校内成绩 | L15: 86 | M15: 96 | N15: 宗志鹏 | O15: 03品尚 | P15: 13:20-15:30 | Q15: 潜能班 | R15: 二期 | S15: 在读 | T15: - | U15: 3132834 | W15: 李润 | X15: 03品尚 | Y15: 07:50-10:00 | Z15: 潜能班 | AA15: 一期 | AB15: 在读 | AC15: - | AD15: 5230783 | AF15: 刘希子 | AG15: 03品尚 | AH15: 13:20-15:30 | AI15: 潜能班 | AJ15: 一期 | AK15: 在读 | AL15: -
A16: 天成大厦 | B16: 2568716390 | C16: 马诗涵 | D16: 沈思浩 | E16: 老生转介绍 | G16: 陈梓萱 | H16: 在读 | I16: 二期 | J16: 3132864 | K16: 校内成绩 | L16: 90 | M16: 100 | N16: 宗志鹏 | O16: 03品尚 | P16: 13:20-15:30 | Q16: 潜能班 | R16: 二期 | S16: 在读 | T16: - | U16: 3132810 | W16: 李润 | X16: 03品尚 | Y16: 15:50-18:00 | Z16: 潜能班 | AA16: 二期 | AB16: 在读 | AC16: - | AD16: 3132858 | AF16: 刘希子 | AG16: 03品尚 | AH16: 10:20-12:30 | AI16: 潜能班 | AJ16: 二期 | AK16: 在读 | AL16: -
A17: 同创汇 | B17: 2715584701 | C17: 陈俊杰 | D17: 林志豪01 | E17: 纯拉新 | H17: 在读 | I17: 一期/二期 | J17: 5230732 | K17: 校内成绩 | L17: 86 | M17: 95 | N17: 何咏04 | O17: 教室3 | P17: 10:30-12:40 | Q17: 启能班 | R17: 一期 | S17: 在读 | T17: - | U17: 5230809 | W17: 李润 | X17: 01智慧林 | Y17: 10:20-12:30 | Z17: 潜能班 | AA17: 二期 | AB17: 在读 | AC17: - | AD17: 3132893 | AF17: 刘希子 | AG17: 01智慧林 | AH17: 15:50-18:00 | AI17: 潜能班 | AJ17: 二期 | AK17: 在读 | AL17: -
A18: 同创汇 | B18: 2743981182 | C18: 杜宇图 | D18: 王丽 | E18: 纯拉新 | H18: 在读 | I18: 一期 | J18: - | N18: - | O18: - | P18: - | Q18: - | R18: - | S18: - | T18: - | U18: 4632448 | W18: 陈南05 | X18: 02彩虹桥 | Y18: 10:20-12:30 | Z18: 潜能班 | AA18: 一期 | AB18: 在读 | AC18: - | AD18: 3132837 | AF18: 高心怡04 | AG18: 02彩虹桥 | AH18: 13:20-15:30 | AI18: 潜能班 | AJ18: 一期 | AK18: 在读 | AL18: -
A19: 同创汇 | B19: 4103453629 | C19: 陈若涵 | D19: 苏丽婷 | E19: 纯拉新 | H19: 在读 | I19: 一期 | J19: 5230802 | K19: 校内成绩 | L19: 72 | M19: 90 | N19: 田雨涵01 | O19: 02彩虹桥 | P19: 15:50-18:00 | Q19: 潜能班 | R19: 一期 | S19: 在读 | T19: - | U19: 4632448 | W19: 陈南05 | X19: 02彩虹桥 | Y19: 10:20-12:30 | Z19: 潜能班 | AA19: 一期 | AB19: 在读 | AC19: - | AD19: 3132837 | AF19: 高心怡04 | AG19: 02彩虹桥 | AH19: 13:20-15:30 | AI19: 潜能班 | AJ19: 一期 | AK19: 在读 | AL19: -
A20: 新宝利 | B20: 2244875334 | C20: 闫睿欣 | D20: 张敏烨 | E20: 新生转介绍 | G20: 顾玉瑶 | H20: 在读 | I20: 三期 | J20: 3132902 | K20: 校内成绩 | L20: 72 | M20: 90 | N20: 陈中帅 | O20: 教室3 | P20: 13:20-15:30 | Q20: 潜能班 | R20: 三期 | S20: 在读 | T20: - | U20: 5111226 | W20: 李润 | X20: 教室5 | Y20: 15:50-18:00 | Z20: 潜能班 | AA20: 三期 | AB20: 在读 | AC20: - | AD20: 5170871 | AF20: 肖锐03 | AG20: 教室2 | AH20: 10:20-12:30 | AI20: 潜能班 | AJ20: 三期 | AK20: 在读 | AL20: -
A21: 同创汇 | B21: 2489383127 | C21: 黄喆 | D21: 张敏烨 | E21: 新生转介绍 | G21: 陈滢西 | H21: 在读 | I21: 一期 | J21: 5230802 | K21: 校内成绩 | L21: 72 | M21: 90 | N21: 田雨涵01 | O21: 02彩虹桥 | P21: 15:50-18:00 | Q21: 潜能班 | R21: 一期 | S21: 在读 | T21: - | U21: 4632448 | W21: 陈南05 | X21: 02彩虹桥 | Y21: 10:20-12:30 | Z21: 潜能班 | AA21: 一期 | AB21: 在读 | AC21: - | AD21: 3132837 | AF21: 高心怡04 | AG21: 02彩虹桥 | AH21: 13:20-15:30 | AI21: 潜能班 | AJ21: 一期 | AK21: 在读 | AL21: -
A22: 同创汇 | B22: 2304918401 | C22: 高凯文 | D22: 王丽 | E22: 老生转介绍 | G22: 李倬承 | H22: 在读 | I22: 二期 | J22: 3132872 | K22: 校内成绩 | L22: 72 | M22: 90 | N22: 何咏04 | O22: 01智慧林 | P22: 13:20-15:30 | Q22: 潜能班 | R22: 二期 | S22: 在读 | T22: - | U22: 5230809 | W22: 李润 | X22: 01智慧林 | Y22: 10:20-12:30 | Z22: 潜能班 | AA22: 二期 | AB22: 在读 | AC22: - | AD22: - | AF22: - | AG22: - | AH22: - | AI22: - | AJ22: - | AK22: - | AL22: -
A23: 同创汇 | B23: 2414638176 | C23: 彦华 | D23: 林志豪01 | E23: 纯拉新 | H23: 在读 | I23: 二期 | J23: 3132872 | K23: 校内成绩 | L23: 64 | M23: 85 | N23: 何咏04 | O23: 01智慧林 | P23: 13:20-15:30 | Q23: 潜能班 | R23: 二期 | S23: 在读 | T23: - | U23: - | W23: - | X23: - | Y23: - | Z23: - | AA23: - | AB23: - | AC23: - | AD23: - | AF23: - | AG23: - | AH23: - | AI23: - | AJ23: - | AK23: - | AL23: -
A24: 同创汇 | B24: 4462940335 | C24: 龙柳橙 | D24: 龙倩敏 | E24: 新生转介绍 | G24: 叶晓静 | H24: 在读 | I24: 二期 | J24: 3132872 | K24: 报前测成绩 | L24: 75 | M24: - | N24: 何咏04 | O24: 01智慧林 | P24: 13:20-15:30 | Q24: 潜能班 | R24: 二期 | S24: 在读 | T24: - | U24: 5230809 | W24: 李润 | X24: 01智慧林 | Y24: 10:20-12:30 | Z24: 潜能班 | AA24: 二期 | AB24: 在读 | AC24: - | AD24: 3132893 | AF24: 刘希子 | AG24: 01智慧林 | AH24: 15:50-18:00 | AI24: 潜能班 | AJ24: 二期 | AK24: 在读 | AL24: -
A25: 同创汇 | B25: 2413160133 | C25: 朵朵 | D25: 戎凯01 | E25: 新生转介绍 | G25: 涂馨允 | H25: 在读 | I25: 一期 | J25: 5230802 | K25: 校内成绩 | L25: 72 | M25: 90 | N25: 田雨涵01 | O25: 02彩虹桥 | P25: 15:50-18:00 | Q25: 潜能班 | R25: 一期 | S25: 在读 | T25: - | U25: 4632448 | W25: 陈南05 | X25: 02彩虹桥 | Y25: 10:20-12:30 | Z25: 潜能班 | AA25: 一期 | AB25: 在读 | AC25: - | AD25: 3132837 | AF25: 高心怡04 | AG25: 02彩虹桥 | AH25: 13:20-15:30 | AI25: 潜能班 | AJ25: 一期 | AK25: 在读 | AL25: -
A26: 同创汇 | B26: 2701666734 | C26: 涂馨允 | D26: 戎凯01 | E26: 新生转介绍 | G26: 陈秉谦 | H26: 在读 | I26: 一期 | J26: 5230802 | K26: 校内成绩 | L26: 86 | M26: 96 | N26: 田雨涵01 | O26: 02彩虹桥 | P26: 15:50-18:00 | Q26: 潜能班 | R26: 一期 | S26: 在读 | T26: - | U26: 4632448 | W26: 陈南05 | X26: 02彩虹桥 | Y26: 10:20-12:30 | Z26: 潜能班 | AA26: 一期 | AB26: 在读 | AC26: - | AD26: 3132837 | AF26: 高心怡04 | AG26: 02彩虹桥 | AH26: 13:20-15:30 | AI26: 潜能班 | AJ26: 一期 | AK26: 在读 | AL26: -
A27: 同创汇 | B27: 4198557381 | C27: 张俊健 | D27: 林志豪01 | E27: 新生转介绍 | G27: 李浩林 | H27: 在读 | I27: 二期 | J27: 3132872 | K27: 校内成绩 | L27: 72 | M27: 90 | N27: 何咏04 | O27: 01智慧林 | P27: 13:20-15:30 | Q27: 潜能班 | R27: 二期 | S27: 在读 | T27: - | U27: 5230809 | W27: 李润 | X27: 01智慧林 | Y27: 10:20-12:30 | Z27: 潜能班 | AA27: 二期 | AB27: 在读 | AC27: - | AD27: 3132893 | AF27: 刘希子 | AG27: 01智慧林 | AH27: 15:50-18:00 | AI27: 潜能班 | AJ27: 二期 | AK27: 在读 | AL27: -
A28: 同创汇 | B28: 2554261157 | C28: 杨沛梵 | D28: 戎凯01 | E28: 纯拉新 | H28: 在读 | I28: 一期 | J28: 5230802 | K28: 校内成绩 | L28: 72 | M28: 90 | N28: 田雨涵01 | O28: 02彩虹桥 | P28: 15:50-18:00 | Q28: 潜能班 | R28: 一期 | S28: 在读 | T28: - | U28: 4632448 | W28: 陈南05 | X28: 02彩虹桥 | Y28: 10:20-12:30 | Z28: 潜能班 | AA28: 一期 | AB28: 在读 | AC28: - | AD28: 3132837 | AF28: 高心怡04 | AG28: 02彩虹桥 | AH28: 13:20-15:30 | AI28: 潜能班 | AJ28: 一期 | AK28: 在读 | AL28: -
A29: 新宝利 | B29: 4860505150 | C29: 王梓赫 | D29: 陈亮延 | E29: 新生转介绍 | G29: 钟博睿 | H29: 在读 | I29: 一期 | J29: 5230742 | K29: 校内成绩 | L29: 72 | M29: 90 | N29: 何咏04 | O29: 教室2 | P29: 13:20-15:30 | Q29: 潜能班 | R29: 一期 | S29: 在读 | T29: - | U29: 5230773 | W29: 陈南05 | X29: 教室2 | Y29: 15:50-18:00 | Z29: 潜能班 | AA29: 一期 | AB29: 在读 | AC29: - | AD29: 3132888 | AF29: 肖锐03 | AG29: 教室2 | AH29: 10:20-12:30 | AI29: 潜能班 | AJ29: 一期 | AK29: 在读 | AL29: -
A30: 新宝利 | B30: 2406026641 | C30: 郭梓爱 | D30: 张敏烨 | E30: 新生转介绍 | G30: 千惠 | H30: 在读 | I30: 一期 | J30: 5230732 | K30: 校内成绩 | L30: 86 | M30: 96 | N30: 何咏04 | O30: 教室3 | P30: 10:30-12:40 | Q30: 启能班 | R30: 一期 | S30: 在读 | T30: - | U30: 5230773 | W30: 陈南05 | X30: 教室2 | Y30: 15:50-18:00 | Z30: 潜能班 | AA30: 一期 | AB30: 在读 | AC30: - | AD30: 3132899 | AF30: 肖锐03 | AG30: 教室3 | AH30: 07:50-10:00 | AI30: 潜能班 | AJ30: 一期 | AK30: 在读 | AL30: -
A31: 同创汇 | B31: 2579947640 | C31: 梁静彤 | D31: 张敏烨 | E31: 新生转介绍 | G31: 林梓博 | H31: 在读 | I31: 一期/二期 | J31: 3132872 | K31: 校内成绩 | L31: 60 | M31: 80 | N31: 何咏04 | O31: 01智慧林 | P31: 13:20-15:30 | Q31: 潜能班 | R31: 二期 | S31: 在读 | T31: - | U31: 4632448 | W31: 陈南05 | X31: 02彩虹桥 | Y31: 10:20-12:30 | Z31: 潜能班 | AA31: 一期 | AB31: 在读 | AC31: - | AD31: 3132893 | AF31: 刘希子 | AG31: 01智慧林 | AH31: 15:50-18:00 | AI31: 潜能班 | AJ31: 二期 | AK31: 在读 | AL31: -
A32: 同创汇 | B32: 4067487942 | C32: 廖宇轩 | D32: 戎凯01 | E32: 老生转介绍 | G32: 张权 | H32: 在读 | I32: 零期 | J32: 3132897 | K32: 校内成绩 | L32: 85 | M32: 95 | N32: 陈中帅 | O32: 01智慧林 | P32: 10:20-12:30 | Q32: 潜能班 | R32: 零期 | S32: 在读 | T32: - | U32: 5230722 | W32: 李润 | X32: 01智慧林 | Y32: 15:50-18:00 | Z32: 潜能班 | AA32: 零期 | AB32: 在读 | AC32: - | AD32: 5230737 | AF32: 高心怡04 | AG32: 01智慧林 | AH32: 13:20-15:30 | AI32: 潜能班 | AJ32: 零期 | AK32: 在读 | AL32: - | AM32: 是 | AN32: 否 | AO32: 否
A33: 新宝利 | B33: 2321411555 | C33: 林梓博 | D33: 张敏烨 | E33: 新生转介绍 | G33: 穆邵瀚 | H33: 在读 | I33: 三期 | J33: 4632447 | K33: 校内成绩 | L33: 60 | M33: 80 | N33: 田雨涵01 | O33: 教室5 | P33: 10:20-12:30 | Q33: 潜能班 | R33: 三期 | S33: 在读 | T33: - | U33: 5111226 | W33: 李润 | X33: 教室5 | Y33: 15:50-18:00 | Z33: 潜能班 | AA33: 三期 | AB33: 在读 | AC33: - | AD33: 4513388 | AF33: 肖锐03 | AG33: 教室5 | AH33: 13:20-15:30 | AI33: 潜能班 | AJ33: 三期 | AK33: 在读 | AL33: -
A34: 天成大厦 | B34: 4858579623 | C34: 善美 | D34: 陈亮延 | E34: 新生转介绍 | G34: 梁诗晨 | H34: 在读 | I34: 三期 | J34: 5230801 | K34: 校内成绩 | L34: 60 | M34: 80 | N34: 宗志鹏 | O34: 03品尚 | P34: 13:20-15:30 | Q34: 潜能班 | R34: 三期 | S34: 在读 | T34: - | U34: 5230739 | W34: 李润 | X34: 03品尚 | Y34: 10:20-12:30 | Z34: 潜能班 | AA34: 三期 | AB34: 在读 | AC34: - | AD34: 5230788 | AF34: 刘希子 | AG34: 03品尚 | AH34: 15:50-18:00 | AI34: 潜能班 | AJ34: 三期 | AK34: 在读 | AL34: -
A35: 新宝利 | B35: 2520505537 | C35: 严佩瑶 | D35: 王丽 | E35: 新生转介绍 | G35: 郑熙芸 | H35: 在读 | I35: 三期 | J35: 4632447 | K35: 校内成绩 | L35: 62 | M35: 83 | N35: 田雨涵01 | O35: 教室5 | P35: 10:20-12:30 | Q35: 潜能班 | R35: 三期 | S35: 在读 | T35: - | U35: 5111226 | W35: 李润 | X35: 教室5 | Y35: 15:50-18:00 | Z35: 潜能班 | AA35: 三期 | AB35: 在读 | AC35: - | AD35: 4513388 | AF35: 肖锐03 | AG35: 教室5 | AH35: 13:20-15:30 | AI35: 潜能班 | AJ35: 三期 | AK35: 在读 | AL35: -
A36: 同创汇 | B36: 2446527834 | C36: 黄蔚羚 | D36: 戎凯01 | E36: 纯拉新 | H36: 在读 | I36: 一期 | J36: 5230802 | K36: 校内成绩 | L36: 85 | M36: 95 | N36: 田雨涵01 | O36: 02彩虹桥 | P36: 15:50-18:00 | Q36: 潜能班 | R36: 一期 | S36: 在读 | T36: - | U36: 4632448 | W36: 陈南05 | X36: 02彩虹桥 | Y36: 10:20-12:30 | Z36: 潜能班 | AA36: 一期 | AB36: 在读 | AC36: - | AD36: 3132837 | AF36: 高心怡04 | AG36: 02彩虹桥 | AH36: 13:20-15:30 | AI36: 潜能班 | AJ36: 一期 | AK36: 在读 | AL36: -
A37: 同创汇 | B37: 4834944316 | C37: 杨晨谦 | D37: 苏丽婷 | E37: 纯拉新 | H37: 在读 | I37: 一期 | J37: 5230802 | K37: 校内成绩 | L37: 72 | M37: 90 | N37: 田雨涵01 | O37: 02彩虹桥 | P37: 15:50-18:00 | Q37: 潜能班 | R37: 一期 | S37: 在读 | T37: - | U37: 4632448 | W37: 陈南05 | X37: 02彩虹桥 | Y37: 10:20-12:30 | Z37: 潜能班 | AA37: 一期 | AB37: 在读 | AC37: - | AD37: 3132837 | AF37: 高心怡04 | AG37: 02彩虹桥 | AH37: 13:20-15:30 | AI37: 潜能班 | AJ37: 一期 | AK37: 在读 | AL37: -
A38: 新宝利 | B38: 4857845454 | C38: 李梓滔 | D38: 林志豪01 | E38: 纯拉新 | H38: 在读 | I38: 三期 | J38: 5111035 | K38: 报前测成绩 | L38: 95 | M38: - | N38: 何咏04 | O38: 教室2 | P38: 15:50-18:00 | Q38: 启能班 | R38: 三期 | S38: 在读 | T38: - | U38: 5230747 | W38: 陈南05 | X38: 教室3 | Y38: 10:20-12:30 | Z38: 潜能班 | AA38: 三期 | AB38: 在读 | AC38: - | AD38: 4513388 | AF38: 肖锐03 | AG38: 教室5 | AH38: 13:20-15:30 | AI38: 潜能班 | AJ38: 三期 | AK38: 在读 | AL38: -
A39: 新宝利 | B39: 4834953191 | C39: 陈昊璟 | D39: 张敏烨 | E39: 新生转介绍 | G39: 崔梓莹 | H39: 在读 | I39: 三期 | J39: 4632447 | K39: 校内成绩 | L39: 64 | M39: 85 | N39: 田雨涵01 | O39: 教室5 | P39: 10:20-12:30 | Q39: 潜能班 | R39: 三期 | S39: 在读 | T39: - | U39: 5111226 | W39: 李润 | X39: 教室5 | Y39: 15:50-18:00 | Z39: 潜能班 | AA39: 三期 | AB39: 在读 | AC39: - | AD39: 4513388 | AF39: 肖锐03 | AG39: 教室5 | AH39: 13:20-15:30 | AI39: 潜能班 | AJ39: 三期 | AK39: 在读 | AL39: -
A40: 同创汇 | B40: 2170843710 | C40: 黄乐怡 | D40: 王丽 | E40: 纯拉新 | H40: 在读 | I40: 二期 | J40: 3132872 | K40: 校内成绩 | L40: 74 | M40: 92 | N40: 何咏04 | O40: 01智慧林 | P40: 13:20-15:30 | Q40: 潜能班 | R40: 二期 | S40: 在读 | T40: - | U40: 5230809 | W40: 李润 | X40: 01智慧林 | Y40: 10:20-12:30 | Z40: 潜能班 | AA40: 二期 | AB40: 在读 | AC40: - | AD40: 3132893 | AF40: 刘希子 | AG40: 01智慧林 | AH40: 15:50-18:00 | AI40: 潜能班 | AJ40: 二期 | AK40: 在读 | AL40: -
...

Sheet 零期·UV电访分配
A1: 教学点 | B1: 学生uid | C1: 学生姓名 | D1: 归属顾问 | E1: 雪球思维 | J1: 悦读创作 | N1: 双语素养 | R1: 课前家长会-老师（T-2） | U1: 首课电联老师 | AA1: 课中家长会-老师&顾问（T4～T7） | AE1: 学员情况-顾问 | AH1: 课前电访-顾问（T-2） | AJ1: 首课电访（U3）-顾问 | AL1: 意向盘点（U3）-顾问&老师 | AQ1: 满意度调查（U4）-顾问 | AR1: 意向校准（U5）-顾问 | AS1: 在读 | AT1: 应续 | AU1: 数 | AV1: 语 | AW1: 英 | AX1: 已续 | AY1: 未续报卡点-顾问
E2: 主讲 | F2: 上课时段 | G2: 班型 | H2: 期次 | I2: 是否在读 | J2: 主讲 | K2: 上课时段 | L2: 期次 | M2: 是否在读 | N2: 主讲 | O2: 上课时段 | P2: 期次 | Q2: 是否在读 | R2: 邀约人 | S2: 课前诺访 | T2: 课前确访 | U2: U1 | W2: U2 | Y2: U3 | AA2: 邀约人（U4） | AB2: 课中诺访 | AC2: 现场跟进人 | AD2: 到场情况 | AE2: 顾问 | AF2: 介绍人 | AG2: 中签学校 | AH2: 是否VIP群 | AI2: 电访记录 | AJ2: 电访记录 | AK2: 核心诉求 | AL2: 学员意向 | AM2: 数学 | AN2: 语文 | AO2: 英语 | AP2: 判定依据 | AQ2: 是否参与 | AR2: 校准依据 | AS2: =SUM(AS3:AS130) | AT2: =SUM(AT3:AT130) | AU2: =COUNTIF(AU3:AU130,"是") | AV2: =COUNTIF(AV3:AV130,"是") | AW2: =COUNTIF(AW3:AW130,"是") | AX2: =SUM(AX3:AX130) | AY2: （U3～U4） | AZ2: （T6～T7） | BA2: （U8～U10）
A3: 同创汇 | B3: 4067487942 | C3: =VLOOKUP(B3,'UV台帐'!B:AL,2,0) | D3: =VLOOKUP(B3,'UV台帐'!B:AL,3,0) | E3: =VLOOKUP(B3,'UV台帐'!B:AL,13,0) | F3: =VLOOKUP(B3,'UV台帐'!B:AL,15,0) | G3: =VLOOKUP(B3,'UV台帐'!B:AL,16,0) | H3: =VLOOKUP(B3,'UV台帐'!B:AL,17,0) | I3: =VLOOKUP(B3,'UV台帐'!B:AL,18,0) | J3: =VLOOKUP(B3,'UV台帐'!B:AL,22,0) | K3: =VLOOKUP(B3,'UV台帐'!B:AL,24,0) | L3: =VLOOKUP(B3,'UV台帐'!B:AL,26,0) | M3: =VLOOKUP(B3,'UV台帐'!B:AL,27,0) | N3: =VLOOKUP(B3,'UV台帐'!B:AL,31,0) | O3: =VLOOKUP(B3,'UV台帐'!B:AL,33,0) | P3: =VLOOKUP(B3,'UV台帐'!B:AL,35,0) | Q3: =VLOOKUP(B3,'UV台帐'!B:AL,36,0) | S3: 否 | T3: 否 | W3: 李润,高心怡04 | AA3: 李润 | AB3: 是 | AC3: 陈中帅 | AD3: 是 | AE3: 戎凯01 | AF3: =VLOOKUP(B3,'UV台帐'!B:G,6,0) | AH3: 是 | AJ3: 未接2 | AK3: 未接2 | AL3: S | AO3: S | AS3: =COUNTIFS(H3,"零期",I3,"在读")+COUNTIFS(L3,"零期",M3,"在读")+COUNTIFS(P3,"零期",Q3,"在读") | AT3: =AS3-AX3 | AU3: =VLOOKUP(B3,'UV台帐'!B:AL,19,0) | AV3: =VLOOKUP(B3,'UV台帐'!B:AL,28,0) | AW3: =VLOOKUP(B3,'UV台帐'!B:AL,37,0) | AX3: =COUNTIFS(H3,"零期",AU3,"是")+COUNTIFS(L3,"零期",AV3,"是")+COUNTIFS(P3,"零期",AW3,"是") | AZ3: 没人聊上，妈妈是决策人，听完讲座就走了。
A4: 新宝利 | B4: 2136468815 | C4: =VLOOKUP(B4,'UV台帐'!B:AL,2,0) | D4: =VLOOKUP(B4,'UV台帐'!B:AL,3,0) | E4: =VLOOKUP(B4,'UV台帐'!B:AL,13,0) | F4: =VLOOKUP(B4,'UV台帐'!B:AL,15,0) | G4: =VLOOKUP(B4,'UV台帐'!B:AL,16,0) | H4: =VLOOKUP(B4,'UV台帐'!B:AL,17,0) | I4: =VLOOKUP(B4,'UV台帐'!B:AL,18,0) | J4: =VLOOKUP(B4,'UV台帐'!B:AL,22,0) | K4: =VLOOKUP(B4,'UV台帐'!B:AL,24,0) | L4: =VLOOKUP(B4,'UV台帐'!B:AL,26,0) | M4: =VLOOKUP(B4,'UV台帐'!B:AL,27,0) | N4: =VLOOKUP(B4,'UV台帐'!B:AL,31,0) | O4: =VLOOKUP(B4,'UV台帐'!B:AL,33,0) | P4: =VLOOKUP(B4,'UV台帐'!B:AL,35,0) | Q4: =VLOOKUP(B4,'UV台帐'!B:AL,36,0) | S4: 是 | T4: 是 | W4: 田雨涵01 | Y4: 李润 | AA4: 田雨涵01 | AB4: 是 | AC4: 龙倩敏 | AD4: 是 | AE4: 王达04 | AF4: =VLOOKUP(B4,'UV台帐'!B:G,6,0) | AG4: 二中 | AH4: 是 | AI4: 没问题，已建群， | AJ4: 妈妈表示不知道孩子在校区真正学的怎么样，昨天网上爸爸看了一下孩子的作业错的还是比较多的，孩子回家之后不愿意复习预习，妈妈希望老师可以给孩子下任务（例如单词要记下来多少个，第二天如果有错误的话＋作业等等），家长好像也不知道孩子的课前测和课后作业得分，妈妈表示孩子比较容易分神需要多做提醒，和让孩子做第一排，之前有上过突破教育，上过语文的一对一，没有效果， | AK4: 妈妈表示不知道孩子在校区真正学的怎么样，昨天网上爸爸看了一下孩子的作业错的还是比较多的，孩子回家之后不愿意复习预习，妈妈希望老师可以给孩子下任务（例如单词要记下来多少个，第二天如果有错误的话＋作业等等），家长好像也不知道孩子的课前测和课后作业得分，妈妈表示孩子比较容易分神需要多做提醒，和让孩子做第一排，之前有上过突破教育，上过语文的一对一，没有效果， | AL4: B | AM4: B | AN4: B | AO4: B | AP4: 肖锐老师判定B，孩子学习课次表现上有上升，家长回复量偏少，但是孩子课堂意愿比较好。 | AS4: =COUNTIFS(H4,"零期",I4,"在读")+COUNTIFS(L4,"零期",M4,"在读")+COUNTIFS(P4,"零期",Q4,"在读") | AT4: =AS4-AX4 | AU4: =VLOOKUP(B4,'UV台帐'!B:AL,19,0) | AV4: =VLOOKUP(B4,'UV台帐'!B:AL,28,0) | AW4: =VLOOKUP(B4,'UV台帐'!B:AL,37,0) | AX4: =COUNTIFS(H4,"零期",AU4,"是")+COUNTIFS(L4,"零期",AV4,"是")+COUNTIFS(P4,"零期",AW4,"是") | AZ4: 今晚答复，卡点机构对比，不自信，担心学不好，成绩中上。
A5: 同创汇 | B5: 2163375170 | C5: =VLOOKUP(B5,'UV台帐'!B:AL,2,0) | D5: =VLOOKUP(B5,'UV台帐'!B:AL,3,0) | E5: =VLOOKUP(B5,'UV台帐'!B:AL,13,0) | F5: =VLOOKUP(B5,'UV台帐'!B:AL,15,0) | G5: =VLOOKUP(B5,'UV台帐'!B:AL,16,0) | H5: =VLOOKUP(B5,'UV台帐'!B:AL,17,0) | I5: =VLOOKUP(B5,'UV台帐'!B:AL,18,0) | J5: =VLOOKUP(B5,'UV台帐'!B:AL,22,0) | K5: =VLOOKUP(B5,'UV台帐'!B:AL,24,0) | L5: =VLOOKUP(B5,'UV台帐'!B:AL,26,0) | M5: =VLOOKUP(B5,'UV台帐'!B:AL,27,0) | N5: =VLOOKUP(B5,'UV台帐'!B:AL,31,0) | O5: =VLOOKUP(B5,'UV台帐'!B:AL,33,0) | P5: =VLOOKUP(B5,'UV台帐'!B:AL,35,0) | Q5: =VLOOKUP(B5,'UV台帐'!B:AL,36,0) | S5: 是 | T5: 是 | U5: 田雨涵01,黄铭怡 | AA5: 田雨涵01 | AB5: 是 | AC5: 玉玲 | AD5: 是 | AE5: 王丽 | AF5: =VLOOKUP(B5,'UV台帐'!B:G,6,0) | AH5: 是 | AI5: 数学想要上大帅的班，对换师不满，数学从中帅换博闻现在换路涵老师 | AJ5: 孩子爸爸的电话，孩子妈妈管学习，第一天连续上三科孩子太疲惫了，英语调一期上课去了，孩子状态没那么好的话配合度就没那么高，说后面也会考虑秋季，每次续报都是哥哥给钱的 | AK5: 孩子爸爸的电话，孩子妈妈管学习，第一天连续上三科孩子太疲惫了，英语调一期上课去了，孩子状态没那么好的话配合度就没那么高，说后面也会考虑秋季，每次续报都是哥哥给钱的 | AL5: S | AM5: A | AP5: 数学：孩子学习态度有问题，有主动问秋季课的事情 | AQ5: 是 | AR5: 0期数学语文，1期英语；满意度调查，明确一定会报读；所以学员整体意向是S；在前台有明确咨询过课程，目前是时间异议比较大，希望AB上完数学和语文，但是目前没法协调时间。 | AS5: =COUNTIFS(H5,"零期",I5,"在读")+COUNTIFS(L5,"零期",M5,"在读")+COUNTIFS(P5,"零期",Q5,"在读") | AT5: =AS5-AX5 | AU5: =VLOOKUP(B5,'UV台帐'!B:AL,19,0) | AV5: 是 | AW5: =VLOOKUP(B5,'UV台帐'!B:AL,37,0) | AX5: 2 | AZ5: 已转化
A6: 新宝利 | B6: 2207027530 | C6: =VLOOKUP(B6,'UV台帐'!B:AL,2,0) | D6: =VLOOKUP(B6,'UV台帐'!B:AL,3,0) | E6: =VLOOKUP(B6,'UV台帐'!B:AL,13,0) | F6: =VLOOKUP(B6,'UV台帐'!B:AL,15,0) | G6: =VLOOKUP(B6,'UV台帐'!B:AL,16,0) | H6: =VLOOKUP(B6,'UV台帐'!B:AL,17,0) | I6: =VLOOKUP(B6,'UV台帐'!B:AL,18,0) | J6: =VLOOKUP(B6,'UV台帐'!B:AL,22,0) | K6: =VLOOKUP(B6,'UV台帐'!B:AL,24,0) | L6: =VLOOKUP(B6,'UV台帐'!B:AL,26,0) | M6: =VLOOKUP(B6,'UV台帐'!B:AL,27,0) | N6: =VLOOKUP(B6,'UV台帐'!B:AL,31,0) | O6: =VLOOKUP(B6,'UV台帐'!B:AL,33,0) | P6: =VLOOKUP(B6,'UV台帐'!B:AL,35,0) | Q6: =VLOOKUP(B6,'UV台帐'!B:AL,36,0) | S6: 是 | T6: 是 | W6: 田雨涵01,肖锐03 | AA6: 肖锐03 | AB6: 是 | AC6: 杨林 | AD6: 是 | AE6: 杨林33 | AF6: =VLOOKUP(B6,'UV台帐'!B:G,6,0) | AG6: 三中 | AH6: 是 | AI6: 7.3日时间冲突，有长期学习的想法 | AJ6: 课程感知不错，配合度高，有长期学习的想法，支付能力待定 | AK6: 课程感知不错，配合度高，有长期学习的想法，支付能力待定 | AL6: A | AM6: A | AN6: A | AO6: C | AP6: 课程感知不错，配合度高，有长期学习的想法，价格有部分异议 | AQ6: 是 | AR6: 满意度调查对三科满意度不错，但是也表示上课不久，体验感不明显；不清楚孩子目前的兴趣情况；建议老师引导孩子主动回家反馈假期学习状况，有助于家长对于机构的信任建立；意向有机会A升S。家长明确说了价格偏贵，哪怕填写还在犹豫，说明也有一定的续报考虑。 | AS6: =COUNTIFS(H6,"零期",I6,"在读")+COUNTIFS(L6,"零期",M6,"在读")+COUNTIFS(P6,"零期",Q6,"在读") | AT6: =AS6-AX6 | AU6: =VLOOKUP(B6,'UV台帐'!B:AL,19,0) | AV6: =VLOOKUP(B6,'UV台帐'!B:AL,28,0) | AW6: =VLOOKUP(B6,'UV台帐'!B:AL,37,0) | AX6: =COUNTIFS(H6,"零期",AU6,"是")+COUNTIFS(L6,"零期",AV6,"是")+COUNTIFS(P6,"零期",AW6,"是") | AZ6: 报一科，英语大概率不报
A7: 同创汇 | B7: 2225312488 | C7: =VLOOKUP(B7,'UV台帐'!B:AL,2,0) | D7: =VLOOKUP(B7,'UV台帐'!B:AL,3,0) | E7: =VLOOKUP(B7,'UV台帐'!B:AL,13,0) | F7: =VLOOKUP(B7,'UV台帐'!B:AL,15,0) | G7: =VLOOKUP(B7,'UV台帐'!B:AL,16,0) | H7: =VLOOKUP(B7,'UV台帐'!B:AL,17,0) | I7: =VLOOKUP(B7,'UV台帐'!B:AL,18,0) | J7: =VLOOKUP(B7,'UV台帐'!B:AL,22,0) | K7: =VLOOKUP(B7,'UV台帐'!B:AL,24,0) | L7: =VLOOKUP(B7,'UV台帐'!B:AL,26,0) | M7: =VLOOKUP(B7,'UV台帐'!B:AL,27,0) | N7: =VLOOKUP(B7,'UV台帐'!B:AL,31,0) | O7: =VLOOKUP(B7,'UV台帐'!B:AL,33,0) | P7: =VLOOKUP(B7,'UV台帐'!B:AL,35,0) | Q7: =VLOOKUP(B7,'UV台帐'!B:AL,36,0) | S7: 是 | T7: 是 | U7: 田雨涵01 | AA7: 陈南05 | AB7: 是 | AC7: 天宝 | AD7: 是 | AE7: 王丽 | AF7: =VLOOKUP(B7,'UV台帐'!B:G,6,0) | AG7: 民办，龙涛 | AH7: 是 | AI7: 正常上课 | AJ7: 妈妈说孩子之前都没有补习过，孩子白云过来，需要1.5小时，说只考虑寒暑假，秋季没打算，7.13开始学校那边也会组织预习，开始学新初一内容。家长觉得孩子懒 | AK7: 妈妈说孩子之前都没有补习过，孩子白云过来，需要1.5小时，说只考虑寒暑假，秋季没打算，7.13开始学校那边也会组织预习，开始学新初一内容。家长觉得孩子懒 | AL7: B | AM7: B | AN7: C | AO7: B | AP7: 住白云，孩子基础较弱 | AS7: =COUNTIFS(H7,"零期",I7,"在读")+COUNTIFS(L7,"零期",M7,"在读")+COUNTIFS(P7,"零期",Q7,"在读") | AT7: =AS7-AX7 | AU7: =VLOOKUP(B7,'UV台帐'!B:AL,19,0) | AV7: =VLOOKUP(B7,'UV台帐'!B:AL,28,0) | AW7: =VLOOKUP(B7,'UV台帐'!B:AL,37,0) | AX7: =COUNTIFS(H7,"零期",AU7,"是")+COUNTIFS(L7,"零期",AV7,"是")+COUNTIFS(P7,"零期",AW7,"是") | AZ7: 孩子初中的私立学校比较严格，周末不一定放假，周日中午吃完饭便要回校，其次是怕学校的作业太多，孩子无法完成，再安排补课的话孩子会产生逆反心理，因此需要看秋季开课学校的情况之后再考虑；
A8: 同创汇 | B8: 2234603980 | C8: =VLOOKUP(B8,'UV台帐'!B:AL,2,0) | D8: =VLOOKUP(B8,'UV台帐'!B:AL,3,0) | E8: =VLOOKUP(B8,'UV台帐'!B:AL,13,0) | F8: =VLOOKUP(B8,'UV台帐'!B:AL,15,0) | G8: =VLOOKUP(B8,'UV台帐'!B:AL,16,0) | H8: =VLOOKUP(B8,'UV台帐'!B:AL,17,0) | I8: =VLOOKUP(B8,'UV台帐'!B:AL,18,0) | J8: =VLOOKUP(B8,'UV台帐'!B:AL,22,0) | K8: =VLOOKUP(B8,'UV台帐'!B:AL,24,0) | L8: =VLOOKUP(B8,'UV台帐'!B:AL,26,0) | M8: =VLOOKUP(B8,'UV台帐'!B:AL,27,0) | N8: =VLOOKUP(B8,'UV台帐'!B:AL,31,0) | O8: =VLOOKUP(B8,'UV台帐'!B:AL,33,0) | P8: =VLOOKUP(B8,'UV台帐'!B:AL,35,0) | Q8: =VLOOKUP(B8,'UV台帐'!B:AL,36,0) | S8: 是 | T8: 否 | U8: 刘希子 | Y8: 田雨涵01 | AA8: 刘希子 | AB8: 是 | AC8: 刘晨 | AD8: 是 | AE8: 戎凯01 | AF8: =VLOOKUP(B8,'UV台帐'!B:G,6,0) | AG8: 广附 | AH8: 是 | AI8: 可正常来上课 | AJ8: 妈妈这边还是比较满意，没有过多的提需，还是要看孩子整体的学习情况和后续的安排在做决定，先发价格和时间给家长做参考，目前在考虑秋季班 需求：家长想了解秋季及未来学习规划和秋季的时间安排； 希子老师：孩子容易开小差； | AK8: 妈妈这边还是比较满意，没有过多的提需，还是要看孩子整体的学习情况和后续的安排在做决定，先发价格和时间给家长做参考，目前在考虑秋季班 需求：家长想了解秋季及未来学习规划和秋季的时间安排； 希子老师：孩子容易开小差； | AL8: S | AM8: S | AN8: S | AO8: B | AS8: =COUNTIFS(H8,"零期",I8,"在读")+COUNTIFS(L8,"零期",M8,"在读")+COUNTIFS(P8,"零期",Q8,"在读") | AT8: =AS8-AX8 | AU8: =VLOOKUP(B8,'UV台帐'!B:AL,19,0) | AV8: =VLOOKUP(B8,'UV台帐'!B:AL,28,0) | AW8: =VLOOKUP(B8,'UV台帐'!B:AL,37,0) | AX8: =COUNTIFS(H8,"零期",AU8,"是")+COUNTIFS(L8,"零期",AV8,"是")+COUNTIFS(P8,"零期",AW8,"是") | AZ8: 已报名
A9: 同创汇 | B9: 2270640709 | C9: =VLOOKUP(B9,'UV台帐'!B:AL,2,0) | D9: =VLOOKUP(B9,'UV台帐'!B:AL,3,0) | E9: =VLOOKUP(B9,'UV台帐'!B:AL,13,0) | F9: =VLOOKUP(B9,'UV台帐'!B:AL,15,0) | G9: =VLOOKUP(B9,'UV台帐'!B:AL,16,0) | H9: =VLOOKUP(B9,'UV台帐'!B:AL,17,0) | I9: =VLOOKUP(B9,'UV台帐'!B:AL,18,0) | J9: =VLOOKUP(B9,'UV台帐'!B:AL,22,0) | K9: =VLOOKUP(B9,'UV台帐'!B:AL,24,0) | L9: =VLOOKUP(B9,'UV台帐'!B:AL,26,0) | M9: =VLOOKUP(B9,'UV台帐'!B:AL,27,0) | N9: =VLOOKUP(B9,'UV台帐'!B:AL,31,0) | O9: =VLOOKUP(B9,'UV台帐'!B:AL,33,0) | P9: =VLOOKUP(B9,'UV台帐'!B:AL,35,0) | Q9: =VLOOKUP(B9,'UV台帐'!B:AL,36,0) | S9: 是 | T9: 是 | U9: 高心怡04 | AA9: 高心怡04 | AB9: 是 | AC9: 戎凯 | AD9: 是 | AE9: 戎凯01 | AF9: =VLOOKUP(B9,'UV台帐'!B:G,6,0) | AG9: 育才实验 | AH9: 是 | AI9: 可正常来上课 | AJ9: 希望孩子在笔记中比标记好重点，做作业方面准确度提升，作业完成不好的，可以适当留堂，考虑语文英语两科，需要问孩子意见，主要担心一天三节课，孩子不接受，又担心孩子初中压力大。 | AK9: 希望孩子在笔记中比标记好重点，做作业方面准确度提升，作业完成不好的，可以适当留堂，考虑语文英语两科，需要问孩子意见，主要担心一天三节课，孩子不接受，又担心孩子初中压力大。 | AL9: S | AO9: A | AS9: =COUNTIFS(H9,"零期",I9,"在读")+COUNTIFS(L9,"零期",M9,"在读")+COUNTIFS(P9,"零期",Q9,"在读") | AT9: =AS9-AX9 | AU9: =VLOOKUP(B9,'UV台帐'!B:AL,19,0) | AV9: =VLOOKUP(B9,'UV台帐'!B:AL,28,0) | AW9: =VLOOKUP(B9,'UV台帐'!B:AL,37,0) | AX9: =COUNTIFS(H9,"零期",AU9,"是")+COUNTIFS(L9,"零期",AV9,"是")+COUNTIFS(P9,"零期",AW9,"是") | AZ9: 已报名
A10: 新宝利 | B10: 2271507248 | C10: =VLOOKUP(B10,'UV台帐'!B:AL,2,0) | D10: =VLOOKUP(B10,'UV台帐'!B:AL,3,0) | E10: =VLOOKUP(B10,'UV台帐'!B:AL,13,0) | F10: =VLOOKUP(B10,'UV台帐'!B:AL,15,0) | G10: =VLOOKUP(B10,'UV台帐'!B:AL,16,0) | H10: =VLOOKUP(B10,'UV台帐'!B:AL,17,0) | I10: =VLOOKUP(B10,'UV台帐'!B:AL,18,0) | J10: =VLOOKUP(B10,'UV台帐'!B:AL,22,0) | K10: =VLOOKUP(B10,'UV台帐'!B:AL,24,0) | L10: =VLOOKUP(B10,'UV台帐'!B:AL,26,0) | M10: =VLOOKUP(B10,'UV台帐'!B:AL,27,0) | N10: =VLOOKUP(B10,'UV台帐'!B:AL,31,0) | O10: =VLOOKUP(B10,'UV台帐'!B:AL,33,0) | P10: =VLOOKUP(B10,'UV台帐'!B:AL,35,0) | Q10: =VLOOKUP(B10,'UV台帐'!B:AL,36,0) | S10: 是 | T10: 是 | AA10: 李润 | AB10: 是 | AC10: 沈源 | AD10: 是 | AE10: 王达04 | AF10: =VLOOKUP(B10,'UV台帐'!B:G,6,0) | AG10: 广园 | AH10: 是 | AI10: 没问题，已建群 | AJ10: 表示每天上课回来看30分钟视频哄着，孩子之前从一年级到五年级都有补习，之前在新东方上过一年半，后面孩子不愿意补习，坚持不下来，妈妈现在有买到一个线上的打卡课程（视频课+阶段测），孩子这两天回家都说不想来，说不想一整天都在校区，表示在家里也可以学，妈妈表示暂时没有意见，但表示可以多关注一下孩子，以及孩子的笔记情况因为发现孩子不认真和认真说做的笔记区别很大，不认真的很潦草家长表示不知道孩子的课前测成绩 | AK10: 表示每天上课回来看30分钟视频哄着，孩子之前从一年级到五年级都有补习，之前在新东方上过一年半，后面孩子不愿意补习，坚持不下来，妈妈现在有买到一个线上的打卡课程（视频课+阶段测），孩子这两天回家都说不想来，说不想一整天都在校区，表示在家里也可以学，妈妈表示暂时没有意见，但表示可以多关注一下孩子，以及孩子的笔记情况因为发现孩子不认真和认真说做的笔记区别很大，不认真的很潦草家长表示不知道孩子的课前测成绩 | AL10: B | AM10: B | AN10: B | AO10: B | AP10: 中帅老师：判定B，之前有上补习班，线上补习妈妈也有安排，有学习规划也有支付能力 就是学习兴趣方面需要提高。肖锐老师判定A,孩子课堂的表现是会比较积极 | AQ10: 是 | AR10: 满意度调查，对于三科老师均打4分的体感；并且对于暑期课程满意度整体表示一般。在建议/意见栏，明确提出——课程反馈有点草率，我想了解孩子学的题目熟悉到哪个程度，比如哪方面还欠佳的，在课堂上还没搞清楚的，要求家长在家做怎样的配合 | AS10: =COUNTIFS(H10,"零期",I10,"在读")+COUNTIFS(L10,"零期",M10,"在读")+COUNTIFS(P10,"零期",Q10,"在读") | AT10: =AS10-AX10 | AU10: =VLOOKUP(B10,'UV台帐'!B:AL,19,0) | AV10: =VLOOKUP(B10,'UV台帐'!B:AL,28,0) | AW10: =VLOOKUP(B10,'UV台帐'!B:AL,37,0) | AX10: =COUNTIFS(H10,"零期",AU10,"是")+COUNTIFS(L10,"零期",AV10,"是")+COUNTIFS(P10,"零期",AW10,"是") | AZ10: 报2科数学英语，语文暂时不报，需要语文老师关注 追单，搞定孩子
A11: 新宝利 | B11: 2305874638 | C11: =VLOOKUP(B11,'UV台帐'!B:AL,2,0) | D11: =VLOOKUP(B11,'UV台帐'!B:AL,3,0) | E11: =VLOOKUP(B11,'UV台帐'!B:AL,13,0) | F11: =VLOOKUP(B11,'UV台帐'!B:AL,15,0) | G11: =VLOOKUP(B11,'UV台帐'!B:AL,16,0) | H11: =VLOOKUP(B11,'UV台帐'!B:AL,17,0) | I11: =VLOOKUP(B11,'UV台帐'!B:AL,18,0) | J11: =VLOOKUP(B11,'UV台帐'!B:AL,22,0) | K11: =VLOOKUP(B11,'UV台帐'!B:AL,24,0) | L11: =VLOOKUP(B11,'UV台帐'!B:AL,26,0) | M11: =VLOOKUP(B11,'UV台帐'!B:AL,27,0) | N11: =VLOOKUP(B11,'UV台帐'!B:AL,31,0) | O11: =VLOOKUP(B11,'UV台帐'!B:AL,33,0) | P11: =VLOOKUP(B11,'UV台帐'!B:AL,35,0) | Q11: =VLOOKUP(B11,'UV台帐'!B:AL,36,0) | S11: 是 | T11: 否 | AA11: 肖锐03 | AB11: 是 | AC11: 已转化 | AD11: 是 | AE11: 张敏烨 | AF11: =VLOOKUP(B11,'UV台帐'!B:G,6,0) | AH11: 是 | AI11: 未接，已留言 | AJ11: 已转化 | AK11: 已转化 | AQ11: 是 | AS11: =COUNTIFS(H11,"零期",I11,"在读")+COUNTIFS(L11,"零期",M11,"在读")+COUNTIFS(P11,"零期",Q11,"在读") | AT11: =AS11-AX11 | AU11: =VLOOKUP(B11,'UV台帐'!B:AL,19,0) | AV11: =VLOOKUP(B11,'UV台帐'!B:AL,28,0) | AW11: =VLOOKUP(B11,'UV台帐'!B:AL,37,0) | AX11: =COUNTIFS(H11,"零期",AU11,"是")+COUNTIFS(L11,"零期",AV11,"是")+COUNTIFS(P11,"零期",AW11,"是")
