Workbook

Sheet 新初一数据看板
B2: 暑假整体汇总 | D2: =SUM(D4:D16)/2 | E2: =E8+E12+E16 | F2: =E2/(25*D2) | G2: =G8+G12+G16 | H2: =G2/E2 | I2: =SUM(I4:I16)/2 | J2: =I2/(E2+I2) | K2: =(K8*$E$8+K12*$E$12+K16*$E$16)/$E$2 | L2: =(L8*$E$8+L12*$E$12+L16*$E$16)/$E$2 | M2: =(M8*$E$8+M12*$E$12+M16*$E$16)/$E$2 | O2: 一期顾问转化合计 | Q2: =Q8+Q12+Q16 | R2: =SUM(R4:R16)/2 | S2: =Q2-R2 | T2: =S2*55% | U2: =SUM(U4:U16)/2 | V2: =U2/S2 | W2: =U2/T2 | X2: 学员意向分层(UV) | AL2: 零期顾问转化合计 | AN2: =AN8+AN12+AN16 | AO2: =SUM(AO4:AO16)/2 | AP2: =AN2-AO2 | AQ2: =AP2*55% | AR2: =SUM(AR4:AR16)/2 | AS2: =AR2/AP2 | AT2: =AR2/AQ2
B3: 老师看板 | C3: 学科 | D3: 班量 | E3: 在读PV | F3: 满班率 | G3: 暑续秋PV | H3: 转化率 | I3: 课前退PV | J3: 课前退率 | K3: 加微率 | L3: 首联率 | M3: vip入群率 | O3: 所属校区 | P3: 顾问 | Q3: 一期总PV | R3: 已转PV | S3: 应转PV | T3: 转化目标 | U3: 实际转化PV | V3: 实际转化率 | W3: 达成率 | X3: S | Y3: 占比 | Z3: A | AA3: 占比 | AB3: B | AC3: 占比 | AD3: C | AE3: 占比 | AL3: 所属校区 | AM3: 顾问 | AN3: 零期总PV | AO3: 已转PV | AP3: 应转PV | AQ3: 转化目标 | AR3: 实际转化PV | AS3: 实际转化率 | AT3: 达成率
B4: 陈中帅 | C4: 数学 | D4: 7 | E4: =COUNTIFS('UV台帐'!N:N,B4,'UV台帐'!S:S,"在读") | F4: =E4/(D4*25) | G4: =SUMPRODUCT(('UV台帐'!N:N=B4)*('UV台帐'!T:T="是")) | H4: =G4/E4 | I4: =COUNTIFS('UV台帐'!N:N,B4,'UV台帐'!S:S,"课前退") | J4: =I4/(E4+I4) | K4: =COUNTIF('陈中帅'!T:T,"是")/E4 | L4: =COUNTIF('陈中帅'!U:U,"是")/E4 | M4: =COUNTIF('陈中帅'!V:V,"是")/E4 | O4: 天成 | P4: 陈亮延 | Q4: =SUMIF('一期·UV电访分配'!BF:BF,P4,'一期·UV电访分配'!BR:ATS) | R4: 0 | S4: =Q4-R4 | T4: =S4*55% | U4: =SUMIF('一期·UV电访分配'!BF:BF,P4,'一期·UV电访分配'!BW:BW)-R4 | V4: =U4/S4 | W4: =U4/T4 | X4: =COUNTIFS('一期·UV电访分配'!BF:BF,P4,'一期·UV电访分配'!AJ:AJ,"*S*") | Y4: =X4/(Z4+AB4+AD4+X4) | Z4: =COUNTIFS('一期·UV电访分配'!BF:BF,P4,'一期·UV电访分配'!AJ:AJ,"*A*") | AA4: =Z4/(Z4+AB4+AD4+X4) | AB4: =COUNTIFS('一期·UV电访分配'!BF:BF,P4,'一期·UV电访分配'!AJ:AJ,"*B*") | AC4: =AB4/(Z4+AB4+AD4+X4) | AD4: =COUNTIFS('一期·UV电访分配'!BF:BF,P4,'一期·UV电访分配'!AJ:AJ,"*C*") | AE4: =AD4/(Z4+AB4+AD4+X4) | AL4: 天成 | AM4: 陈亮延 | AN4: =SUMIF('零期·UV电访分配'!AE:AE,AM4,'零期·UV电访分配'!AS:AS) | AP4: =AN4-AO4 | AQ4: =AP4*55% | AR4: =SUMIF('零期·UV电访分配'!AE:AE,AM4,'零期·UV电访分配'!AX:AX)-AO4 | AS4: =AR4/AP4 | AT4: =AR4/AQ4
B5: 何咏04 | C5: 数学 | D5: 4 | E5: =COUNTIFS('UV台帐'!N:N,B5,'UV台帐'!S:S,"在读") | F5: =E5/(D5*25) | G5: =SUMPRODUCT(('UV台帐'!N:N=B5)*('UV台帐'!T:T="是")) | H5: =G5/E5 | I5: =COUNTIFS('UV台帐'!N:N,B5,'UV台帐'!S:S,"课前退") | J5: =I5/(E5+I5) | K5: =COUNTIF('何咏04'!T:T,"是")/E5 | L5: =COUNTIF('何咏04'!U:U,"是")/E5 | M5: =COUNTIF('何咏04'!V:V,"是")/E5 | P5: 王达04 | Q5: =SUMIF('一期·UV电访分配'!BF:BF,P5,'一期·UV电访分配'!BR:BR) | R5: 5 | S5: =Q5-R5 | T5: =S5*55% | U5: =SUMIF('一期·UV电访分配'!BF:BF,P5,'一期·UV电访分配'!BW:BW)-R5 | V5: =U5/S5 | W5: =U5/T5 | X5: =COUNTIFS('一期·UV电访分配'!BF:BF,P5,'一期·UV电访分配'!AJ:AJ,"*S*") | Y5: =X5/(Z5+AB5+AD5+X5) | Z5: =COUNTIFS('一期·UV电访分配'!BF:BF,P5,'一期·UV电访分配'!AJ:AJ,"*A*") | AA5: =Z5/(Z5+AB5+AD5+X5) | AB5: =COUNTIFS('一期·UV电访分配'!BF:BF,P5,'一期·UV电访分配'!AJ:AJ,"*B*") | AC5: =AB5/(Z5+AB5+AD5+X5) | AD5: =COUNTIFS('一期·UV电访分配'!BF:BF,P5,'一期·UV电访分配'!AJ:AJ,"*C*") | AE5: =AD5/(Z5+AB5+AD5+X5) | AM5: 王达04 | AN5: =SUMIF('零期·UV电访分配'!AE:AE,AM5,'零期·UV电访分配'!AS:AS) | AP5: =AN5-AO5 | AQ5: =AP5*55% | AR5: =SUMIF('零期·UV电访分配'!AE:AE,AM5,'零期·UV电访分配'!AX:AX)-AO5 | AS5: =AR5/AP5 | AT5: =AR5/AQ5
B6: 田雨涵01 | C6: 数学 | D6: 5 | E6: =COUNTIFS('UV台帐'!N:N,B6,'UV台帐'!S:S,"在读") | F6: =E6/(D6*25) | G6: =SUMPRODUCT(('UV台帐'!N:N=B6)*('UV台帐'!T:T="是")) | H6: =G6/E6 | I6: =COUNTIFS('UV台帐'!N:N,B6,'UV台帐'!S:S,"课前退") | J6: =I6/(E6+I6) | K6: =COUNTIF('田雨涵01'!T:T,"是")/E6 | L6: =COUNTIF('田雨涵01'!U:U,"是")/E6 | M6: =COUNTIF('田雨涵01'!V:V,"是")/E6 | P6: 沈思浩 | Q6: =SUMIF('一期·UV电访分配'!BF:BF,P6,'一期·UV电访分配'!BR:BR) | R6: 1 | S6: =Q6-R6 | T6: =S6*55% | U6: =SUMIF('一期·UV电访分配'!BF:BF,P6,'一期·UV电访分配'!BW:BW)-R6 | V6: =U6/S6 | W6: =U6/T6 | X6: =COUNTIFS('一期·UV电访分配'!BF:BF,P6,'一期·UV电访分配'!AJ:AJ,"*S*") | Y6: =X6/(Z6+AB6+AD6+X6) | Z6: =COUNTIFS('一期·UV电访分配'!BF:BF,P6,'一期·UV电访分配'!AJ:AJ,"*A*") | AA6: =Z6/(Z6+AB6+AD6+X6) | AB6: =COUNTIFS('一期·UV电访分配'!BF:BF,P6,'一期·UV电访分配'!AJ:AJ,"*B*") | AC6: =AB6/(Z6+AB6+AD6+X6) | AD6: =COUNTIFS('一期·UV电访分配'!BF:BF,P6,'一期·UV电访分配'!AJ:AJ,"*C*") | AE6: =AD6/(Z6+AB6+AD6+X6) | AM6: 沈思浩 | AN6: =SUMIF('零期·UV电访分配'!AE:AE,AM6,'零期·UV电访分配'!AS:AS) | AO6: 2 | AP6: =AN6-AO6 | AQ6: =AP6*55% | AR6: =SUMIF('零期·UV电访分配'!AE:AE,AM6,'零期·UV电访分配'!AX:AX)-AO6 | AS6: =AR6/AP6 | AT6: =AR6/AQ6
B7: 宗志鹏 | C7: 数学 | D7: 1 | E7: =COUNTIFS('UV台帐'!N:N,B7,'UV台帐'!S:S,"在读") | F7: =E7/(D7*25) | G7: =SUMPRODUCT(('UV台帐'!N:N=B7)*('UV台帐'!T:T="是")) | H7: =G7/E7 | I7: =COUNTIFS('UV台帐'!N:N,B7,'UV台帐'!S:S,"课前退") | J7: =I7/(E7+I7) | K7: =COUNTIF('宗志鹏'!T:T,"是")/E7 | L7: =COUNTIF('宗志鹏'!U:U,"是")/E7 | M7: =COUNTIF('宗志鹏'!V:V,"是")/E7 | P7: 龙倩敏 | Q7: =SUMIF('一期·UV电访分配'!BF:BF,P7,'一期·UV电访分配'!BR:BR) | R7: 3 | S7: =Q7-R7 | T7: =S7*55% | U7: =SUMIF('一期·UV电访分配'!BF:BF,P7,'一期·UV电访分配'!BW:BW)-R7 | V7: =IFERROR(U7/S7,0) | W7: =IFERROR(U7/T7,0) | X7: =COUNTIFS('一期·UV电访分配'!BF:BF,P7,'一期·UV电访分配'!AJ:AJ,"*S*") | Y7: =IFERROR(X7/(Z7+AB7+AD7+X7),0) | Z7: =COUNTIFS('一期·UV电访分配'!BF:BF,P7,'一期·UV电访分配'!AJ:AJ,"*A*") | AA7: =IFERROR(Z7/(Z7+AB7+AD7+X7),0) | AB7: =COUNTIFS('一期·UV电访分配'!BF:BF,P7,'一期·UV电访分配'!AJ:AJ,"*B*") | AC7: =IFERROR(AB7/(Z7+AB7+AD7+X7),0) | AD7: =COUNTIFS('一期·UV电访分配'!BF:BF,P7,'一期·UV电访分配'!AJ:AJ,"*C*") | AE7: =IFERROR(AD7/(Z7+AB7+AD7+X7),0) | AM7: 龙倩敏 | AN7: =SUMIF('零期·UV电访分配'!AE:AE,AM7,'零期·UV电访分配'!AS:AS) | AP7: =AN7-AO7 | AQ7: =AP7*55% | AR7: =SUMIF('零期·UV电访分配'!AE:AE,AM7,'零期·UV电访分配'!AX:AX)-AO7 | AS7: =AR7/AP7 | AT7: =AR7/AQ7
B8: 数学合计 | D8: =SUM(D4:D7) | E8: =SUM(E4:E7) | F8: =E8/(D8*25) | G8: =SUM(G4:G7) | H8: =G8/E8 | I8: =SUM(I4:I7) | J8: =I8/(E8+I8) | K8: =(K4*$E$4+K5*$E$5+K6*$E$6+K7*$E$7)/$E$8 | L8: =(L4*$E$4+L5*$E$5+L6*$E$6+L7*$E$7)/$E$8 | M8: =(M4*$E$4+M5*$E$5+M6*$E$6+M7*$E$7)/$E$8 | O8: 合计 | Q8: =SUM(Q4:Q7) | R8: =SUM(R4:R7) | S8: =Q8-R8 | T8: =S8*55% | U8: =SUM(U4:U7) | V8: =U8/S8 | W8: =U8/T8 | X8: =SUM(X4:X7) | Y8: =X8/(Z8+AB8+AD8+X8) | Z8: =SUM(Z4:Z7) | AA8: =Z8/(Z8+AB8+AD8+X8) | AB8: =SUM(AB4:AB7) | AC8: =AB8/(Z8+AB8+AD8+X8) | AD8: =SUM(AD4:AD7) | AE8: =AD8/(Z8+AB8+AD8+X8) | AL8: 合计 | AN8: =SUM(AN4:AN7) | AO8: =SUM(AO4:AO7) | AP8: =AN8-AO8 | AQ8: =AP8*55% | AR8: =SUM(AR4:AR7) | AS8: =AR8/AP8 | AT8: =AR8/AQ8
B9: 黄铭怡 | C9: 语文 | D9: 5 | E9: =COUNTIFS('UV台帐'!W:W,B9,'UV台帐'!AB:AB,"在读") | F9: =E9/(D9*25) | G9: =SUMPRODUCT(('UV台帐'!W:W=B9)*('UV台帐'!AC:AC="是")) | H9: =G9/E9 | I9: =COUNTIFS('UV台帐'!W:W,B9,'UV台帐'!AB:AB,"课前退") | J9: =I9/(E9+I9) | K9: =COUNTIF('黄铭怡'!T:T,"是")/E9 | L9: =COUNTIF('黄铭怡'!U:U,"是")/E9 | M9: =COUNTIF('黄铭怡'!V:V,"是")/E9 | O9: 同创汇 | P9: 戎凯01 | Q9: =SUMIF('一期·UV电访分配'!BF:BF,P9,'一期·UV电访分配'!BR:BR) | R9: 8 | S9: =Q9-R9 | T9: =S9*55% | U9: =SUMIF('一期·UV电访分配'!BF:BF,P9,'一期·UV电访分配'!BW:BW)-R9 | V9: =U9/S9 | W9: =U9/T9 | X9: =COUNTIFS('一期·UV电访分配'!BF:BF,P9,'一期·UV电访分配'!AJ:AJ,"*S*") | Y9: =X9/(Z9+AB9+AD9+X9) | Z9: =COUNTIFS('一期·UV电访分配'!BF:BF,P9,'一期·UV电访分配'!AJ:AJ,"*A*") | AA9: =Z9/(Z9+AB9+AD9+X9) | AB9: =COUNTIFS('一期·UV电访分配'!BF:BF,P9,'一期·UV电访分配'!AJ:AJ,"*B*") | AC9: =AB9/(Z9+AB9+AD9+X9) | AD9: =COUNTIFS('一期·UV电访分配'!BF:BF,P9,'一期·UV电访分配'!AJ:AJ,"*C*") | AE9: =AD9/(Z9+AB9+AD9+X9) | AL9: 同创汇 | AM9: 戎凯01 | AN9: =SUMIF('零期·UV电访分配'!AE:AE,AM9,'零期·UV电访分配'!AS:AS) | AO9: 7 | AP9: =AN9-AO9 | AQ9: =AP9*55% | AR9: =SUMIF('零期·UV电访分配'!AE:AE,AM9,'零期·UV电访分配'!AX:AX)-AO9 | AS9: =AR9/AP9 | AT9: =AR9/AQ9
B10: 李润 | C10: 语文 | D10: 7 | E10: =COUNTIFS('UV台帐'!W:W,B10,'UV台帐'!AB:AB,"在读") | F10: =E10/(D10*25) | G10: =SUMPRODUCT(('UV台帐'!W:W=B10)*('UV台帐'!AC:AC="是")) | H10: =G10/E10 | I10: =COUNTIFS('UV台帐'!W:W,B10,'UV台帐'!AB:AB,"课前退") | J10: =I10/(E10+I10) | K10: =COUNTIF('李润'!T:T,"是")/E10 | L10: =COUNTIF('李润'!U:U,"是")/E10 | M10: =COUNTIF('李润'!V:V,"是")/E10 | P10: 王丽 | Q10: =SUMIF('一期·UV电访分配'!BF:BF,P10,'一期·UV电访分配'!BR:BR) | R10: 6 | S10: =Q10-R10 | T10: =S10*55% | U10: =SUMIF('一期·UV电访分配'!BF:BF,P10,'一期·UV电访分配'!BW:BW)-R10 | V10: =U10/S10 | W10: =U10/T10 | X10: =COUNTIFS('一期·UV电访分配'!BF:BF,P10,'一期·UV电访分配'!AJ:AJ,"*S*") | Y10: =X10/(Z10+AB10+AD10+X10) | Z10: =COUNTIFS('一期·UV电访分配'!BF:BF,P10,'一期·UV电访分配'!AJ:AJ,"*A*") | AA10: =Z10/(Z10+AB10+AD10+X10) | AB10: =COUNTIFS('一期·UV电访分配'!BF:BF,P10,'一期·UV电访分配'!AJ:AJ,"*B*") | AC10: =AB10/(Z10+AB10+AD10+X10) | AD10: =COUNTIFS('一期·UV电访分配'!BF:BF,P10,'一期·UV电访分配'!AJ:AJ,"*C*") | AE10: =AD10/(Z10+AB10+AD10+X10) | AM10: 王丽 | AN10: =SUMIF('零期·UV电访分配'!AE:AE,AM10,'零期·UV电访分配'!AS:AS) | AO10: 17 | AP10: =AN10-AO10 | AQ10: =AP10*55% | AR10: =SUMIF('零期·UV电访分配'!AE:AE,AM10,'零期·UV电访分配'!AX:AX)-AO10 | AS10: =AR10/AP10 | AT10: =AR10/AQ10
B11: 陈南05 | C11: 语文 | D11: 4 | E11: =COUNTIFS('UV台帐'!W:W,B11,'UV台帐'!AB:AB,"在读") | F11: =E11/(D11*25) | G11: =SUMPRODUCT(('UV台帐'!W:W=B11)*('UV台帐'!AC:AC="是")) | H11: =G11/E11 | I11: =COUNTIFS('UV台帐'!W:W,B11,'UV台帐'!AB:AB,"课前退") | J11: =I11/(E11+I11) | K11: =COUNTIF('陈南05'!T:T,"是")/E11 | L11: =COUNTIF('陈南05'!U:U,"是")/E11 | M11: =COUNTIF('陈南05'!V:V,"是")/E11 | P11: 苏丽婷 | Q11: =SUMIF('一期·UV电访分配'!BF:BF,P11,'一期·UV电访分配'!BR:BR) | R11: 0 | S11: =Q11-R11 | T11: =S11*55% | U11: =SUMIF('一期·UV电访分配'!BF:BF,P11,'一期·UV电访分配'!BW:BW)-R11 | V11: =U11/S11 | W11: =U11/T11 | X11: =COUNTIFS('一期·UV电访分配'!BF:BF,P11,'一期·UV电访分配'!AJ:AJ,"*S*") | Y11: =X11/(Z11+AB11+AD11+X11) | Z11: =COUNTIFS('一期·UV电访分配'!BF:BF,P11,'一期·UV电访分配'!AJ:AJ,"*A*") | AA11: =Z11/(Z11+AB11+AD11+X11) | AB11: =COUNTIFS('一期·UV电访分配'!BF:BF,P11,'一期·UV电访分配'!AJ:AJ,"*B*") | AC11: =AB11/(Z11+AB11+AD11+X11) | AD11: =COUNTIFS('一期·UV电访分配'!BF:BF,P11,'一期·UV电访分配'!AJ:AJ,"*C*") | AE11: =AD11/(Z11+AB11+AD11+X11) | AM11: 苏丽婷 | AN11: =SUMIF('零期·UV电访分配'!AE:AE,AM11,'零期·UV电访分配'!AS:AS) | AO11: 1 | AP11: =AN11-AO11 | AQ11: =AP11*55% | AR11: =SUMIF('零期·UV电访分配'!AE:AE,AM11,'零期·UV电访分配'!AX:AX)-AO11 | AS11: =AR11/AP11 | AT11: =AR11/AQ11
B12: 语文合计 | D12: =SUM(D9:D11) | E12: =SUM(E9:E11) | F12: =E12/(D12*25) | G12: =SUM(G9:G11) | H12: =G12/E12 | I12: =SUM(I9:I11) | J12: =I12/(E12+I12) | K12: =(K9*$E$9+K10*$E$10+K11*$E$11)/$E$12 | L12: =(L9*$E$9+L10*$E$10+L11*$E$11)/$E$12 | M12: =(M9*$E$9+M10*$E$10+M11*$E$11)/$E$12 | O12: 合计 | Q12: =SUM(Q9:Q11) | R12: =SUM(R9:R11) | S12: =Q12-R12 | T12: =S12*55% | U12: =SUM(U9:U11) | V12: =U12/S12 | W12: =U12/T12 | X12: =SUM(X9:X11) | Y12: =X12/(Z12+AB12+AD12+X12) | Z12: =SUM(Z9:Z11) | AA12: =Z12/(Z12+AB12+AD12+X12) | AB12: =SUM(AB9:AB11) | AC12: =AB12/(Z12+AB12+AD12+X12) | AD12: =SUM(AD9:AD11) | AE12: =AD12/(Z12+AB12+AD12+X12) | AL12: 合计 | AN12: =SUM(AN9:AN11) | AO12: =SUM(AO9:AO11) | AP12: =AN12-AO12 | AQ12: =AP12*55% | AR12: =SUM(AR9:AR11) | AS12: =AR12/AP12 | AT12: =AR12/AQ12
B13: 刘希子 | C13: 英语 | D13: 6 | E13: =COUNTIFS('UV台帐'!AF:AF,B13,'UV台帐'!AK:AK,"在读") | F13: =E13/(D13*25) | G13: =SUMPRODUCT(('UV台帐'!AF:AF=B13)*('UV台帐'!AL:AL="是")) | H13: =G13/E13 | I13: =COUNTIFS('UV台帐'!AF:AF,B13,'UV台帐'!AK:AK,"课前退") | J13: =I13/(E13+I13) | K13: =COUNTIF('刘希子'!T:T,"是")/E13 | L13: =COUNTIF('刘希子'!U:U,"是")/E13 | M13: =COUNTIF('刘希子'!V:V,"是")/E13 | O13: 新宝利 | P13: 杨林33 | Q13: =SUMIF('一期·UV电访分配'!BF:BF,P13,'一期·UV电访分配'!BR:BR) | R13: 1 | S13: =Q13-R13 | T13: =S13*55% | U13: =SUMIF('一期·UV电访分配'!BF:BF,P13,'一期·UV电访分配'!BW:BW)-R13 | V13: =U13/S13 | W13: =U13/T13 | X13: =COUNTIFS('一期·UV电访分配'!BF:BF,P13,'一期·UV电访分配'!AJ:AJ,"*S*") | Y13: =X13/(Z13+AB13+AD13+X13) | Z13: =COUNTIFS('一期·UV电访分配'!BF:BF,P13,'一期·UV电访分配'!AJ:AJ,"*A*") | AA13: =Z13/(Z13+AB13+AD13+X13) | AB13: =COUNTIFS('一期·UV电访分配'!BF:BF,P13,'一期·UV电访分配'!AJ:AJ,"*B*") | AC13: =AB13/(Z13+AB13+AD13+X13) | AD13: =COUNTIFS('一期·UV电访分配'!BF:BF,P13,'一期·UV电访分配'!AJ:AJ,"*C*") | AE13: =AD13/(Z13+AB13+AD13+X13) | AL13: 新宝利 | AM13: 杨林33 | AN13: =SUMIF('零期·UV电访分配'!AE:AE,AM13,'零期·UV电访分配'!AS:AS) | AP13: =AN13-AO13 | AQ13: =AP13*55% | AR13: =SUMIF('零期·UV电访分配'!AE:AE,AM13,'零期·UV电访分配'!AX:AX)-AO13 | AS13: =AR13/AP13 | AT13: =AR13/AQ13
B14: 肖锐03 | C14: 英语 | D14: 7 | E14: =COUNTIFS('UV台帐'!AF:AF,B14,'UV台帐'!AK:AK,"在读") | F14: =E14/(D14*25) | G14: =SUMPRODUCT(('UV台帐'!AF:AF=B14)*('UV台帐'!AL:AL="是")) | H14: =G14/E14 | I14: =COUNTIFS('UV台帐'!AF:AF,B14,'UV台帐'!AK:AK,"课前退") | J14: =I14/(E14+I14) | K14: =COUNTIF('肖锐03'!T:T,"是")/E14 | L14: =COUNTIF('肖锐03'!U:U,"是")/E14 | M14: =COUNTIF('肖锐03'!V:V,"是")/E14 | P14: 林志豪01 | Q14: =SUMIF('一期·UV电访分配'!BF:BF,P14,'一期·UV电访分配'!BR:BR) | R14: 0 | S14: =Q14-R14 | T14: =S14*55% | U14: =SUMIF('一期·UV电访分配'!BF:BF,P14,'一期·UV电访分配'!BW:BW)-R14 | V14: =U14/S14 | W14: =U14/T14 | X14: =COUNTIFS('一期·UV电访分配'!BF:BF,P14,'一期·UV电访分配'!AJ:AJ,"*S*") | Y14: =X14/(Z14+AB14+AD14+X14) | Z14: =COUNTIFS('一期·UV电访分配'!BF:BF,P14,'一期·UV电访分配'!AJ:AJ,"*A*") | AA14: =Z14/(Z14+AB14+AD14+X14) | AB14: =COUNTIFS('一期·UV电访分配'!BF:BF,P14,'一期·UV电访分配'!AJ:AJ,"*B*") | AC14: =AB14/(Z14+AB14+AD14+X14) | AD14: =COUNTIFS('一期·UV电访分配'!BF:BF,P14,'一期·UV电访分配'!AJ:AJ,"*C*") | AE14: =AD14/(Z14+AB14+AD14+X14) | AM14: 林志豪01 | AN14: =SUMIF('零期·UV电访分配'!AE:AE,AM14,'零期·UV电访分配'!AS:AS) | AO14: 12 | AP14: =AN14-AO14 | AQ14: =AP14*55% | AR14: =SUMIF('零期·UV电访分配'!AE:AE,AM14,'零期·UV电访分配'!AX:AX)-AO14 | AS14: =AR14/AP14 | AT14: =AR14/AQ14
B15: 高心怡04 | C15: 英语 | D15: 6 | E15: =COUNTIFS('UV台帐'!AF:AF,B15,'UV台帐'!AK:AK,"在读") | F15: =E15/(D15*25) | G15: =SUMPRODUCT(('UV台帐'!AF:AF=B15)*('UV台帐'!AL:AL="是")) | H15: =G15/E15 | I15: =COUNTIFS('UV台帐'!AF:AF,B15,'UV台帐'!AK:AK,"课前退") | J15: =I15/(E15+I15) | K15: =COUNTIF('高心怡04'!T:T,"是")/E15 | L15: =COUNTIF('高心怡04'!U:U,"是")/E15 | M15: =COUNTIF('高心怡04'!V:V,"是")/E15 | P15: 张敏烨 | Q15: =SUMIF('一期·UV电访分配'!BF:BF,P15,'一期·UV电访分配'!BR:BR) | R15: 1 | S15: =Q15-R15 | T15: =S15*55% | U15: =SUMIF('一期·UV电访分配'!BF:BF,P15,'一期·UV电访分配'!BW:BW)-R15 | V15: =U15/S15 | W15: =U15/T15 | X15: =COUNTIFS('一期·UV电访分配'!BF:BF,P15,'一期·UV电访分配'!AJ:AJ,"*S*") | Y15: =X15/(Z15+AB15+AD15+X15) | Z15: =COUNTIFS('一期·UV电访分配'!BF:BF,P15,'一期·UV电访分配'!AJ:AJ,"*A*") | AA15: =Z15/(Z15+AB15+AD15+X15) | AB15: =COUNTIFS('一期·UV电访分配'!BF:BF,P15,'一期·UV电访分配'!AJ:AJ,"*B*") | AC15: =AB15/(Z15+AB15+AD15+X15) | AD15: =COUNTIFS('一期·UV电访分配'!BF:BF,P15,'一期·UV电访分配'!AJ:AJ,"*C*") | AE15: =AD15/(Z15+AB15+AD15+X15) | AM15: 张敏烨 | AN15: =SUMIF('零期·UV电访分配'!AE:AE,AM15,'零期·UV电访分配'!AS:AS) | AO15: 3 | AP15: =AN15-AO15 | AQ15: =AP15*55% | AR15: =SUMIF('零期·UV电访分配'!AE:AE,AM15,'零期·UV电访分配'!AX:AX)-AO15 | AS15: =AR15/AP15 | AT15: =AR15/AQ15
B16: 英语合计 | D16: =SUM(D13:D14) | E16: =SUM(E13:E15) | F16: =E16/(D16*25) | G16: =SUM(G13:G15) | H16: =G16/E16 | I16: =SUM(I13:I15) | J16: =I16/(E16+I16) | K16: =(K13*$E$13+K14*$E$14+K15*$E$15)/$E$16 | L16: =(L13*$E$13+L14*$E$14+L15*$E$15)/$E$16 | M16: =(M13*$E$13+M14*$E$14+M15*$E$15)/$E$16 | O16: 合计 | Q16: =SUM(Q13:Q15) | R16: =SUM(R13:R15) | S16: =Q16-R16 | T16: =S16*55% | U16: =SUM(U13:U15) | V16: =U16/S16 | W16: =U16/T16 | X16: =SUM(X13:X15) | Y16: =X16/(Z16+AB16+AD16+X16) | Z16: =SUM(Z13:Z15) | AA16: =Z16/(Z16+AB16+AD16+X16) | AB16: =SUM(AB13:AB15) | AC16: =AB16/(Z16+AB16+AD16+X16) | AD16: =SUM(AD13:AD15) | AE16: =AD16/(Z16+AB16+AD16+X16) | AL16: 合计 | AN16: =SUM(AN13:AN15) | AO16: =SUM(AO13:AO15) | AP16: =AN16-AO16 | AQ16: =AP16*55% | AR16: =SUM(AR13:AR15) | AS16: =AR16/AP16 | AT16: =AR16/AQ16
B18: 一期汇总 | D18: 基础信息 | K18: 课前服务 | N18: 课中家长会 | Y18: 一期 | Z18: 学员数 | AB18: vip入群率 | AC18: 课前家长会（UV） | AE18: 课中家长会（UV） | AG18: 转化率 （PV） | AH18: 学员意向分层(PV)
D19: =SUM(D21:D33)/2 | E19: =E25+E29+E33 | F19: =E19/(25*D19) | G19: =G25+G29+G33 | H19: =G19/E19 | I19: =SUM(I21:I33)/2 | J19: =I19/(E19+I19) | K19: =(K25*$E$49+K29*$E$53+K33*$E$57)/$E$43 | L19: =(L25*$E$49+L29*$E$53+L33*$E$57)/$E$43 | M19: =(M25*$E$49+M29*$E$53+M33*$E$57)/$E$43 | N19: =SUM(N21:N33)/2 | O19: =N19/E19 | P19: =SUM(P21:P33)/2 | Q19: =SUM(Q21:Q33)/2 | R19: =Q19/P19 | S19: =SUM(S21:S33)/2 | T19: =SUM(T21:T33)/2 | U19: =T19/S19 | V19: =SUM(V21:V33)/2 | W19: =V19/E19 | Y19: 校区 | Z19: PV | AA19: UV | AC19: 课前诺访 | AD19: 课前确访 | AE19: 课中诺访 | AF19: 课中确访 | AH19: S | AI19: 占比 | AJ19: A | AK19: 占比 | AL19: B | AM19: 占比 | AN19: C | AO19: 占比
B20: 老师看板 | C20: 学科 | D20: 班量 | E20: 在读PV | F20: 满班率 | G20: 暑续秋PV | H20: 转化率 | I20: 课前退PV | J20: 课前退率 | K20: 加微率 | L20: 首联率 | M20: vip入群率 | N20: 课中诺访 | O20: 诺访率PV | P20: 7月18日应到 | Q20: 7月18日实到 | R20: 到场率 | S20: 7月19日应到 | T20: 7月19日实到 | U20: 到场率 | V20: 整体到场 | W20: 到场率 | Y20: 天成大厦 | Z20: =SUMIF('一期·UV电访分配'!A:A,Y20,'一期·UV电访分配'!BR:BR) | AA20: =COUNTIF('一期·UV电访分配'!A:A,Y20) | AB20: =IFERROR(COUNTIFS('一期·UV电访分配'!A:A,Y20,'一期·UV电访分配'!R:R,"是")/AA20,0) | AC20: =IFERROR(COUNTIFS('一期·UV电访分配'!A:A,Y20,'一期·UV电访分配'!AL:AL,"是")/AA20,0) | AD20: =IFERROR(COUNTIFS('一期·UV电访分配'!A:A,Y20,'一期·UV电访分配'!AM:AM,"是")/AA20,0) | AE20: =IFERROR(COUNTIFS('一期·UV电访分配'!A:A,Y20,'一期·UV电访分配'!AY:AY,"是")/AA20,0) | AF20: =IFERROR(COUNTIFS('一期·UV电访分配'!A:A,Y20,'一期·UV电访分配'!BE:BE,"是")/AA20,0) | AG20: =IFERROR(SUMIF('一期·UV电访分配'!A:A,Y20,'一期·UV电访分配'!BW:BW)/Z20,0) | AH20: =COUNTIFS('一期·UV电访分配'!A:A,Y20,'一期·UV电访分配'!AJ:AJ,"*S*") | AI20: =IFERROR(AH20/Z20,0) | AJ20: =COUNTIFS('一期·UV电访分配'!A:A,Y20,'一期·UV电访分配'!AJ:AJ,"*A*") | AK20: =IFERROR(AJ20/Z20,0) | AL20: =COUNTIFS('一期·UV电访分配'!A:A,Y20,'一期·UV电访分配'!AJ:AJ,"*B*") | AM20: =IFERROR(AL20/Z20,0) | AN20: =COUNTIFS('一期·UV电访分配'!A:A,Y20,'一期·UV电访分配'!AJ:AJ,"*C*") | AO20: =IFERROR(AN20/Z20,0)
B21: 陈中帅 | C21: 数学 | D21: 2 | E21: =COUNTIFS('UV台帐'!N:N,B21,'UV台帐'!S:S,"在读",'UV台帐'!R:R,"一期") | F21: =E21/(D21*25) | G21: =SUMPRODUCT(('UV台帐'!N:N=B21)*('UV台帐'!T:T="是")*('UV台帐'!R:R="一期")) | H21: =G21/E21 | I21: =COUNTIFS('UV台帐'!N:N,B21,'UV台帐'!S:S,"课前退",'UV台帐'!R:R,"一期") | J21: =I21/(E21+I21) | K21: =IFERROR(COUNTIFS('陈中帅'!T:T,"是",'陈中帅'!B:B,"一期")/E21,"") | L21: =COUNTIFS('陈中帅'!U:U,"是",'陈中帅'!B:B,"一期")/E21 | M21: =COUNTIFS('陈中帅'!V:V,"是",'陈中帅'!B:B,"一期")/E21 | N21: =COUNTIFS('一期·UV电访分配'!E:E,B21,'一期·UV电访分配'!AY:AY,"是") | O21: =N21/E21 | P21: =COUNTIFS('一期·UV电访分配'!E:E,B21,'一期·UV电访分配'!I:I,"在读",'一期·UV电访分配'!H:H,"一期",'一期·UV电访分配'!A:A,"同创汇") | Q21: =COUNTIFS('一期·UV电访分配'!E:E,B21,'一期·UV电访分配'!I:I,"在读",'一期·UV电访分配'!H:H,"一期",'一期·UV电访分配'!A:A,"同创汇",'一期·UV电访分配'!BE:BE,"是") | R21: =Q21/P21 | S21: =COUNTIFS('一期·UV电访分配'!E:E,B21,'一期·UV电访分配'!I:I,"在读",'一期·UV电访分配'!H:H,"一期",'一期·UV电访分配'!A:A,"新宝利") | T21: =COUNTIFS('一期·UV电访分配'!E:E,B21,'一期·UV电访分配'!I:I,"在读",'一期·UV电访分配'!H:H,"一期",'一期·UV电访分配'!A:A,"新宝利",'一期·UV电访分配'!BE:BE,"是") | U21: =IFERROR(T21/S21,0) | V21: =T21+Q21 | W21: =V21/E21 | Y21: 同创汇 | Z21: =SUMIF('一期·UV电访分配'!A:A,Y21,'一期·UV电访分配'!BR:BR) | AA21: =COUNTIF('一期·UV电访分配'!A:A,Y21) | AB21: =COUNTIFS('一期·UV电访分配'!A:A,Y21,'一期·UV电访分配'!R:R,"是")/AA21 | AC21: =COUNTIFS('一期·UV电访分配'!A:A,Y21,'一期·UV电访分配'!AL:AL,"是")/AA21 | AD21: =COUNTIFS('一期·UV电访分配'!A:A,Y21,'一期·UV电访分配'!AM:AM,"是")/AA21 | AE21: =COUNTIFS('一期·UV电访分配'!A:A,Y21,'一期·UV电访分配'!AY:AY,"是")/AA21 | AF21: =COUNTIFS('一期·UV电访分配'!A:A,Y21,'一期·UV电访分配'!BE:BE,"是")/AA21 | AG21: =SUMIF('一期·UV电访分配'!A:A,Y21,'一期·UV电访分配'!BW:BW)/Z21 | AH21: =COUNTIFS('一期·UV电访分配'!A:A,Y21,'一期·UV电访分配'!AJ:AJ,"*S*") | AI21: =AH21/Z21 | AJ21: =COUNTIFS('一期·UV电访分配'!A:A,Y21,'一期·UV电访分配'!AJ:AJ,"*A*") | AK21: =AJ21/Z21 | AL21: =COUNTIFS('一期·UV电访分配'!A:A,Y21,'一期·UV电访分配'!AJ:AJ,"*B*") | AM21: =AL21/Z21 | AN21: =COUNTIFS('一期·UV电访分配'!A:A,Y21,'一期·UV电访分配'!AJ:AJ,"*C*") | AO21: =AN21/Z21
B22: 何咏04 | C22: 数学 | D22: 2 | E22: =COUNTIFS('UV台帐'!N:N,B22,'UV台帐'!S:S,"在读",'UV台帐'!R:R,"一期") | F22: =IFERROR(E22/(D22*25),"0") | G22: =SUMPRODUCT(('UV台帐'!N:N=B22)*('UV台帐'!T:T="是")*('UV台帐'!R:R="一期")) | H22: =IFERROR(G22/E22,"0") | I22: =COUNTIFS('UV台帐'!N:N,B22,'UV台帐'!S:S,"课前退",'UV台帐'!R:R,"一期") | J22: =IFERROR(I22/(E22+I22),"0") | K22: =IFERROR(COUNTIFS('何咏04'!T:T,"是",'何咏04'!B:B,"一期")/E22,"0") | L22: =IFERROR(COUNTIFS('何咏04'!U:U,"是",'何咏04'!B:B,"一期")/E22,"0") | M22: =IFERROR(COUNTIFS('何咏04'!V:V,"是",'何咏04'!B:B,"一期")/E22,"0") | N22: =COUNTIFS('一期·UV电访分配'!E:E,B22,'一期·UV电访分配'!AY:AY,"是") | O22: =N22/E22 | P22: =COUNTIFS('一期·UV电访分配'!E:E,B22,'一期·UV电访分配'!I:I,"在读",'一期·UV电访分配'!H:H,"一期",'一期·UV电访分配'!A:A,"同创汇") | Q22: =COUNTIFS('一期·UV电访分配'!E:E,B22,'一期·UV电访分配'!I:I,"在读",'一期·UV电访分配'!H:H,"一期",'一期·UV电访分配'!A:A,"同创汇",'一期·UV电访分配'!BE:BE,"是") | R22: =Q22/P22 | T22: 0 | U22: =IFERROR(T22/S22,0) | V22: =T22+Q22 | W22: =V22/E22 | Y22: 新宝利 | Z22: =SUMIF('一期·UV电访分配'!A:A,Y22,'一期·UV电访分配'!BR:BR) | AA22: =COUNTIF('一期·UV电访分配'!A:A,Y22) | AB22: =COUNTIFS('一期·UV电访分配'!A:A,Y22,'一期·UV电访分配'!R:R,"是")/AA22 | AC22: =COUNTIFS('一期·UV电访分配'!A:A,Y22,'一期·UV电访分配'!AL:AL,"是")/AA22 | AD22: =COUNTIFS('一期·UV电访分配'!A:A,Y22,'一期·UV电访分配'!AM:AM,"是")/AA22 | AE22: =COUNTIFS('一期·UV电访分配'!A:A,Y22,'一期·UV电访分配'!AY:AY,"是")/AA22 | AF22: =COUNTIFS('一期·UV电访分配'!A:A,Y22,'一期·UV电访分配'!BE:BE,"是")/AA22 | AG22: =SUMIF('一期·UV电访分配'!A:A,Y22,'一期·UV电访分配'!BW:BW)/Z22 | AH22: =COUNTIFS('一期·UV电访分配'!A:A,Y22,'一期·UV电访分配'!AJ:AJ,"*S*") | AI22: =AH22/Z22 | AJ22: =COUNTIFS('一期·UV电访分配'!A:A,Y22,'一期·UV电访分配'!AJ:AJ,"*A*") | AK22: =AJ22/Z22 | AL22: =COUNTIFS('一期·UV电访分配'!A:A,Y22,'一期·UV电访分配'!AJ:AJ,"*B*") | AM22: =AL22/Z22 | AN22: =COUNTIFS('一期·UV电访分配'!A:A,Y22,'一期·UV电访分配'!AJ:AJ,"*C*") | AO22: =AN22/Z22
B23: 田雨涵01 | C23: 数学 | D23: 1 | E23: =COUNTIFS('UV台帐'!N:N,B23,'UV台帐'!S:S,"在读",'UV台帐'!R:R,"一期") | F23: =E23/(D23*25) | G23: =SUMPRODUCT(('UV台帐'!N:N=B23)*('UV台帐'!T:T="是")*('UV台帐'!R:R="一期")) | H23: =G23/E23 | I23: =COUNTIFS('UV台帐'!N:N,B23,'UV台帐'!S:S,"课前退",'UV台帐'!R:R,"一期") | J23: =I23/(E23+I23) | K23: =COUNTIFS('田雨涵01'!T:T,"是",'田雨涵01'!B:B,"一期")/E23 | L23: =COUNTIFS('田雨涵01'!U:U,"是",'田雨涵01'!B:B,"一期")/E23 | M23: =COUNTIFS('田雨涵01'!V:V,"是",'田雨涵01'!B:B,"一期")/E23 | N23: =COUNTIFS('一期·UV电访分配'!E:E,B23,'一期·UV电访分配'!AY:AY,"是") | O23: =N23/E23 | P23: =COUNTIFS('一期·UV电访分配'!E:E,B23,'一期·UV电访分配'!I:I,"在读",'一期·UV电访分配'!H:H,"一期",'一期·UV电访分配'!A:A,"同创汇") | Q23: =COUNTIFS('一期·UV电访分配'!E:E,B23,'一期·UV电访分配'!I:I,"在读",'一期·UV电访分配'!H:H,"一期",'一期·UV电访分配'!A:A,"同创汇",'一期·UV电访分配'!BE:BE,"是") | R23: =Q23/P23 | S23: =COUNTIFS('一期·UV电访分配'!E:E,B23,'一期·UV电访分配'!I:I,"在读",'一期·UV电访分配'!H:H,"一期",'一期·UV电访分配'!A:A,"新宝利") | T23: =COUNTIFS('一期·UV电访分配'!E:E,B23,'一期·UV电访分配'!I:I,"在读",'一期·UV电访分配'!H:H,"一期",'一期·UV电访分配'!A:A,"新宝利",'一期·UV电访分配'!BE:BE,"是") | U23: =IFERROR(T23/S23,0) | V23: =T23+Q23 | W23: =V23/E23 | Y23: 分校合计 | Z23: =SUM(Z20:Z22) | AA23: =SUM(AA20:AA22) | AB23: =COUNTIF('一期·UV电访分配'!R:R,"是")/AA23 | AC23: =COUNTIF('一期·UV电访分配'!AL:AL,"是")/AA23 | AD23: =COUNTIF('一期·UV电访分配'!AM:AM,"是")/AA23 | AE23: =COUNTIF('一期·UV电访分配'!AY:AY,"是")/AA23 | AF23: =COUNTIF('一期·UV电访分配'!BE:BE,"是")/AA23 | AG23: =SUM('一期·UV电访分配'!BW:BW)/Z23 | AH23: =SUM(AH20:AH22) | AI23: =AH23/Z23 | AJ23: =SUM(AJ20:AJ22) | AK23: =AJ23/Z23 | AL23: =SUM(AL20:AL22) | AM23: =AL23/Z23 | AN23: =SUM(AN20:AN22) | AO23: =AN23/Z23
B24: 宗志鹏 | C24: 数学 | D24: 0 | E24: =COUNTIFS('UV台帐'!N:N,B24,'UV台帐'!S:S,"在读",'UV台帐'!R:R,"一期") | F24: =IFERROR(E24/(D24*25),"0") | G24: =SUMPRODUCT(('UV台帐'!N:N=B24)*('UV台帐'!T:T="是")*('UV台帐'!R:R="一期")) | H24: =IFERROR(G24/E24,"0") | I24: =COUNTIFS('UV台帐'!N:N,B24,'UV台帐'!S:S,"课前退",'UV台帐'!R:R,"一期") | J24: =IFERROR(I24/(E24+I24),"0") | K24: =IFERROR(COUNTIFS('宗志鹏'!T:T,"是",'宗志鹏'!B:B,"一期")/E24,"0") | L24: =IFERROR(COUNTIFS('宗志鹏'!U:U,"是",'宗志鹏'!B:B,"一期")/E24,"0") | M24: =IFERROR(COUNTIFS('宗志鹏'!V:V,"是",'宗志鹏'!B:B,"一期")/E24,"0") | N24: =COUNTIFS('一期·UV电访分配'!E:E,B24,'一期·UV电访分配'!AY:AY,"是") | O24: =N24/E24 | P24: =COUNTIFS('一期·UV电访分配'!E:E,B24,'一期·UV电访分配'!I:I,"在读",'一期·UV电访分配'!H:H,"一期",'一期·UV电访分配'!A:A,"同创汇") | Q24: 0 | R24: =Q24/P24 | T24: 0 | U24: =T24/S24 | V24: =T24+Q24 | W24: =V24/E24
B25: 数学合计 | D25: =SUM(D21:D24) | E25: =SUM(E21:E24) | F25: =E25/(D25*25) | G25: =SUM(G21:G24) | H25: =G25/E25 | I25: =SUM(I21:I24) | J25: =I25/(E25+I25) | K25: =(K21*$E$45+K22*$E$46+K23*$E$47+K24*$E$48)/$E$49 | L25: =(L21*$E$45+L22*$E$46+L23*$E$47+L24*$E$48)/$E$49 | M25: =(M21*$E$45+M22*$E$46+M23*$E$47+M24*$E$48)/$E$49 | N25: =SUM(N21:N23) | O25: =N25/E25 | P25: =SUM(P21:P23) | Q25: =SUM(Q21:Q23) | R25: =Q25/P25 | S25: =SUM(S21:S23) | T25: =SUM(T21:T23) | U25: =IFERROR(T25/S25,0) | V25: =T25+Q25 | W25: =V25/E25
B26: 黄铭怡 | C26: 语文 | D26: 1 | E26: =COUNTIFS('UV台帐'!W:W,B26,'UV台帐'!AB:AB,"在读",'UV台帐'!AA:AA,"一期") | F26: =E26/(D26*25) | G26: =SUMPRODUCT(('UV台帐'!W:W=B26)*('UV台帐'!AC:AC="是")*('UV台帐'!AA:AA="一期")) | H26: =G26/E26 | I26: =COUNTIFS('UV台帐'!W:W,B26,'UV台帐'!AB:AB,"课前退",'UV台帐'!AA:AA,"一期") | J26: =I26/(E26+I26) | K26: =COUNTIFS('黄铭怡'!T:T,"是",'黄铭怡'!B:B,"一期")/E26 | L26: =COUNTIFS('黄铭怡'!U:U,"是",'黄铭怡'!B:B,"一期")/E26 | M26: =COUNTIFS('黄铭怡'!V:V,"是",'黄铭怡'!B:B,"一期")/E26 | N26: =COUNTIFS('一期·UV电访分配'!J:J,B26,'一期·UV电访分配'!AY:AY,"是") | O26: =N26/E26 | P26: =COUNTIFS('一期·UV电访分配'!J:J,B26,'一期·UV电访分配'!M:M,"在读",'一期·UV电访分配'!L:L,"一期",'一期·UV电访分配'!A:A,"同创汇") | Q26: =COUNTIFS('一期·UV电访分配'!J:J,B26,'一期·UV电访分配'!M:M,"在读",'一期·UV电访分配'!L:L,"一期",'一期·UV电访分配'!A:A,"同创汇",'一期·UV电访分配'!BE:BE,"是") | R26: =Q26/P26 | S26: =COUNTIFS('一期·UV电访分配'!J:J,B26,'一期·UV电访分配'!M:M,"在读",'一期·UV电访分配'!L:L,"一期",'一期·UV电访分配'!A:A,"新宝利") | T26: =COUNTIFS('一期·UV电访分配'!J:J,B26,'一期·UV电访分配'!M:M,"在读",'一期·UV电访分配'!L:L,"一期",'一期·UV电访分配'!A:A,"新宝利",'一期·UV电访分配'!BE:BE,"是") | U26: =IFERROR(T26/S26,0) | V26: =T26+Q26 | W26: =V26/E26
B27: 李润 | C27: 语文 | D27: 2 | E27: =COUNTIFS('UV台帐'!W:W,B27,'UV台帐'!AB:AB,"在读",'UV台帐'!AA:AA,"一期") | F27: =E27/(D27*25) | G27: =SUMPRODUCT(('UV台帐'!W:W=B27)*('UV台帐'!AC:AC="是")*('UV台帐'!AA:AA="一期")) | H27: =G27/E27 | I27: =COUNTIFS('UV台帐'!W:W,B27,'UV台帐'!AB:AB,"课前退",'UV台帐'!AA:AA,"一期") | J27: =I27/(E27+I27) | K27: =COUNTIFS('李润'!T:T,"是",'李润'!B:B,"一期")/E27 | L27: =COUNTIFS('李润'!U:U,"是",'李润'!B:B,"一期")/E27 | M27: =COUNTIFS('李润'!V:V,"是",'李润'!B:B,"一期")/E27 | N27: =COUNTIFS('一期·UV电访分配'!J:J,B27,'一期·UV电访分配'!AY:AY,"是") | O27: =N27/E27 | P27: =COUNTIFS('一期·UV电访分配'!J:J,B27,'一期·UV电访分配'!M:M,"在读",'一期·UV电访分配'!L:L,"一期",'一期·UV电访分配'!A:A,"同创汇") | Q27: =COUNTIFS('一期·UV电访分配'!J:J,B27,'一期·UV电访分配'!M:M,"在读",'一期·UV电访分配'!L:L,"一期",'一期·UV电访分配'!A:A,"同创汇",'一期·UV电访分配'!BE:BE,"是") | R27: =IFERROR(Q27/P27,0) | S27: =COUNTIFS('一期·UV电访分配'!J:J,B27,'一期·UV电访分配'!M:M,"在读",'一期·UV电访分配'!L:L,"一期",'一期·UV电访分配'!A:A,"新宝利") | T27: =COUNTIFS('一期·UV电访分配'!J:J,B27,'一期·UV电访分配'!M:M,"在读",'一期·UV电访分配'!L:L,"一期",'一期·UV电访分配'!A:A,"新宝利",'一期·UV电访分配'!BE:BE,"是") | U27: =T27/S27 | V27: =T27+Q27 | W27: =V27/E27
B28: 陈南05 | C28: 语文 | D28: 2 | E28: =COUNTIFS('UV台帐'!W:W,B28,'UV台帐'!AB:AB,"在读",'UV台帐'!AA:AA,"一期") | F28: =E28/(D28*25) | G28: =SUMPRODUCT(('UV台帐'!W:W=B28)*('UV台帐'!AC:AC="是")*('UV台帐'!AA:AA="一期")) | H28: =G28/E28 | I28: =COUNTIFS('UV台帐'!W:W,B28,'UV台帐'!AB:AB,"课前退",'UV台帐'!AA:AA,"一期") | J28: =I28/(E28+I28) | K28: =COUNTIFS('陈南05'!T:T,"是",'陈南05'!B:B,"一期")/E28 | L28: =COUNTIFS('陈南05'!U:U,"是",'陈南05'!B:B,"一期")/E28 | M28: =COUNTIFS('陈南05'!V:V,"是",'陈南05'!B:B,"一期")/E28 | N28: =COUNTIFS('一期·UV电访分配'!J:J,B28,'一期·UV电访分配'!AY:AY,"是") | O28: =N28/E28 | P28: =COUNTIFS('一期·UV电访分配'!J:J,B28,'一期·UV电访分配'!M:M,"在读",'一期·UV电访分配'!L:L,"一期",'一期·UV电访分配'!A:A,"同创汇") | Q28: =COUNTIFS('一期·UV电访分配'!J:J,B28,'一期·UV电访分配'!M:M,"在读",'一期·UV电访分配'!L:L,"一期",'一期·UV电访分配'!A:A,"同创汇",'一期·UV电访分配'!BE:BE,"是") | R28: =Q28/P28 | S28: =COUNTIFS('一期·UV电访分配'!J:J,B28,'一期·UV电访分配'!M:M,"在读",'一期·UV电访分配'!L:L,"一期",'一期·UV电访分配'!A:A,"新宝利") | T28: =COUNTIFS('一期·UV电访分配'!J:J,B28,'一期·UV电访分配'!M:M,"在读",'一期·UV电访分配'!L:L,"一期",'一期·UV电访分配'!A:A,"新宝利",'一期·UV电访分配'!BE:BE,"是") | U28: =IFERROR(T28/S28,0) | V28: =T28+Q28 | W28: =V28/E28
B29: 语文合计 | D29: =SUM(D26:D28) | E29: =SUM(E26:E28) | F29: =E29/(D29*25) | G29: =SUM(G26:G28) | H29: =G29/E29 | I29: =SUM(I26:I28) | J29: =I29/(E29+I29) | K29: =(K26*$E$50+K27*$E$51+K28*$E$52)/$E$53 | L29: =(L26*$E$50+L27*$E$51+L28*$E$52)/$E$53 | M29: =(M26*$E$50+M27*$E$51+M28*$E$52)/$E$53 | N29: =SUM(N26:N28) | O29: =N29/E29 | P29: =SUM(P26:P28) | Q29: =SUM(Q26:Q28) | R29: =Q29/P29 | S29: =SUM(S26:S28) | T29: =SUM(T26:T28) | U29: =T29/S29 | V29: =T29+Q29 | W29: =V29/E29
B30: 刘希子 | C30: 英语 | D30: 1 | E30: =COUNTIFS('UV台帐'!AF:AF,B30,'UV台帐'!AK:AK,"在读",'UV台帐'!AJ:AJ,"一期") | F30: =E30/(D30*25) | G30: =SUMPRODUCT(('UV台帐'!AF:AF=B30)*('UV台帐'!AL:AL="是")*('UV台帐'!AJ:AJ="一期")) | H30: =G30/E30 | I30: =COUNTIFS('UV台帐'!AF:AF,B30,'UV台帐'!AK:AK,"课前退",'UV台帐'!AJ:AJ,"一期") | J30: =I30/(E30+I30) | K30: =COUNTIFS('刘希子'!T:T,"是",'刘希子'!B:B,"一期")/E30 | L30: =COUNTIFS('刘希子'!U:U,"是",'刘希子'!B:B,"一期")/E30 | M30: =COUNTIFS('刘希子'!V:V,"是",'刘希子'!B:B,"一期")/E30 | N30: =COUNTIFS('一期·UV电访分配'!N:N,B30,'一期·UV电访分配'!AY:AY,"是") | O30: =N30/E30 | P30: =COUNTIFS('一期·UV电访分配'!N:N,B30,'一期·UV电访分配'!Q:Q,"在读",'一期·UV电访分配'!P:P,"一期",'一期·UV电访分配'!A:A,"同创汇") | Q30: =COUNTIFS('一期·UV电访分配'!N:N,B30,'一期·UV电访分配'!Q:Q,"在读",'一期·UV电访分配'!P:P,"一期",'一期·UV电访分配'!A:A,"同创汇",'一期·UV电访分配'!BE:BE,"是") | R30: =IFERROR(Q30/P30,0) | S30: =COUNTIFS('一期·UV电访分配'!N:N,B30,'一期·UV电访分配'!Q:Q,"在读",'一期·UV电访分配'!P:P,"一期",'一期·UV电访分配'!A:A,"新宝利") | T30: =COUNTIFS('一期·UV电访分配'!N:N,B30,'一期·UV电访分配'!Q:Q,"在读",'一期·UV电访分配'!P:P,"一期",'一期·UV电访分配'!A:A,"新宝利",'一期·UV电访分配'!BE:BE,"是") | U30: =IFERROR(T30/S30,0) | V30: =T30+Q30 | W30: =V30/E30
B31: 肖锐03 | C31: 英语 | D31: 2 | E31: =COUNTIFS('UV台帐'!AF:AF,B31,'UV台帐'!AK:AK,"在读",'UV台帐'!AJ:AJ,"一期") | F31: =E31/(D31*25) | G31: =SUMPRODUCT(('UV台帐'!AF:AF=B31)*('UV台帐'!AL:AL="是")*('UV台帐'!AJ:AJ="一期")) | H31: =G31/E31 | I31: =COUNTIFS('UV台帐'!AF:AF,B31,'UV台帐'!AK:AK,"课前退",'UV台帐'!AJ:AJ,"一期") | J31: =I31/(E31+I31) | K31: =COUNTIFS('肖锐03'!T:T,"是",'肖锐03'!B:B,"一期")/E31 | L31: =COUNTIFS('肖锐03'!U:U,"是",'肖锐03'!B:B,"一期")/E31 | M31: =COUNTIFS('肖锐03'!V:V,"是",'肖锐03'!B:B,"一期")/E31 | N31: =COUNTIFS('一期·UV电访分配'!N:N,B31,'一期·UV电访分配'!AY:AY,"是") | O31: =N31/E31 | P31: =COUNTIFS('一期·UV电访分配'!N:N,B31,'一期·UV电访分配'!Q:Q,"在读",'一期·UV电访分配'!P:P,"一期",'一期·UV电访分配'!A:A,"同创汇") | Q31: =COUNTIFS('一期·UV电访分配'!N:N,B31,'一期·UV电访分配'!Q:Q,"在读",'一期·UV电访分配'!P:P,"一期",'一期·UV电访分配'!A:A,"同创汇",'一期·UV电访分配'!BE:BE,"是") | R31: =IFERROR(Q31/P31,0) | S31: =COUNTIFS('一期·UV电访分配'!N:N,B31,'一期·UV电访分配'!Q:Q,"在读",'一期·UV电访分配'!P:P,"一期",'一期·UV电访分配'!A:A,"新宝利") | T31: =COUNTIFS('一期·UV电访分配'!N:N,B31,'一期·UV电访分配'!Q:Q,"在读",'一期·UV电访分配'!P:P,"一期",'一期·UV电访分配'!A:A,"新宝利",'一期·UV电访分配'!BE:BE,"是") | U31: =T31/S31 | V31: =T31+Q31 | W31: =V31/E31
B32: 高心怡04 | C32: 英语 | D32: 2 | E32: =COUNTIFS('UV台帐'!AF:AF,B32,'UV台帐'!AK:AK,"在读",'UV台帐'!AJ:AJ,"一期") | F32: =E32/(D32*25) | G32: =SUMPRODUCT(('UV台帐'!AF:AF=B32)*('UV台帐'!AL:AL="是")*('UV台帐'!AJ:AJ="一期")) | H32: =G32/E32 | I32: =COUNTIFS('UV台帐'!AF:AF,B32,'UV台帐'!AK:AK,"课前退",'UV台帐'!AJ:AJ,"一期") | J32: =I32/(E32+I32) | K32: =COUNTIFS('高心怡04'!T:T,"是",'高心怡04'!B:B,"一期")/E32 | L32: =COUNTIFS('高心怡04'!U:U,"是",'高心怡04'!B:B,"一期")/E32 | M32: =COUNTIFS('高心怡04'!V:V,"是",'高心怡04'!B:B,"一期")/E32 | N32: =COUNTIFS('一期·UV电访分配'!N:N,B32,'一期·UV电访分配'!AY:AY,"是") | O32: =N32/E32 | P32: =COUNTIFS('一期·UV电访分配'!N:N,B32,'一期·UV电访分配'!Q:Q,"在读",'一期·UV电访分配'!P:P,"一期",'一期·UV电访分配'!A:A,"同创汇") | Q32: =COUNTIFS('一期·UV电访分配'!N:N,B32,'一期·UV电访分配'!Q:Q,"在读",'一期·UV电访分配'!P:P,"一期",'一期·UV电访分配'!A:A,"同创汇",'一期·UV电访分配'!BE:BE,"是") | R32: =Q32/P32 | S32: =COUNTIFS('一期·UV电访分配'!N:N,B32,'一期·UV电访分配'!Q:Q,"在读",'一期·UV电访分配'!P:P,"一期",'一期·UV电访分配'!A:A,"新宝利") | T32: =COUNTIFS('一期·UV电访分配'!N:N,B32,'一期·UV电访分配'!Q:Q,"在读",'一期·UV电访分配'!P:P,"一期",'一期·UV电访分配'!A:A,"新宝利",'一期·UV电访分配'!BE:BE,"是") | U32: =IFERROR(T32/S32,0) | V32: =T32+Q32 | W32: =V32/E32
B33: 英语合计 | D33: =SUM(D30:D32) | E33: =SUM(E30:E32) | F33: =E33/(D33*25) | G33: =SUM(G30:G32) | H33: =G33/E33 | I33: =SUM(I30:I32) | J33: =I33/(E33+I33) | K33: =(K30*$E$54+K31*$E$55+K32*$E$56)/$E$57 | L33: =(L30*$E$54+L31*$E$55+L32*$E$56)/$E$57 | M33: =(M30*$E$54+M31*$E$55+M32*$E$56)/$E$57 | N33: =SUM(N30:N32) | O33: =N33/E33 | P33: =SUM(P30:P32) | Q33: =SUM(Q30:Q32) | R33: =Q33/P33 | S33: =SUM(S30:S32) | T33: =SUM(T30:T32) | U33: =T33/S33 | V33: =T33+Q33 | W33: =V33/E33
B35: 零期 | C35: 学员数 | E35: vip入群率 | F35: 课前家长会（UV） | H35: 课中家长会（UV） | J35: 转化率 （PV） | K35: 学员意向分层(PV)
B36: 校区 | C36: PV | D36: UV | F36: 课前诺访 | G36: 课前确访 | H36: 课中诺访 | I36: 课中确访 | K36: S | L36: 占比 | M36: A | N36: 占比 | O36: B | P36: 占比 | Q36: C | R36: 占比
B37: 天成大厦 | C37: =SUMIF('零期·UV电访分配'!A:A,B37,'零期·UV电访分配'!AS:AS) | D37: =COUNTIF('零期·UV电访分配'!A:A,B37) | E37: =IFERROR(COUNTIFS('零期·UV电访分配'!A:A,B37,'零期·UV电访分配'!AH:AH,"是")/D37,0) | F37: =IFERROR(COUNTIFS('零期·UV电访分配'!A:A,B37,'零期·UV电访分配'!S:S,"是")/D37,0) | G37: =IFERROR(COUNTIFS('零期·UV电访分配'!A:A,B37,'零期·UV电访分配'!T:T,"是")/D37,0) | H37: =IFERROR(COUNTIFS('零期·UV电访分配'!A:A,B37,'零期·UV电访分配'!AB:AB,"是")/D37,0) | I37: =IFERROR(COUNTIFS('零期·UV电访分配'!A:A,B37,'零期·UV电访分配'!AD:AD,"是")/D37,0) | J37: =IFERROR(SUMIF('零期·UV电访分配'!A:A,B37,'零期·UV电访分配'!AX:AX)/C37,0) | K37: =COUNTIFS('零期·UV电访分配'!A:A,B37,'零期·UV电访分配'!AM:AM,"S")+COUNTIFS('零期·UV电访分配'!A:A,B37,'零期·UV电访分配'!AN:AN,"S")+COUNTIFS('零期·UV电访分配'!A:A,B37,'零期·UV电访分配'!AO:AO,"S") | L37: =IFERROR(K37/C37,0) | M37: =COUNTIFS('零期·UV电访分配'!A:A,B37,'零期·UV电访分配'!AM:AM,"A")+COUNTIFS('零期·UV电访分配'!A:A,B37,'零期·UV电访分配'!AN:AN,"A")+COUNTIFS('零期·UV电访分配'!A:A,B37,'零期·UV电访分配'!AO:AO,"A") | N37: =IFERROR(M37/C37,0) | O37: =COUNTIFS('零期·UV电访分配'!A:A,B37,'零期·UV电访分配'!AM:AM,"B")+COUNTIFS('零期·UV电访分配'!A:A,B37,'零期·UV电访分配'!AN:AN,"B")+COUNTIFS('零期·UV电访分配'!A:A,B37,'零期·UV电访分配'!AO:AO,"B") | P37: =IFERROR(O37/C37,0) | Q37: =COUNTIFS('零期·UV电访分配'!A:A,B37,'零期·UV电访分配'!AM:AM,"C")+COUNTIFS('零期·UV电访分配'!A:A,B37,'零期·UV电访分配'!AN:AN,"C")+COUNTIFS('零期·UV电访分配'!A:A,B37,'零期·UV电访分配'!AO:AO,"C") | R37: =IFERROR(Q37/C37,0)
B38: 同创汇 | C38: =SUMIF('零期·UV电访分配'!A:A,B38,'零期·UV电访分配'!AS:AS) | D38: =COUNTIF('零期·UV电访分配'!A:A,B38) | E38: =COUNTIFS('零期·UV电访分配'!A:A,B38,'零期·UV电访分配'!AH:AH,"是")/D38 | F38: =COUNTIFS('零期·UV电访分配'!A:A,B38,'零期·UV电访分配'!S:S,"是")/D38 | G38: =COUNTIFS('零期·UV电访分配'!A:A,B38,'零期·UV电访分配'!T:T,"是")/D38 | H38: =COUNTIFS('零期·UV电访分配'!A:A,B38,'零期·UV电访分配'!AB:AB,"是")/D38 | I38: =COUNTIFS('零期·UV电访分配'!A:A,B38,'零期·UV电访分配'!AD:AD,"是")/D38 | J38: =SUMIF('零期·UV电访分配'!A:A,B38,'零期·UV电访分配'!AX:AX)/C38 | K38: =COUNTIFS('零期·UV电访分配'!A:A,B38,'零期·UV电访分配'!AM:AM,"S")+COUNTIFS('零期·UV电访分配'!A:A,B38,'零期·UV电访分配'!AN:AN,"S")+COUNTIFS('零期·UV电访分配'!A:A,B38,'零期·UV电访分配'!AO:AO,"S") | L38: =K38/C38 | M38: =COUNTIFS('零期·UV电访分配'!A:A,B38,'零期·UV电访分配'!AM:AM,"A")+COUNTIFS('零期·UV电访分配'!A:A,B38,'零期·UV电访分配'!AN:AN,"A")+COUNTIFS('零期·UV电访分配'!A:A,B38,'零期·UV电访分配'!AO:AO,"A") | N38: =M38/C38 | O38: =COUNTIFS('零期·UV电访分配'!A:A,B38,'零期·UV电访分配'!AM:AM,"B")+COUNTIFS('零期·UV电访分配'!A:A,B38,'零期·UV电访分配'!AN:AN,"B")+COUNTIFS('零期·UV电访分配'!A:A,B38,'零期·UV电访分配'!AO:AO,"B") | P38: =O38/C38 | Q38: =COUNTIFS('零期·UV电访分配'!A:A,B38,'零期·UV电访分配'!AM:AM,"C")+COUNTIFS('零期·UV电访分配'!A:A,B38,'零期·UV电访分配'!AN:AN,"C")+COUNTIFS('零期·UV电访分配'!A:A,B38,'零期·UV电访分配'!AO:AO,"C") | R38: =Q38/C38
B39: 新宝利 | C39: =SUMIF('零期·UV电访分配'!A:A,B39,'零期·UV电访分配'!AS:AS) | D39: =COUNTIF('零期·UV电访分配'!A:A,B39) | E39: =COUNTIFS('零期·UV电访分配'!A:A,B39,'零期·UV电访分配'!AH:AH,"是")/D39 | F39: =COUNTIFS('零期·UV电访分配'!A:A,B39,'零期·UV电访分配'!S:S,"是")/D39 | G39: =COUNTIFS('零期·UV电访分配'!A:A,B39,'零期·UV电访分配'!T:T,"是")/D39 | H39: =COUNTIFS('零期·UV电访分配'!A:A,B39,'零期·UV电访分配'!AB:AB,"是")/D39 | I39: =COUNTIFS('零期·UV电访分配'!A:A,B39,'零期·UV电访分配'!AD:AD,"是")/D39 | J39: =SUMIF('零期·UV电访分配'!A:A,B39,'零期·UV电访分配'!AX:AX)/C39 | K39: =COUNTIFS('零期·UV电访分配'!A:A,B39,'零期·UV电访分配'!AM:AM,"S")+COUNTIFS('零期·UV电访分配'!A:A,B39,'零期·UV电访分配'!AN:AN,"S")+COUNTIFS('零期·UV电访分配'!A:A,B39,'零期·UV电访分配'!AO:AO,"S") | L39: =K39/C39 | M39: =COUNTIFS('零期·UV电访分配'!A:A,B39,'零期·UV电访分配'!AM:AM,"A")+COUNTIFS('零期·UV电访分配'!A:A,B39,'零期·UV电访分配'!AN:AN,"A")+COUNTIFS('零期·UV电访分配'!A:A,B39,'零期·UV电访分配'!AO:AO,"A") | N39: =M39/C39 | O39: =COUNTIFS('零期·UV电访分配'!A:A,B39,'零期·UV电访分配'!AM:AM,"B")+COUNTIFS('零期·UV电访分配'!A:A,B39,'零期·UV电访分配'!AN:AN,"B")+COUNTIFS('零期·UV电访分配'!A:A,B39,'零期·UV电访分配'!AO:AO,"B") | P39: =O39/C39 | Q39: =COUNTIFS('零期·UV电访分配'!A:A,B39,'零期·UV电访分配'!AM:AM,"C")+COUNTIFS('零期·UV电访分配'!A:A,B39,'零期·UV电访分配'!AN:AN,"C")+COUNTIFS('零期·UV电访分配'!A:A,B39,'零期·UV电访分配'!AO:AO,"C") | R39: =Q39/C39
B40: 分校合计 | C40: =SUM(C37:C39) | D40: =SUM(D37:D39) | E40: =COUNTIF('零期·UV电访分配'!AH:AH,"是")/D40 | F40: =COUNTIF('零期·UV电访分配'!S:S,"是")/D40 | G40: =COUNTIF('零期·UV电访分配'!T:T,"是")/D40 | H40: =COUNTIF('零期·UV电访分配'!AB:AB,"是")/D40 | I40: =COUNTIF('零期·UV电访分配'!AD:AD,"是")/D40 | J40: ='零期·UV电访分配'!AX10/C40 | K40: =SUM(K37:K39) | L40: =K40/C40 | M40: =SUM(M37:M39) | N40: =M40/C40 | O40: =SUM(O37:O39) | P40: =O40/C40 | Q40: =SUM(Q37:Q39) | R40: =Q40/C40
B42: 零期汇总 | D42: 基础信息 | K42: 课前服务 | N42: 课中家长会
D43: =SUM(D45:D57)/2 | E43: =E49+E53+E57 | F43: =E43/(25*D43) | G43: =G49+G53+G57 | H43: =G43/E43 | I43: =SUM(I45:I57)/2 | J43: =I43/(E43+I43) | K43: =(K49*$E$49+K53*$E$53+K57*$E$57)/$E$43 | L43: =(L49*$E$49+L53*$E$53+L57*$E$57)/$E$43 | M43: =(M49*$E$49+M53*$E$53+M57*$E$57)/$E$43 | N43: =SUM(N45:N57)/2 | O43: =N43/E43 | P43: =SUM(P45:P57)/2 | Q43: =SUM(Q45:Q57)/2 | R43: =Q43/P43 | S43: =SUM(S45:S57)/2 | T43: =SUM(T45:T57)/2 | U43: =T43/S43 | V43: =SUM(V45:V57)/2 | W43: =V43/E43
B44: 老师看板 | C44: 学科 | D44: 班量 | E44: 在读PV | F44: 满班率 | G44: 暑续秋PV | H44: 转化率 | I44: 课前退PV | J44: 课前退率 | K44: 加微率 | L44: 首联率 | M44: vip入群率 | N44: 课中诺访 | O44: 诺访率PV | P44: 7月4日应到 | Q44: 7月4日实到 | R44: 到场率 | S44: 7月5日应到 | T44: 7月5日实到 | U44: 到场率 | V44: 整体到场 | W44: 到场率
...

Sheet 一期·UV电访分配
A1: 教学点 | B1: 学生uid | C1: 学生姓名 | D1: 归属顾问 | E1: 雪球思维 | J1: 悦读创作 | N1: 双语素养 | R1: 课前电访-顾问（T-2） | AA1: 需求分析 | AD1: 具体需求（目标/学能/老师关注度） | AE1: 报名阈值 | AK1: 课前家长会-老师（T-2） | AN1: 首课电联-老师&顾问（U1～U5） | BD1: 课中家长会-老师&顾问（T4～T7） | BF1: 学员情况-顾问 | BI1: 首课电访（U1）-顾问 | BK1: 意向盘点（U3）-顾问&老师 | BP1: 满意度调查（U4）-顾问 | BQ1: 意向校准（U5）-顾问 | BR1: 在读 | BS1: 应续 | BT1: 数 | BU1: 语 | BV1: 英 | BW1: 已续 | BX1: 未续报卡点-顾问
E2: 主讲 | F2: 上课时段 | G2: 班型 | H2: 期次 | I2: 是否在读 | J2: 主讲 | K2: 上课时段 | L2: 期次 | M2: 是否在读 | N2: 主讲 | O2: 上课时段 | P2: 期次 | Q2: 是否在读 | R2: 是否VIP群 | S2: 意向盘点 | T2: 是否到店测试 | U2: 报读科目是否在同一期 | V2: 学校（小学/初中） | W2: 校内成绩 | X2: 学习习惯 | Y2: 报名初衷 | Z2: 电访记录（为什么报，校内成绩，学习习惯，学校） | AA2: 需求 | AB2: 沟通判定记录 | AC2: 需求学科 | AD2: 目标：提分、目标高中（公办）、自主、指标到校 学能：习惯、意愿、 老师关注度：课堂提问、给家长个性化反馈（互动）、多表扬、 | AE2: 需求紧迫性 | AF2: 付费能力 | AG2: 孩子意愿 | AH2: 家长认可度 | AI2: 家长意识 | AJ2: 意向判定 | AK2: 邀约人 | AL2: 课前诺访 | AM2: 课前确访 | AN2: 电联人（U1） | AO2: 是否完成 | AP2: 跟进记录 | AQ2: 电联人（U2） | AR2: 是否完成 | AS2: 跟进记录 | AT2: 电联人（U3） | AU2: 是否完成 | AV2: 跟进记录 | AW2: 电联人（U4） | AX2: 是否完成 | AY2: 课中诺访 | AZ2: 跟进记录 | BA2: 电联人（U5） | BB2: 是否完成 | BC2: 跟进记录 | BD2: 现场跟进人 | BE2: 课中确访 | BF2: 顾问 | BG2: 介绍人 | BH2: 中签学校 | BI2: 电访记录 | BJ2: 核心诉求 | BK2: 学员意向 | BL2: 数学 | BM2: 语文 | BN2: 英语 | BO2: 判定依据 | BP2: 是否参与 | BQ2: 校准依据 | BR2: =SUM(BR3:BR128) | BS2: =SUM(BS3:BS128) | BT2: =COUNTIF(BT3:BT128,"是") | BU2: =COUNTIF(BU3:BU128,"是") | BV2: =COUNTIF(BV3:BV128,"是") | BW2: =SUM(BW3:BW128) | BX2: （U3～U4） | BY2: （T6～T7） | BZ2: （U8～U10）
A3: 新宝利 | B3: 2341143960 | C3: =VLOOKUP(B3,'UV台帐'!B:AL,2,0) | D3: =VLOOKUP(B3,'UV台帐'!B:AL,3,0) | E3: =VLOOKUP(B3,'UV台帐'!B:AL,13,0) | F3: =VLOOKUP(B3,'UV台帐'!B:AL,15,0) | G3: =VLOOKUP(B3,'UV台帐'!B:AL,16,0) | H3: =VLOOKUP(B3,'UV台帐'!B:AL,17,0) | I3: =VLOOKUP(B3,'UV台帐'!B:AL,18,0) | J3: =VLOOKUP(B3,'UV台帐'!B:AL,22,0) | K3: =VLOOKUP(B3,'UV台帐'!B:AL,24,0) | L3: =VLOOKUP(B3,'UV台帐'!B:AL,26,0) | M3: =VLOOKUP(B3,'UV台帐'!B:AL,27,0) | N3: =VLOOKUP(B3,'UV台帐'!B:AL,31,0) | O3: =VLOOKUP(B3,'UV台帐'!B:AL,33,0) | P3: =VLOOKUP(B3,'UV台帐'!B:AL,35,0) | Q3: =VLOOKUP(B3,'UV台帐'!B:AL,36,0) | R3: 是 | S3: B | T3: 是 | U3: 否 | W3: 语文90，英语95 | X3: 学习习惯一般 | Y3: 小升初衔接 | Z3: 价格敏感型，开眼镜店最近生意不好，妈妈比较关注学习习惯，价格便宜可能会考虑。大概率后面会磨价格B，其他机构在读，语文和英语，报过价格，觉得贵。 | AA3: 明确需求 | AB3: 家长做门店生意，妈妈平时没时间过多关注孩子的学习情况，比较关注孩子学习效果和学习习惯改善，价格便宜可能会考虑，报过价格，觉得贵。 | AD3: 效果维度-提分,效果维度-抓习惯 | AE3: 1.不紧迫，觉得初一不需要学 | AF3: 1-无支付能力 | AG3: 2-一般 | AH3: 2-评价一般、无感 | AI3: 2-有意识无规划 | AJ3: C-小于8 | AK3: 陈南05 | AL3: 是 | BF3: 杨林33 | BG3: =VLOOKUP(B3,'UV台帐'!B:G,6,0) | BR3: =COUNTIFS(H3,"一期",I3,"在读")+COUNTIFS(L3,"一期",M3,"在读")+COUNTIFS(P3,"一期",Q3,"在读") | BS3: =BR3-BW3 | BT3: =VLOOKUP(B3,'UV台帐'!B:AL,19,0) | BU3: =VLOOKUP(B3,'UV台帐'!B:AL,28,0) | BV3: =VLOOKUP(B3,'UV台帐'!B:AL,37,0) | BW3: =COUNTIFS(H3,"一期",BT3,"是")+COUNTIFS(L3,"一期",BU3,"是")+COUNTIFS(P3,"一期",BV3,"是") | CA3: 2341143960
A4: 新宝利 | B4: 2649629431 | C4: =VLOOKUP(B4,'UV台帐'!B:AL,2,0) | D4: =VLOOKUP(B4,'UV台帐'!B:AL,3,0) | E4: =VLOOKUP(B4,'UV台帐'!B:AL,13,0) | F4: =VLOOKUP(B4,'UV台帐'!B:AL,15,0) | G4: =VLOOKUP(B4,'UV台帐'!B:AL,16,0) | H4: =VLOOKUP(B4,'UV台帐'!B:AL,17,0) | I4: =VLOOKUP(B4,'UV台帐'!B:AL,18,0) | J4: =VLOOKUP(B4,'UV台帐'!B:AL,22,0) | K4: =VLOOKUP(B4,'UV台帐'!B:AL,24,0) | L4: =VLOOKUP(B4,'UV台帐'!B:AL,26,0) | M4: =VLOOKUP(B4,'UV台帐'!B:AL,27,0) | N4: =VLOOKUP(B4,'UV台帐'!B:AL,31,0) | O4: =VLOOKUP(B4,'UV台帐'!B:AL,33,0) | P4: =VLOOKUP(B4,'UV台帐'!B:AL,35,0) | Q4: =VLOOKUP(B4,'UV台帐'!B:AL,36,0) | R4: 是 | S4: B | T4: 是 | U4: 是 | V4: 4小学，65中 | W4: 语文90，数学95，英语90 | Y4: 朋友介绍说有课一起学习感受一下 | Z4: 白云距离远，1小时通勤，过往补习经历卓越1-2年，B；6000/3课/30次课，寒暑。一个小时，转介绍。 | AA4: 明确需求 | AB4: 7月11日线下诊断面谈，语文，不稳定，阅读（家长关注，他其实不太清楚，希望老师分析什么薄弱），写作（关注孩子的框架老师说结构不好）， 英语成绩优异，学校，但是书面成绩好，口语不好，担心初中口语不行，重点关注口语读的模块，各方面的都不错英语。 数学是孩子最好的科目，基本95，诊断成绩也80+，没有明确太弱的模块，但是方程计算还是会出错。 对孩子的关注度可以的，家长讲了很多英语要会讲，孩子习惯方面一般重难点部分不爱圈重点，书面不错，家长还说了因为跨段上课，需要白老师 @林志豪01(白老师)协助中午午休后2点收一下孩子的电子产品，让他们把早上的数学和英语作业做了，如果语文作文课要求，留下做完走。沟通期间说过数学也有考虑，英语有明确的提升的需求。 | AC4: 英 | AD4: 效果维度-提分,效果维度-抓习惯 | AE4: 2-一般，对于目标需求一般 | AF4: 2-支付能力一般 | AG4: 2-一般 | AH4: 2-一般 | AI4: 2-有意识无规划 | AJ4: B-8-10 | AK4: 何咏04 | AL4: 是 | BF4: 林志豪01 | BG4: =VLOOKUP(B4,'UV台帐'!B:G,6,0) | BR4: =COUNTIFS(H4,"一期",I4,"在读")+COUNTIFS(L4,"一期",M4,"在读")+COUNTIFS(P4,"一期",Q4,"在读") | BS4: =BR4-BW4 | BT4: =VLOOKUP(B4,'UV台帐'!B:AL,19,0) | BU4: =VLOOKUP(B4,'UV台帐'!B:AL,28,0) | BV4: =VLOOKUP(B4,'UV台帐'!B:AL,37,0) | BW4: =COUNTIFS(H4,"一期",BT4,"是")+COUNTIFS(L4,"一期",BU4,"是")+COUNTIFS(P4,"一期",BV4,"是") | BX4: 语文，不稳定，阅读（关注，分析什么薄弱），写作（关注孩子的，框架），英语口语好重点关注。作文课留下来做完。 | CA4: 2649629431
A5: 新宝利 | B5: 2704638904 | C5: =VLOOKUP(B5,'UV台帐'!B:AL,2,0) | D5: =VLOOKUP(B5,'UV台帐'!B:AL,3,0) | E5: =VLOOKUP(B5,'UV台帐'!B:AL,13,0) | F5: =VLOOKUP(B5,'UV台帐'!B:AL,15,0) | G5: =VLOOKUP(B5,'UV台帐'!B:AL,16,0) | H5: =VLOOKUP(B5,'UV台帐'!B:AL,17,0) | I5: =VLOOKUP(B5,'UV台帐'!B:AL,18,0) | J5: =VLOOKUP(B5,'UV台帐'!B:AL,22,0) | K5: =VLOOKUP(B5,'UV台帐'!B:AL,24,0) | L5: =VLOOKUP(B5,'UV台帐'!B:AL,26,0) | M5: =VLOOKUP(B5,'UV台帐'!B:AL,27,0) | N5: =VLOOKUP(B5,'UV台帐'!B:AL,31,0) | O5: =VLOOKUP(B5,'UV台帐'!B:AL,33,0) | P5: =VLOOKUP(B5,'UV台帐'!B:AL,35,0) | Q5: =VLOOKUP(B5,'UV台帐'!B:AL,36,0) | R5: 是 | S5: B | T5: 是 | U5: 是 | V5: 4小学，65中 | W5: 语文85+，数学100，英语85+ | Y5: 找英语机构，价格贵 | Z5: 白云，距离远，1小时通勤，数学基本满分，语文英语弱，考虑过秋季，但是要好才可以，价格偏高.B，线下面谈，问过价格。4000价格。有报签测成绩，语文：阅读写作方法，写作，多互动，偏内向，背单词没办法。作文写完回去。 | AA5: 明确需求 | AB5: 7月初首次面谈，7月11日线下诊断面谈，家长虽然白云，但是配合度很高，详细沟通如下 7月初首次通过外呼激活，邀约线下，初次见面就带孩子来，了解了大纲，师资，秋季价格，初次沟通妈咪，说过在家有补课英语效果不好换机构，学的好考虑英语 7月11日沟通： 语文，孩子和华辰是朋友，语文阅读是差于华辰，具体在理解段落中心方面重视写不全，找不准，希望老师能给孩子一些好的方法能找到，作文内容可以的，但是校内老师说结构不好，没框架。 数学：数学孩子成绩很优秀基本100分校内，但是本次诊断错了一题方程，妈咪很诧异，因为孩子是参加过华新入学考，且考试难度高于诊断，觉得孩子总是出现低级错误。思维方面都很不错在几何方面。 英语：妈咪重点关注科目，孩子校内成绩是A，但是孩子这边平时看他测试和背书，完全没办法，尤其是单词模块，就是硬背，很担心孩子初中遇到长单词更难，口语太难，妈咪说学校不教口语模块，他的口语想一个个词读句子，太烂了，希望老师多让他开口读。 对孩子的关注度高，过了入学考的华新，但是最终选择65中MK过，因为民办太贵原因，孩子书写很大字，语文老师 @陈南05(陈南)家长希望能给些建议，该批评批评，知道这样中考书写太吃亏，家长还说了因为跨段上课，需要白老师协助中午午休后2点收一下孩子的电子产品，让他们把早上的数学和英语作业做了，如果语文作文课要求，留下做完走。沟通期间说过数学也有考虑，英语有明确的提升的需求 | AC5: 语,英 | AD5: 效果维度-提分,效果维度-抓习惯,沟通维度：老师有个性化,沟通维度：老师有关注度 | AE5: 3-非常紧迫，有短期目标和长期需求 | AF5: 2-支付能力一般 | AG5: 2-一般 | AH5: 2-评价一般、无感 | AI5: 3-有规划有意识 | AJ5: A-11-13 | AK5: 何咏04 | AL5: 是 | BF5: 林志豪01 | BG5: =VLOOKUP(B5,'UV台帐'!B:G,6,0) | BR5: =COUNTIFS(H5,"一期",I5,"在读")+COUNTIFS(L5,"一期",M5,"在读")+COUNTIFS(P5,"一期",Q5,"在读") | BS5: =BR5-BW5 | BT5: =VLOOKUP(B5,'UV台帐'!B:AL,19,0) | BU5: =VLOOKUP(B5,'UV台帐'!B:AL,28,0) | BV5: =VLOOKUP(B5,'UV台帐'!B:AL,37,0) | BW5: =COUNTIFS(H5,"一期",BT5,"是")+COUNTIFS(L5,"一期",BU5,"是")+COUNTIFS(P5,"一期",BV5,"是") | BX5: 语文：阅读写作方法，写作，多互动，偏内向，背单词没办法。作文写完回去。 | CA5: 2715584701
A6: 新宝利 | B6: 2260449861 | C6: =VLOOKUP(B6,'UV台帐'!B:AL,2,0) | D6: =VLOOKUP(B6,'UV台帐'!B:AL,3,0) | E6: =VLOOKUP(B6,'UV台帐'!B:AL,13,0) | F6: =VLOOKUP(B6,'UV台帐'!B:AL,15,0) | G6: =VLOOKUP(B6,'UV台帐'!B:AL,16,0) | H6: =VLOOKUP(B6,'UV台帐'!B:AL,17,0) | I6: =VLOOKUP(B6,'UV台帐'!B:AL,18,0) | J6: =VLOOKUP(B6,'UV台帐'!B:AL,22,0) | K6: =VLOOKUP(B6,'UV台帐'!B:AL,24,0) | L6: =VLOOKUP(B6,'UV台帐'!B:AL,26,0) | M6: =VLOOKUP(B6,'UV台帐'!B:AL,27,0) | N6: =VLOOKUP(B6,'UV台帐'!B:AL,31,0) | O6: =VLOOKUP(B6,'UV台帐'!B:AL,33,0) | P6: =VLOOKUP(B6,'UV台帐'!B:AL,35,0) | Q6: =VLOOKUP(B6,'UV台帐'!B:AL,36,0) | R6: 是 | S6: A | T6: 否 | U6: 是 | V6: 民德实验 | W6: 三科290,希望杯+PET | X6: 学习习惯良好 | Y6: 衔接初一内容，学的好可以秋季 | Z6: 主动询问秋季班的价格，有长期学的想法，之前有长期的补习经历，小奥有学。A，到店面谈了，校内学生手册成绩单进班，没有明显薄弱，英语过P，具体情况希望三科老师去评估 补习：爱普英语，进阶集训队340 3个半小时，语文也去卓越在学 暑假过来感受学习效果，学的好考虑长期学 | AA6: 明确需求 | AB6: 妈妈反馈没有明显知识薄弱，英语过P，具体学科情况等上暑假让三科老师去评估 补习经历：爱普英语，进阶集训队340 3个半小时，语文也去卓越在学 暑假过来感受整体的学习效果，学的好考虑长期学，目标是能跟得上名德重点班的学习难度。高中目标肯定是冲九大。 | AC6: 语,数 | AD6: 效果维度-提分,沟通维度：老师有关注度 | AE6: 2-一般，对于目标需求一般 | AF6: 2-支付能力一般 | AG6: 3-喜欢 | AH6: 2-评价一般、无感 | AI6: 3-有规划有意识 | AJ6: A-11-13 | AK6: 何咏04 | AL6: 是 | BF6: 杨林33 | BG6: =VLOOKUP(B6,'UV台帐'!B:G,6,0) | BH6: 三中 | BR6: =COUNTIFS(H6,"一期",I6,"在读")+COUNTIFS(L6,"一期",M6,"在读")+COUNTIFS(P6,"一期",Q6,"在读") | BS6: =BR6-BW6 | BT6: =VLOOKUP(B6,'UV台帐'!B:AL,19,0) | BU6: =VLOOKUP(B6,'UV台帐'!B:AL,28,0) | BV6: =VLOOKUP(B6,'UV台帐'!B:AL,37,0) | BW6: =COUNTIFS(H6,"一期",BT6,"是")+COUNTIFS(L6,"一期",BU6,"是")+COUNTIFS(P6,"一期",BV6,"是") | CA6: 4103453629
A7: 同创汇 | B7: 2715584701 | C7: =VLOOKUP(B7,'UV台帐'!B:AL,2,0) | D7: =VLOOKUP(B7,'UV台帐'!B:AL,3,0) | E7: =VLOOKUP(B7,'UV台帐'!B:AL,13,0) | F7: =VLOOKUP(B7,'UV台帐'!B:AL,15,0) | G7: =VLOOKUP(B7,'UV台帐'!B:AL,16,0) | H7: =VLOOKUP(B7,'UV台帐'!B:AL,17,0) | I7: =VLOOKUP(B7,'UV台帐'!B:AL,18,0) | J7: =VLOOKUP(B7,'UV台帐'!B:AL,22,0) | K7: =VLOOKUP(B7,'UV台帐'!B:AL,24,0) | L7: =VLOOKUP(B7,'UV台帐'!B:AL,26,0) | M7: =VLOOKUP(B7,'UV台帐'!B:AL,27,0) | N7: =VLOOKUP(B7,'UV台帐'!B:AL,31,0) | O7: =VLOOKUP(B7,'UV台帐'!B:AL,33,0) | P7: =VLOOKUP(B7,'UV台帐'!B:AL,35,0) | Q7: =VLOOKUP(B7,'UV台帐'!B:AL,36,0) | R7: 是 | S7: B | T7: 否 | U7: 否 | W7: 语文85+，数学95+，英语85+ | X7: 很好，孩子会有很多自己的想法 | Y7: 朋友推荐，一起来提前学新初一，暑假衔接 | Z7: 聊了之后孩子偏好动，多关注一下，聊了平时没有补课的习惯，暑假让他提前过度一下，B。线下聊过价格，校内成绩进班。 | AA7: 明确需求 | AB7: 7月8日沟通，电话沟通 语文：孩子阅读写作是薄弱的，语基部分平时捉的孩子背严格，但是感觉现在阅读和写作得不像当年难了 数学：孩子数学是没什么短板，成绩基本95+，学校考试基本就是计算或者粗心错几分，但是没有提前学 英语：孩子英语也比较稳定，单词会偶尔拼写错误，但整体还行，作文也还可以得，主要阅读和听力会稍微扣分多一些 孩子整体习惯偏好，妈咪说孩子坐久了会动，让助教老师可以在偏边关注一下，沟通暑假报名初衷，妈咪说今年分班，初一想往上冲冲，又因为没提前学，所以暑假找班学，长期规划看孩子意愿情况 | AC7: 语,英 | AD7: 效果维度-提分,效果维度-培优拓展/分班考 | AE7: 2-一般，对于目标需求一般 | AF7: 2-支付能力一般 | AG7: 2-一般 | AH7: 2-评价一般、无感 | AI7: 2-有意识无规划 | AJ7: B-8-10 | AK7: 何咏04 | AL7: 是 | BF7: 林志豪01 | BG7: =VLOOKUP(B7,'UV台帐'!B:G,6,0) | BH7: 三中/二中 | BR7: =COUNTIFS(H7,"一期",I7,"在读")+COUNTIFS(L7,"一期",M7,"在读")+COUNTIFS(P7,"一期",Q7,"在读") | BS7: =BR7-BW7 | BT7: =VLOOKUP(B7,'UV台帐'!B:AL,19,0) | BU7: =VLOOKUP(B7,'UV台帐'!B:AL,28,0) | BV7: =VLOOKUP(B7,'UV台帐'!B:AL,37,0) | BW7: =COUNTIFS(H7,"一期",BT7,"是")+COUNTIFS(L7,"一期",BU7,"是")+COUNTIFS(P7,"一期",BV7,"是") | CA7: 2489383127
A8: 同创汇 | B8: 2743981182 | C8: =VLOOKUP(B8,'UV台帐'!B:AL,2,0) | D8: =VLOOKUP(B8,'UV台帐'!B:AL,3,0) | E8: =VLOOKUP(B8,'UV台帐'!B:AL,13,0) | F8: =VLOOKUP(B8,'UV台帐'!B:AL,15,0) | G8: =VLOOKUP(B8,'UV台帐'!B:AL,16,0) | H8: =VLOOKUP(B8,'UV台帐'!B:AL,17,0) | I8: =VLOOKUP(B8,'UV台帐'!B:AL,18,0) | J8: =VLOOKUP(B8,'UV台帐'!B:AL,22,0) | K8: =VLOOKUP(B8,'UV台帐'!B:AL,24,0) | L8: =VLOOKUP(B8,'UV台帐'!B:AL,26,0) | M8: =VLOOKUP(B8,'UV台帐'!B:AL,27,0) | N8: =VLOOKUP(B8,'UV台帐'!B:AL,31,0) | O8: =VLOOKUP(B8,'UV台帐'!B:AL,33,0) | P8: =VLOOKUP(B8,'UV台帐'!B:AL,35,0) | Q8: =VLOOKUP(B8,'UV台帐'!B:AL,36,0) | R8: 是 | S8: B | T8: 否 | U8: 否 | W8: B | Y8: 端内线索，暑假体验下，后续上的好有计划跟着学 | Z8: 数学在其他机构上课，英语阅读和写作较弱，语文阅读较弱 | AA8: 明确需求 | AB8: 孩子小学三年级前学过KET，但是后面没有坚持，孩子词汇量不够，后面需要多加强词汇的积累。语文阅读较弱，课外读物比较少，需要提升孩子阅读答题技巧。孩子性格比较活泼一些，但不是那种捣蛋型的，有的时候静不下来，需要老师提要求，多监督 | AC8: 语,英 | AD8: 效果维度-提分,效果维度-抓习惯,沟通维度：老师有关注度 | AE8: 2-一般，对于目标需求一般 | AF8: 2-支付能力一般 | AG8: 2-一般 | AH8: 2-评价一般、无感 | AI8: 2-有意识无规划 | AJ8: B-8-10 | AK8: 陈南05 | BF8: 王丽 | BG8: =VLOOKUP(B8,'UV台帐'!B:G,6,0) | BH8: 广大附 | BR8: =COUNTIFS(H8,"一期",I8,"在读")+COUNTIFS(L8,"一期",M8,"在读")+COUNTIFS(P8,"一期",Q8,"在读") | BS8: =BR8-BW8 | BT8: =VLOOKUP(B8,'UV台帐'!B:AL,19,0) | BU8: =VLOOKUP(B8,'UV台帐'!B:AL,28,0) | BV8: =VLOOKUP(B8,'UV台帐'!B:AL,37,0) | BW8: =COUNTIFS(H8,"一期",BT8,"是")+COUNTIFS(L8,"一期",BU8,"是")+COUNTIFS(P8,"一期",BV8,"是") | CA8: 2554261157
A9: 同创汇 | B9: 4103453629 | C9: =VLOOKUP(B9,'UV台帐'!B:AL,2,0) | D9: =VLOOKUP(B9,'UV台帐'!B:AL,3,0) | E9: =VLOOKUP(B9,'UV台帐'!B:AL,13,0) | F9: =VLOOKUP(B9,'UV台帐'!B:AL,15,0) | G9: =VLOOKUP(B9,'UV台帐'!B:AL,16,0) | H9: =VLOOKUP(B9,'UV台帐'!B:AL,17,0) | I9: =VLOOKUP(B9,'UV台帐'!B:AL,18,0) | J9: =VLOOKUP(B9,'UV台帐'!B:AL,22,0) | K9: =VLOOKUP(B9,'UV台帐'!B:AL,24,0) | L9: =VLOOKUP(B9,'UV台帐'!B:AL,26,0) | M9: =VLOOKUP(B9,'UV台帐'!B:AL,27,0) | N9: =VLOOKUP(B9,'UV台帐'!B:AL,31,0) | O9: =VLOOKUP(B9,'UV台帐'!B:AL,33,0) | P9: =VLOOKUP(B9,'UV台帐'!B:AL,35,0) | Q9: =VLOOKUP(B9,'UV台帐'!B:AL,36,0) | R9: 是 | S9: B | T9: 否 | U9: 是 | V9: 天河中学猎德实验 | W9: 285 | X9: 学习态度：能自学 学习习惯：比较认真 性格：前期腼腆慢热 | Y9: 初中做好小升初衔接，想要冲重点班 | Z9: 摇中了猎德实验，有分层考，如有资料可以加餐 孩子性格：安静的性格，会举手回答老师问题，想要严格型的老师 报名是因为性价比高，前期对比了其他机构，认为咱教学大纲符合孩子的学习需求，前期问了我们要校内的电子版课本和分班考资料 妈妈问班容，问吃饭安排 | AA9: 明确需求 | AB9: 要冲天河中学猎德实验学校分层考 ，性格斯斯文文慢热型的孩子，需求是多鼓励和关注孩子 语文：字词、古诗文默写偶尔粗心丢分，文言文积累少，不会翻译，简单基础题无故丢分 数学：拓展综合题、几何模型丢分多 英语：听力，写作题型答题技巧需要帮助孩子提升 | AC9: 语,数,英 | AD9: 效果维度-提分,效果维度-抓习惯,效果维度-培优拓展/分班考,沟通维度：老师有个性化 | AE9: 2-一般，对于目标需求一般 | AF9: 2-支付能力一般 | AG9: 2-一般 | AH9: 2-评价一般、无感 | AI9: 2-有意识无规划 | AJ9: B-8-10 | AK9: 陈南05 | BF9: 苏丽婷 | BG9: =VLOOKUP(B9,'UV台帐'!B:G,6,0) | BH9: 猎德实验 | BR9: =COUNTIFS(H9,"一期",I9,"在读")+COUNTIFS(L9,"一期",M9,"在读")+COUNTIFS(P9,"一期",Q9,"在读") | BS9: =BR9-BW9 | BT9: =VLOOKUP(B9,'UV台帐'!B:AL,19,0) | BU9: =VLOOKUP(B9,'UV台帐'!B:AL,28,0) | BV9: =VLOOKUP(B9,'UV台帐'!B:AL,37,0) | BW9: =COUNTIFS(H9,"一期",BT9,"是")+COUNTIFS(L9,"一期",BU9,"是")+COUNTIFS(P9,"一期",BV9,"是") | CA9: 2579947640
A10: 同创汇 | B10: 2489383127 | C10: =VLOOKUP(B10,'UV台帐'!B:AL,2,0) | D10: =VLOOKUP(B10,'UV台帐'!B:AL,3,0) | E10: =VLOOKUP(B10,'UV台帐'!B:AL,13,0) | F10: =VLOOKUP(B10,'UV台帐'!B:AL,15,0) | G10: =VLOOKUP(B10,'UV台帐'!B:AL,16,0) | H10: =VLOOKUP(B10,'UV台帐'!B:AL,17,0) | I10: =VLOOKUP(B10,'UV台帐'!B:AL,18,0) | J10: =VLOOKUP(B10,'UV台帐'!B:AL,22,0) | K10: =VLOOKUP(B10,'UV台帐'!B:AL,24,0) | L10: =VLOOKUP(B10,'UV台帐'!B:AL,26,0) | M10: =VLOOKUP(B10,'UV台帐'!B:AL,27,0) | N10: =VLOOKUP(B10,'UV台帐'!B:AL,31,0) | O10: =VLOOKUP(B10,'UV台帐'!B:AL,33,0) | P10: =VLOOKUP(B10,'UV台帐'!B:AL,35,0) | Q10: =VLOOKUP(B10,'UV台帐'!B:AL,36,0) | R10: 是 | S10: B | T10: 否 | U10: 是 | W10: 语90，数90，英90 | X10: 数学压轴题要加强，希望老师梳理做题步骤，英语语法薄弱，语文字词粗心 | Y10: 1. 语文：基础字词容易粗心写错，希望课上加强生字默写、阅读理解答题方法指导，顺带积累作文短句素材； 2. 数学：压轴题他要加强，做题耐心不足，计算容易出错，麻烦老师帮孩子梳理审题步骤，纠正马虎的答题习惯； 3. 英语：语法知识点记不牢，麻烦老师用轻量化的练习巩固语法，顺带督促单词日常背诵。 | Z10: 没有线下课补习经历 孩子近视，需要助教老师注意下前面2讲铭牌放前面一点，也发了期望暑假学习孩子能有进步，解决某些问题。过往都是网课，家住白云距离远，可能有价格异议。比较晚报名，线上直收的，没有做入学测，家长愿意来线下，家长表示暑假学的好是可以考虑长期学的 | AA10: 明确需求 | AB10: 语数英都有薄弱点，期望老师解决孩子短板1. 语文：基础字词容易粗心写错，希望课上加强生字默写、阅读理解答题方法指导，顺带积累作文短句素材； 2. 数学：压轴题他要加强，做题耐心不足，计算容易出错，麻烦老师帮孩子梳理审题步骤，纠正马虎的答题习惯； 3. 英语：语法知识点记不牢，麻烦老师用轻量化的练习巩固语法，顺带督促单词日常背诵。孩子近视，需要助教老师注意下让孩子坐前排，也需求是是想奔着初中重点班去的（白云区的中学）但是担心孩子不太适应，没有补习经历，家长配合度挺高，表示暑假上的好，有需要是会考虑，距离较远 | AC10: 语,数,英 | AD10: 效果维度-提分,效果维度-抓习惯 | AE10: 2-一般，对于目标需求一般 | AF10: 2-支付能力一般 | AG10: 2-一般 | AH10: 2-评价一般、无感 | AI10: 2-有意识无规划 | AJ10: B-8-10 | AK10: 陈南05 | BF10: 张敏烨 | BG10: =VLOOKUP(B10,'UV台帐'!B:G,6,0) | BR10: =COUNTIFS(H10,"一期",I10,"在读")+COUNTIFS(L10,"一期",M10,"在读")+COUNTIFS(P10,"一期",Q10,"在读") | BS10: =BR10-BW10 | BT10: =VLOOKUP(B10,'UV台帐'!B:AL,19,0) | BU10: =VLOOKUP(B10,'UV台帐'!B:AL,28,0) | BV10: =VLOOKUP(B10,'UV台帐'!B:AL,37,0) | BW10: =COUNTIFS(H10,"一期",BT10,"是")+COUNTIFS(L10,"一期",BU10,"是")+COUNTIFS(P10,"一期",BV10,"是") | CA10: 2446527834
A11: 同创汇 | B11: 2554261157 | C11: =VLOOKUP(B11,'UV台帐'!B:AL,2,0) | D11: =VLOOKUP(B11,'UV台帐'!B:AL,3,0) | E11: =VLOOKUP(B11,'UV台帐'!B:AL,13,0) | F11: =VLOOKUP(B11,'UV台帐'!B:AL,15,0) | G11: =VLOOKUP(B11,'UV台帐'!B:AL,16,0) | H11: =VLOOKUP(B11,'UV台帐'!B:AL,17,0) | I11: =VLOOKUP(B11,'UV台帐'!B:AL,18,0) | J11: =VLOOKUP(B11,'UV台帐'!B:AL,22,0) | K11: =VLOOKUP(B11,'UV台帐'!B:AL,24,0) | L11: =VLOOKUP(B11,'UV台帐'!B:AL,26,0) | M11: =VLOOKUP(B11,'UV台帐'!B:AL,27,0) | N11: =VLOOKUP(B11,'UV台帐'!B:AL,31,0) | O11: =VLOOKUP(B11,'UV台帐'!B:AL,33,0) | P11: =VLOOKUP(B11,'UV台帐'!B:AL,35,0) | Q11: =VLOOKUP(B11,'UV台帐'!B:AL,36,0) | R11: 是 | S11: B | U11: 是 | V11: 五羊 | W11: 286 | X11: 数学好英语差点，语文一般，需要多鼓励 | Y11: 孩子奶奶报的，父母相送孩子去上一对一，但是奶奶认为孩子需要多接触，奶一直有说，没有伙伴想一起来上课，说明孩子比较内向，可以用班课上课形式来改善孩子，看到改变就可以报名 | Z11: 孩子奶奶交的费用，奶奶告知父母比较偏向让孩子上一对一，孩子小学三科A，之前在新东方上过课，孩子认可，后续会考虑在我们这边长期学，问了课程内容，上课形式，人数 | AA11: 明确需求 | AB11: 奶奶交的费用，父母想去一对一，但是奶奶认为可以让孩子来试一下，孩子学习比较懒散，需要人盯着，需要有老师给出孩子提升点和进步点，加强孩子自信心，给出明确初中学习规划 | AC11: 语,数,英 | AD11: 升学需求-保底本区公办高中,效果维度-提分,效果维度-抓习惯,沟通维度：老师有关注度 | AE11: 2-一般，对于目标需求一般 | AF11: 3-支付能力强 | AG11: 2-一般 | AH11: 1-有雷点、槽点 | AI11: 2-有意识无规划 | AJ11: B-8-10 | AK11: 陈南05 | BF11: 戎凯01 | BG11: =VLOOKUP(B11,'UV台帐'!B:G,6,0) | BR11: =COUNTIFS(H11,"一期",I11,"在读")+COUNTIFS(L11,"一期",M11,"在读")+COUNTIFS(P11,"一期",Q11,"在读") | BS11: =BR11-BW11 | BT11: =VLOOKUP(B11,'UV台帐'!B:AL,19,0) | BU11: =VLOOKUP(B11,'UV台帐'!B:AL,28,0) | BV11: =VLOOKUP(B11,'UV台帐'!B:AL,37,0) | BW11: =COUNTIFS(H11,"一期",BT11,"是")+COUNTIFS(L11,"一期",BU11,"是")+COUNTIFS(P11,"一期",BV11,"是") | CA11: 2519148407
A12: 新宝利 | B12: 4860505150 | C12: =VLOOKUP(B12,'UV台帐'!B:AL,2,0) | D12: =VLOOKUP(B12,'UV台帐'!B:AL,3,0) | E12: =VLOOKUP(B12,'UV台帐'!B:AL,13,0) | F12: =VLOOKUP(B12,'UV台帐'!B:AL,15,0) | G12: =VLOOKUP(B12,'UV台帐'!B:AL,16,0) | H12: =VLOOKUP(B12,'UV台帐'!B:AL,17,0) | I12: =VLOOKUP(B12,'UV台帐'!B:AL,18,0) | J12: =VLOOKUP(B12,'UV台帐'!B:AL,22,0) | K12: =VLOOKUP(B12,'UV台帐'!B:AL,24,0) | L12: =VLOOKUP(B12,'UV台帐'!B:AL,26,0) | M12: =VLOOKUP(B12,'UV台帐'!B:AL,27,0) | N12: =VLOOKUP(B12,'UV台帐'!B:AL,31,0) | O12: =VLOOKUP(B12,'UV台帐'!B:AL,33,0) | P12: =VLOOKUP(B12,'UV台帐'!B:AL,35,0) | Q12: =VLOOKUP(B12,'UV台帐'!B:AL,36,0) | R12: 是 | S12: S | T12: 否 | U12: 是 | V12: 回民小学/华侨 | W12: 280 | X12: 比较懒散，数学和英语偏弱 | Y12: 转介绍，家长觉得孩子成绩不行，自己又没时间管孩子，需要有课外机构进行保驾护航。 | Z12: 抓介绍，已面谈过。孩子成绩比较薄弱，妈妈对于孩子学习是比较着急的，但是比较理性。知道学习还是要靠课外机构提升。已明确续费意向。介绍人博睿三科报名；孩子是同学，母亲是闺蜜。 | AA12: 明确需求 | AB12: 基本情况：转介绍，孩子成绩比较薄弱，妈妈对于孩子学习是比较着急的，知道学习还是要靠课外机构提升。已明确续费意向。介绍人博睿三科报名；孩子是同学，母亲是好朋友。 需求判定：妈妈希望各科老师抓孩子的习惯，例如笔记字迹；学习主动性，特别是语文和英语。希望老师在前几次课多提问孩子，提升孩子投入度。 | AC12: 语,数,英 | AD12: 效果维度-抓习惯,沟通维度：老师有关注度 | AE12: 3-非常紧迫，有短期目标和长期需求 | AF12: 3-支付能力强 | AG12: 2-一般 | AH12: 3-有正面评价 | AI12: 3-有规划有意识 | AJ12: S-14-15 | AK12: 何咏04 | AL12: 是 | BF12: 陈亮延 | BG12: =VLOOKUP(B12,'UV台帐'!B:G,6,0) | BH12: 真光 | BR12: =COUNTIFS(H12,"一期",I12,"在读")+COUNTIFS(L12,"一期",M12,"在读")+COUNTIFS(P12,"一期",Q12,"在读") | BS12: =BR12-BW12 | BT12: =VLOOKUP(B12,'UV台帐'!B:AL,19,0) | BU12: =VLOOKUP(B12,'UV台帐'!B:AL,28,0) | BV12: =VLOOKUP(B12,'UV台帐'!B:AL,37,0) | BW12: =COUNTIFS(H12,"一期",BT12,"是")+COUNTIFS(L12,"一期",BU12,"是")+COUNTIFS(P12,"一期",BV12,"是") | CA12: 2524361673
A13: 同创汇 | B13: 2446527834 | C13: =VLOOKUP(B13,'UV台帐'!B:AL,2,0) | D13: =VLOOKUP(B13,'UV台帐'!B:AL,3,0) | E13: =VLOOKUP(B13,'UV台帐'!B:AL,13,0) | F13: =VLOOKUP(B13,'UV台帐'!B:AL,15,0) | G13: =VLOOKUP(B13,'UV台帐'!B:AL,16,0) | H13: =VLOOKUP(B13,'UV台帐'!B:AL,17,0) | I13: =VLOOKUP(B13,'UV台帐'!B:AL,18,0) | J13: =VLOOKUP(B13,'UV台帐'!B:AL,22,0) | K13: =VLOOKUP(B13,'UV台帐'!B:AL,24,0) | L13: =VLOOKUP(B13,'UV台帐'!B:AL,26,0) | M13: =VLOOKUP(B13,'UV台帐'!B:AL,27,0) | N13: =VLOOKUP(B13,'UV台帐'!B:AL,31,0) | O13: =VLOOKUP(B13,'UV台帐'!B:AL,33,0) | P13: =VLOOKUP(B13,'UV台帐'!B:AL,35,0) | Q13: =VLOOKUP(B13,'UV台帐'!B:AL,36,0) | R13: 是 | S13: B | U13: 是 | W13: 285-295 | Y13: 妈妈想在初中帮助孩子领跑在前面，应为现在还没上课，需要看情况，后续会考虑新宝利 | Z13: 妈妈感觉距离会有点远，后续可能考虑去新宝利上秋季课，先看暑秋上课情况 | AA13: 明确需求 | AB13: 意向校区在新宝利，出行比较方便，六下三科285期末，初中7中实验，小学沙头南，孩子有点懒，孩子愿意来上，需要改善孩子的学习习惯；希望去好的公办高中 2-3年级线上作业帮，4-6年没有补过课，家附近线下没有好的补课机构，希望老师多关注，帮助孩子改正习惯，需要看到习惯改变的效果 | AC13: 语,数,英 | AD13: 效果维度-提分,效果维度-抓习惯,沟通维度：老师有关注度 | AE13: 2-一般，对于目标需求一般 | AF13: 2-支付能力一般 | AG13: 3-喜欢 | AH13: 2-评价一般、无感 | AI13: 2-有意识无规划 | AJ13: B-8-10 | AK13: 陈南05 | BF13: 戎凯01 | BG13: =VLOOKUP(B13,'UV台帐'!B:G,6,0) | BR13: =COUNTIFS(H13,"一期",I13,"在读")+COUNTIFS(L13,"一期",M13,"在读")+COUNTIFS(P13,"一期",Q13,"在读") | BS13: =BR13-BW13 | BT13: =VLOOKUP(B13,'UV台帐'!B:AL,19,0) | BU13: =VLOOKUP(B13,'UV台帐'!B:AL,28,0) | BV13: =VLOOKUP(B13,'UV台帐'!B:AL,37,0) | BW13: =COUNTIFS(H13,"一期",BT13,"是")+COUNTIFS(L13,"一期",BU13,"是")+COUNTIFS(P13,"一期",BV13,"是") | CA13: 2578457931
A14: 同创汇 | B14: 4834944316 | C14: =VLOOKUP(B14,'UV台帐'!B:AL,2,0) | D14: =VLOOKUP(B14,'UV台帐'!B:AL,3,0) | E14: =VLOOKUP(B14,'UV台帐'!B:AL,13,0) | F14: =VLOOKUP(B14,'UV台帐'!B:AL,15,0) | G14: =VLOOKUP(B14,'UV台帐'!B:AL,16,0) | H14: =VLOOKUP(B14,'UV台帐'!B:AL,17,0) | I14: =VLOOKUP(B14,'UV台帐'!B:AL,18,0) | J14: =VLOOKUP(B14,'UV台帐'!B:AL,22,0) | K14: =VLOOKUP(B14,'UV台帐'!B:AL,24,0) | L14: =VLOOKUP(B14,'UV台帐'!B:AL,26,0) | M14: =VLOOKUP(B14,'UV台帐'!B:AL,27,0) | N14: =VLOOKUP(B14,'UV台帐'!B:AL,31,0) | O14: =VLOOKUP(B14,'UV台帐'!B:AL,33,0) | P14: =VLOOKUP(B14,'UV台帐'!B:AL,35,0) | Q14: =VLOOKUP(B14,'UV台帐'!B:AL,36,0) | R14: 是 | S14: A | T14: 否 | U14: 是 | V14: 省实越秀 | W14: 280-290 | X14: 语文很爱阅读。数学正常水平，高难度不行，不爱打草稿，绕弯的题目1-2个弯可以，第三个弯孩子就会畏难。性格是很好强。英语：幼儿阶段没开窍，但4-5年级去英孚学，现在还在英孚，ketPET,过了，是冲刺型选手 | Y14: 学校听了学校的家长会觉得新学期要给孩子补充，小宝有数学和语文的学习需求，大宝数学多学一个班是学而思，英语语文没有安排，打包一起报了 | Z14: 大宝：比较活泼开朗，高敏感孩子，喜欢被鼓励被看见，校内285+。语文很爱阅读。数学正常水平，高难度不行，不爱打草稿，很好强。英语：幼儿阶段没开窍，但4-5年级去英孚学，现在还在英孚，ketPET,过了，是冲刺型选手，基于孩子性格问题执信，二中没去，省市越秀摇中了，开学有分班考，要Top200名，孩子本身很想够上分班的资格，有学习主动性。 | AA14: 明确需求 | AB14: 谦谦性格：活泼开朗，高敏感孩子，喜欢被鼓励被看见，有学习主动性 校内成绩：校内285+ 语文：很爱阅读看书，但文言文课外拓展不足，阅读踩分点不太够的 数学：不爱打草稿，数学逻辑绕3个弯的题型有畏难情绪 英语：英孚拓展学过，KET/PET已通过，这个科目是冲刺型选手 初中学校：省实越秀，有分班考，孩子主动计划冲FC考（Top200名） | AC14: 语,数,英 | AD14: 效果维度-提分,效果维度-抓习惯,效果维度-培优拓展/分班考,沟通维度：老师有关注度 | AE14: 2-一般，对于目标需求一般 | AF14: 3-支付能力强 | AG14: 2-一般 | AH14: 2-评价一般、无感 | AI14: 3-有规划有意识 | AJ14: A-11-13 | AK14: 陈南05 | BF14: 苏丽婷 | BG14: =VLOOKUP(B14,'UV台帐'!B:G,6,0) | BH14: 省实越秀 | BR14: =COUNTIFS(H14,"一期",I14,"在读")+COUNTIFS(L14,"一期",M14,"在读")+COUNTIFS(P14,"一期",Q14,"在读") | BS14: =BR14-BW14 | BT14: =VLOOKUP(B14,'UV台帐'!B:AL,19,0) | BU14: =VLOOKUP(B14,'UV台帐'!B:AL,28,0) | BV14: =VLOOKUP(B14,'UV台帐'!B:AL,37,0) | BW14: =COUNTIFS(H14,"一期",BT14,"是")+COUNTIFS(L14,"一期",BU14,"是")+COUNTIFS(P14,"一期",BV14,"是") | CA14: 2937587526
A15: 同创汇 | B15: 2519148407 | C15: =VLOOKUP(B15,'UV台帐'!B:AL,2,0) | D15: =VLOOKUP(B15,'UV台帐'!B:AL,3,0) | E15: =VLOOKUP(B15,'UV台帐'!B:AL,13,0) | F15: =VLOOKUP(B15,'UV台帐'!B:AL,15,0) | G15: =VLOOKUP(B15,'UV台帐'!B:AL,16,0) | H15: =VLOOKUP(B15,'UV台帐'!B:AL,17,0) | I15: =VLOOKUP(B15,'UV台帐'!B:AL,18,0) | J15: =VLOOKUP(B15,'UV台帐'!B:AL,22,0) | K15: =VLOOKUP(B15,'UV台帐'!B:AL,24,0) | L15: =VLOOKUP(B15,'UV台帐'!B:AL,26,0) | M15: =VLOOKUP(B15,'UV台帐'!B:AL,27,0) | N15: =VLOOKUP(B15,'UV台帐'!B:AL,31,0) | O15: =VLOOKUP(B15,'UV台帐'!B:AL,33,0) | P15: =VLOOKUP(B15,'UV台帐'!B:AL,35,0) | Q15: =VLOOKUP(B15,'UV台帐'!B:AL,36,0) | R15: 是 | S15: B | T15: 否 | U15: 是 | V15: 10中 | W15: 数学语文A，英语B | X15: 面谈说语文不爱阅读，阅读理解最差，英语拼读没有技巧和方法，国际音标在线上学，还是不会运用 | Y15: 对比了很多家机构，最后家长和孩子选择了作业帮 | Z15: 面谈报的，看了环境还不错，现场也有老师在备课，姥姥和孩子现场都感到满意，说对比了几家机构这边便利和性价比高，现场给家长铺垫了暑假有效果一定要考虑秋季继续跟着学，铺垫了秋季的续班费用，教学内容的连贯性，家长觉得可以，会考虑。孩子性格是外向的，首课可能会有点胆怯，但也还好，摇中10中，想参加分层考，具体什么时间考不知道，暑假行课期间给孩子打印些分班考的卷子 | AA15: 明确需求 | AB15: 萱萱性格： 校内成绩： 数学语文是A 英语B 👋语文：不爱阅读，阅读理解最薄弱 ：读文浅，抓不住中心 👋数学：数学填空题错的最多，会理解错题目意思，其次是计算粗心大意的问题。 👋英语：英文背单词稍有困难，想要学音标，线上学过孩子不理解依然死记硬背，背单词需要花费2小时，背不扎实 初中学校：十中，分层考时间不明确，可提供分层真题练习 | AC15: 语,数,英 | AD15: 效果维度-提分,效果维度-抓习惯,效果维度-培优拓展/分班考,沟通维度：老师有个性化 | AE15: 2-一般，对于目标需求一般 | AF15: 2-支付能力一般 | AG15: 3-喜欢 | AH15: 3-有正面评价 | AI15: 2-有意识无规划 | AJ15: A-11-13 | AK15: 陈南05 | AL15: 是 | BF15: 苏丽婷 | BG15: =VLOOKUP(B15,'UV台帐'!B:G,6,0) | BH15: 十中 | BR15: =COUNTIFS(H15,"一期",I15,"在读")+COUNTIFS(L15,"一期",M15,"在读")+COUNTIFS(P15,"一期",Q15,"在读") | BS15: =BR15-BW15 | BT15: =VLOOKUP(B15,'UV台帐'!B:AL,19,0) | BU15: =VLOOKUP(B15,'UV台帐'!B:AL,28,0) | BV15: =VLOOKUP(B15,'UV台帐'!B:AL,37,0) | BW15: =COUNTIFS(H15,"一期",BT15,"是")+COUNTIFS(L15,"一期",BU15,"是")+COUNTIFS(P15,"一期",BV15,"是") | CA15: 4399390086
A16: 新宝利 | B16: 4156594850 | C16: =VLOOKUP(B16,'UV台帐'!B:AL,2,0) | D16: =VLOOKUP(B16,'UV台帐'!B:AL,3,0) | E16: =VLOOKUP(B16,'UV台帐'!B:AL,13,0) | F16: =VLOOKUP(B16,'UV台帐'!B:AL,15,0) | G16: =VLOOKUP(B16,'UV台帐'!B:AL,16,0) | H16: =VLOOKUP(B16,'UV台帐'!B:AL,17,0) | I16: =VLOOKUP(B16,'UV台帐'!B:AL,18,0) | J16: =VLOOKUP(B16,'UV台帐'!B:AL,22,0) | K16: =VLOOKUP(B16,'UV台帐'!B:AL,24,0) | L16: =VLOOKUP(B16,'UV台帐'!B:AL,26,0) | M16: =VLOOKUP(B16,'UV台帐'!B:AL,27,0) | N16: =VLOOKUP(B16,'UV台帐'!B:AL,31,0) | O16: =VLOOKUP(B16,'UV台帐'!B:AL,33,0) | P16: =VLOOKUP(B16,'UV台帐'!B:AL,35,0) | Q16: =VLOOKUP(B16,'UV台帐'!B:AL,36,0) | R16: 是 | S16: A | T16: 否 | U16: 是 | V16: 大南路，真光 | W16: 80+三科 | X16: 容易专注度不高，不爱做笔记 | Y16: 提前学初一，爸爸想找性价比高的机构 | Z16: 初中肯定学，孩子注意力不集中，之前学一对一一对二这种的，首次班课担心真的怕效果不好，最好前排多关注。有支付能力，担心课程效果和老师的关注度，爸爸考虑一对一。A，担心人多。三科80多分，孩子专注力差 | AA16: 明确需求 | AB16: 7月8日沟通，家长层面支付能力不错，之前都是家教的，价格都是500多一次课，支付能力强，爸爸妈妈知道孩子这个情况不补不行 孩子妈咪说孩子成绩一般，各个方面都一般（原话），本次来上课主要是想要是想要转大机构试试班课，但是同步很担心人多关注度不够，重点客户 @肖锐03(Jerry) @陈南05(陈南) @何咏04(何咏)，尽可能让孩子坐前排，关注孩子，平时孩子答题，互动一定要助教拍照做好正面反馈，多做正向反馈 | AC16: 语,数,英 | AD16: 升学需求-保底本区公办高中,效果维度-提分,效果维度-抓习惯,沟通维度：老师有个性化 | AE16: 2-一般，对于目标需求一般 | AF16: 3-支付能力强 | AG16: 2-一般 | AH16: 2-评价一般、无感 | AI16: 3-有规划有意识 | AJ16: A-11-13 | AK16: 何咏04 | AL16: 是 | BF16: 林志豪01 | BG16: =VLOOKUP(B16,'UV台帐'!B:G,6,0) | BR16: =COUNTIFS(H16,"一期",I16,"在读")+COUNTIFS(L16,"一期",M16,"在读")+COUNTIFS(P16,"一期",Q16,"在读") | BS16: =BR16-BW16 | BT16: =VLOOKUP(B16,'UV台帐'!B:AL,19,0) | BU16: =VLOOKUP(B16,'UV台帐'!B:AL,28,0) | BV16: =VLOOKUP(B16,'UV台帐'!B:AL,37,0) | BW16: =COUNTIFS(H16,"一期",BT16,"是")+COUNTIFS(L16,"一期",BU16,"是")+COUNTIFS(P16,"一期",BV16,"是") | CA16: 4850707583
